Workbook

Sheet Inputs
A1: Zoom Communications (ZM) - Take-Private LBO: Inputs
A2: USD millions except per-share. Blue = hard-coded input; black = formula; purple = same-tab link; green = cross-tab link.
A3: Item | B3: Value | C3: Units | D3: Source / note
A5: TRANSACTION
A6: Current share price (close 2026-10-15) | B6: 98.51 | C6: $/sh | D6: stockanalysis.com / finance.yahoo.com, close 2026-10-15
A7: Offer premium to current price | B7: 0.3 | C7: % | D7: User assumption
A8: Offer price per share | B8: =B6*(1+B7) -> 128.063 | C8: $/sh | D8: Formula
A9: Basic shares outstanding (Class A + B) | B9: 291.78371 | C9: m sh | D9: 10-Q Q2 FY27 cover: 263.233m A + 28.551m B as of 2026-08-14
A10: Dilutive securities (RSUs/options, est.) | B10: 6.867104 | C10: m sh | D10: Est.: Q2 FY27 diluted WASO 299.746m less basic WASO 292.879m (8-K 2026-08-25)
A11: Fully diluted shares | B11: =B9+B10 -> 298.65082 | C11: m sh | D11: Formula
A12: Cash & cash equivalents (2026-07-31) | B12: 931.992 | C12: $m | D12: 8-K Ex.99.1 filed 2026-08-25
A13: Marketable securities (2026-07-31) | B13: 6317.729 | C13: $m | D13: 8-K Ex.99.1 filed 2026-08-25
A14: Existing debt | B14: 0 | C14: $m | D14: No borrowings on balance sheet (8-K 2026-08-25)
A15: Minimum operating cash left in business | B15: 500 | C15: $m | D15: Assumption (~10% of LTM revenue)
A16: M&A / transaction fees (% of entry EV) | B16: 0.015 | C16: % | D16: Assumption
A17: Financing fees (% of debt raised) | B17: 0.0225 | C17: % | D17: Assumption
A18: Assumed closing date | B18: 46326 | C18: date | D18: Assumption
A19: Holding period | B19: 5 | C19: years | D19: User assumption
A21: LTM FINANCIALS (LTM to 2026-07-31 = FY26 + 6M FY27 - 6M FY26)
A22: Columns: FY26 (8-K 2026-02-25) | 6M FY27 | 6M FY26 (8-K 2026-08-25) | LTM | E22: FY2026 | F22: 6M FY27 | G22: 6M FY26 | H22: LTM
A23: Revenue | B23: =H23 -> 4993.05 | C23: $m | D23: LTM formula in col H | E23: 4868.769 | F23: 2516.223 | G23: 2391.942 | H23: =E23+F23-G23 -> 4993.05
A24: GAAP income from operations | B24: =H24 -> 1185.095 | C24: $m | D24: LTM formula in col H | E24: 1123.633 | F24: 624.789 | G24: 563.327 | H24: =E24+F24-G24 -> 1185.095
A25: Depreciation & amortization | B25: =H25 -> 130.464 | C25: $m | D25: LTM formula in col H | E25: 132.831 | F25: 65.112 | G25: 67.479 | H25: =E25+F25-G25 -> 130.464
A26: Stock-based compensation expense | B26: =H26 -> 729.245 | C26: $m | D26: LTM formula in col H | E26: 760.776 | F26: 358.737 | G26: 390.268 | H26: =E26+F26-G26 -> 729.245
A27: Capex (purchases of PP&E) | B27: =H27 -> 74.551 | C27: $m | D27: LTM formula in col H | E27: 64.961 | F27: 43.466 | G27: 33.876 | H27: =E27+F27-G27 -> 74.551
A28: LTM EBITDA (GAAP op. income + D&A) | B28: =B24+B25 -> 1315.559 | C28: $m | D28: Formula; SBC treated as expense
A29: LTM Adj. EBITDA (op. income + D&A + SBC) | B29: =B28+B26 -> 2044.804 | C29: $m | D29: Formula; SBC added back (sponsor/lender convention). Basis for valuation & leverage
A30: LTM Adj. EBITDA margin | B30: =B29/B23 -> 0.40953005 | C30: % | D30: Formula
A32: OPERATING ASSUMPTIONS (Year 1-5 = columns C..G of the LBO tab)
A33: Revenue growth Y1 | B33: 0.04 | C33: % | D33: Assumption; FY27 guide $5.085-5.095bn implies ~4.5%; Q2 grew 4.9%
A34: Revenue growth Y2 | B34: 0.04 | C34: % | D34: Assumption
A35: Revenue growth Y3 | B35: 0.035 | C35: % | D35: Assumption
A36: Revenue growth Y4 | B36: 0.035 | C36: % | D36: Assumption
A37: Revenue growth Y5 | B37: 0.03 | C37: % | D37: Assumption
A38: Adj. EBITDA margin Y1 | B38: 0.415 | C38: % | D38: Assumption; modest sponsor cost-out from 41.0% LTM
A39: Adj. EBITDA margin Y2 | B39: 0.42 | C39: % | D39: Assumption
A40: Adj. EBITDA margin Y3 | B40: 0.425 | C40: % | D40: Assumption
A41: Adj. EBITDA margin Y4 | B41: 0.43 | C41: % | D41: Assumption
A42: Adj. EBITDA margin Y5 | B42: 0.43 | C42: % | D42: Assumption
A43: Cash cost to replace SBC (% of revenue) | B43: 0.07 | C43: % | D43: Assumption: ~half of LTM SBC (14.6% of rev) replaced with cash comp post take-private
...

Sheet LBO
A1: Zoom Communications (ZM) - Take-Private LBO
A2: USD millions except per-share. Entry assumed 2026-10-31; Year 1 = 12 months to 2027-10-31 ... Year 5 exit 2031-10-31.
A4: SOURCES & USES
A5: Purchase price
A6: Current share price | B6: =Inputs!B6 -> 98.51
A7: Premium | B7: =Inputs!B7 -> 0.3
A8: Offer price per share | B8: =Inputs!B8 -> 128.063
A9: Fully diluted shares (m) | B9: =Inputs!B11 -> 298.65082
A10: Equity purchase price | B10: =B8*B9 -> 38246.119
A11: Plus: existing debt | B11: =Inputs!B14 -> 0
A12: Less: cash + marketable securities | B12: =-(Inputs!B12+Inputs!B13) -> -7249.721
A13: Entry enterprise value | B13: =B10+B11+B12 -> 30996.398
A14: LTM Adj. EBITDA (incl. SBC add-back) | B14: =Inputs!B29 -> 2044.804
A15: Entry EV / LTM Adj. EBITDA | B15: =B13/B14 -> 15.158616
A16: LTM EBITDA (SBC as expense) | B16: =Inputs!B28 -> 1315.559
A17: Entry EV / LTM EBITDA (SBC expensed) | B17: =B13/B16 -> 23.56139
A18: Implied premium to current market EV | B18: =B13/(B6*B9+B11+B12)-1 -> 0.39810013
A20: Sources | B20: $m | C20: % total | D20: x EBITDA | E20: Rate
A21: Term Loan B | B21: =Inputs!B53*B14 -> 8179.216 | C21: =B21/$B$25 -> 0.20979281 | D21: =B21/B14 -> 4 | E21: =Inputs!B52 -> 0.0713
A22: Senior Notes | B22: =Inputs!B60*B14 -> 4089.608 | C22: =B22/$B$25 -> 0.1048964 | D22: =B22/B14 -> 2 | E22: =Inputs!B59 -> 0.0877
A23: Existing balance sheet cash used | B23: =Inputs!B12+Inputs!B13-Inputs!B15 -> 6749.721 | C23: =B23/$B$25 -> 0.17312697
A24: Sponsor equity (plug) | B24: =B32-SUM(B21:B23) -> 19968.569 | C24: =B24/$B$25 -> 0.51218382
A25: Total sources | B25: =SUM(B21:B24) -> 38987.114 | C25: =B25/$B$25 -> 1
A27: Uses | B27: $m | C27: % total
A28: Purchase of equity | B28: =B10 -> 38246.119 | C28: =B28/$B$32 -> 0.98099386
A29: Refinance existing debt | B29: =B11 -> 0 | C29: =B29/$B$32 -> 0
A30: Transaction fees | B30: =Inputs!B16*B13 -> 464.94597 | C30: =B30/$B$32 -> 0.011925632
A31: Financing fees | B31: =Inputs!B17*(B21+B22) -> 276.04854 | C31: =B31/$B$32 -> 0.0070805072
A32: Total uses | B32: =SUM(B28:B31) -> 38987.114 | C32: =B32/$B$32 -> 1
A33: Check: sources - uses (should be 0) | B33: =B25-B32 -> 0
A34: Total debt / LTM Adj. EBITDA | B34: =(B21+B22)/B14 -> 6
A35: Sponsor equity % of total capitalization | B35: =B24/(B24+B21+B22) -> 0.61942257
A37: OPERATING MODEL
A38: Period | B38: LTM 2026-07 | C38: Year 1 | D38: Year 2 | E38: Year 3 | F38: Year 4 | G38: Year 5
A39: Period end (B = closing) | B39: =Inputs!B18 -> 46326 | C39: =EDATE(Inputs!B18,12) -> 46691 | D39: =EDATE(Inputs!B18,24) -> 47057 | E39: =EDATE(Inputs!B18,36) -> 47422 | F39: =EDATE(Inputs!B18,48) -> 47787 | G39: =EDATE(Inputs!B18,60) -> 48152
A40: Revenue growth | C40: =Inputs!B33 -> 0.04 | D40: =Inputs!B34 -> 0.04 | E40: =Inputs!B35 -> 0.035 | F40: =Inputs!B36 -> 0.035 | G40: =Inputs!B37 -> 0.03
A41: Revenue | B41: =Inputs!B23 -> 4993.05 | C41: =B41*(1+C40) -> 5192.772 | D41: =C41*(1+D40) -> 5400.4829 | E41: =D41*(1+E40) -> 5589.4998 | F41: =E41*(1+F40) -> 5785.1323 | G41: =F41*(1+G40) -> 5958.6862
A42: Adj. EBITDA margin | B42: =Inputs!B30 -> 0.40953005 | C42: =Inputs!B38 -> 0.415 | D42: =Inputs!B39 -> 0.42 | E42: =Inputs!B40 -> 0.425 | F42: =Inputs!B41 -> 0.43 | G42: =Inputs!B42 -> 0.43
A43: Adj. EBITDA (pre-SBC) | B43: =Inputs!B29 -> 2044.804 | C43: =C41*C42 -> 2155.0004 | D43: =D41*D42 -> 2268.2028 | E43: =E41*E42 -> 2375.5374 | F43: =F41*F42 -> 2487.6069 | G43: =G41*G42 -> 2562.2351
A44: Less: cash replacement of SBC | C44: =-C41*Inputs!B43 -> -363.49404 | D44: =-D41*Inputs!B43 -> -378.0338 | E44: =-E41*Inputs!B43 -> -391.26498 | F44: =-F41*Inputs!B43 -> -404.95926 | G44: =-G41*Inputs!B43 -> -417.10804
...
