Workbook

Sheet Notes
A1: Advanced Micro Devices, Inc. (NASDAQ: AMD) - Financial Model
A3: Prepared 2026-10-14 (Initiating Coverage, Task 2). Units: USD millions except per-share (USD) and share counts (millions).
A4: Fiscal year ends on the last Saturday of December (FY2025 = 2025-12-27).
A6: COLOR CODE: blue = hardcoded input / historical data; black = formula; green = link to another sheet; grey italic = static scenario snapshot.
A7: SCENARIO SWITCH: Scenarios!C3 (1 Bull, 2 Base, 3 Bear). Named range: ScenarioSel.
A9: SOURCES
A10: - AMD Form 10-K FY2025 (filed 2026-02-04) and Form 10-K FY2024 (filed 2025-02-05), via SEC XBRL (stock-data get_financials).
A11: - AMD Form 10-Q Q2 FY2026 (filed 2026-08-05) and Q1 FY2026 (filed 2026-05-06), via XBRL and sec.gov.
A12: - AMD Q4/FY2025 earnings release (2026-02-03, ir.amd.com): full FY2025/FY2024 statements, segment data, FCF reconciliation.
A13: - AMD Q4/FY2024 earnings release EX-99.1 (2025-02-04) and Q4/FY2023 EX-99.1 (2024-01-30): FY2022-FY2023 statements and segments.
A14: - AMD Q2 FY2026 earnings release (2026-08-05): Q3 FY2026 guidance about USD 13.0bn +/- 0.3bn; non-GAAP GM about 56%.
A15: - Market data: stock-data get_quote, USD 605.53 at 2026-10-14 07:49 UTC.
... A27: TABS: Revenue Model | Income Statement | Cash Flow | Balance Sheet | Scenarios | DCF Inputs | Quarterly Hist | Checks

Sheet Revenue Model
A1: AMD - Revenue Model
A2: USD millions. Historical segment totals are reported (10-K / earnings releases); sub-product splits are analyst estimates (blue). Projections driven by Scenarios tab.
A4: Revenue by product | C4: FY2022A | D4: FY2023A | E4: FY2024A | F4: FY2025A | G4: FY2026E | H4: FY2027E | I4: FY2028E | J4: FY2029E | K4: FY2030E
A5: Data Center
A6: Server CPU (EPYC) | B6: hist split = estimate | C6: 5493 | D6: 5596 | E6: 7329 | F6: 9735 | G6: =F6*(1+G7) -> 13629 | H6: =G6*(1+H7) -> 17036.25 | I6: =H6*(1+I7) -> 19591.688 | J6: =I6*(1+J7) -> 21942.69 | K6: =J6*(1+K7) -> 24136.959
A7: YoY growth % | D7: =D6/C6-1 -> 0.018751138 | E7: =E6/D6-1 -> 0.30968549 | F7: =F6/E6-1 -> 0.3282849 | G7: =Scenarios!G9 -> 0.4 | H7: =Scenarios!H9 -> 0.25 | I7: =Scenarios!I9 -> 0.15 | J7: =Scenarios!J9 -> 0.12 | K7: =Scenarios!K9 -> 0.1
A8: Data Center GPU (Instinct MI-series) | B8: hist split = estimate | C8: 400 | D8: 700 | E8: 5000 | F8: 6500 | G8: =F8*(1+G9) -> 15600 | H8: =G8*(1+H9) -> 29640 | I8: =H8*(1+I9) -> 42978 | J8: =I8*(1+J9) -> 53722.5 | K8: =J8*(1+K9) -> 61780.875
A9: YoY growth % | D9: =D8/C8-1 -> 0.75 | E9: =E8/D8-1 -> 6.1428571 | F9: =F8/E8-1 -> 0.3 | G9: =Scenarios!G15 -> 1.4 | H9: =Scenarios!H15 -> 0.9 | I9: =Scenarios!I15 -> 0.45 | J9: =Scenarios!J15 -> 0.25 | K9: =Scenarios!K15 -> 0.15
A10: Networking (Pensando), rack-scale & other | B10: hist split = estimate | C10: 150 | D10: 200 | E10: 250 | F10: 400 | G10: =F10*(1+G11) -> 1000 | H10: =G10*(1+H11) -> 2000 | I10: =H10*(1+I11) -> 3000 | J10: =I10*(1+J11) -> 3900 | K10: =J10*(1+K11) -> 4680
A11: YoY growth % | D11: =D10/C10-1 -> 0.33333333 | E11: =E10/D10-1 -> 0.25 | F11: =F10/E10-1 -> 0.6 | G11: =Scenarios!G21 -> 1.5 | H11: =Scenarios!H21 -> 1 | I11: =Scenarios!I21 -> 0.5 | J11: =Scenarios!J21 -> 0.3 | K11: =Scenarios!K21 -> 0.2
A12: Data Center total | C12: =C6+C8+C10 -> 6043 | D12: =D6+D8+D10 -> 6496 | E12: =E6+E8+E10 -> 12579 | F12: =F6+F8+F10 -> 16635 | G12: =G6+G8+G10 -> 30229 | H12: =H6+H8+H10 -> 48676.25 | I12: =I6+I8+I10 -> 65569.688 | J12: =J6+J8+J10 -> 79565.19 | K12: =K6+K8+K10 -> 90597.834
A13: % of total revenue | C13: =C12/C47 -> 0.25604847 | D13: =D12/D47 -> 0.28641975 | E13: =E12/E47 -> 0.48784177 | F13: =F12/F47 -> 0.48023904 | G13: =G12/G47 -> 0.61098928 | H13: =H12/H47 -> 0.70425729 | I13: =I12/I47 -> 0.75007793 | J13: =J12/J47 -> 0.77489575 | K13: =K12/K47 -> 0.79116915
A14: YoY growth % | D14: =D12/C12-1 -> 0.074962767 | E14: =E12/D12-1 -> 0.93642241 | F14: =F12/E12-1 -> 0.32244217 | G14: =G12/F12-1 -> 0.81719267 | H14: =H12/G12-1 -> 0.61025009 | I14: =I12/H12-1 -> 0.34705709 | J14: =J12/I12-1 -> 0.2134447 | K14: =K12/J12-1 -> 0.13866169
A16: Client
A17: Desktop CPU (Ryzen, Threadripper) | B17: hist split = estimate | C17: 2790 | D17: 2093 | E17: 3174 | F17: 5320 | G17: =F17*(1+G18) -> 6118 | H17: =G17*(1+H18) -> 6485.08 | I17: =H17*(1+I18) -> 6809.334 | J17: =I17*(1+J18) -> 7149.8007 | K17: =J17*(1+K18) -> 7435.7927
A18: YoY growth % | D18: =D17/C17-1 -> -0.24982079 | E18: =E17/D17-1 -> 0.51648352 | F18: =F17/E17-1 -> 0.67611846 | G18: =Scenarios!G27 -> 0.15 | H18: =Scenarios!H27 -> 0.06 | I18: =Scenarios!I27 -> 0.05 | J18: =Scenarios!J27 -> 0.05 | K18: =Scenarios!K27 -> 0.04
A19: Notebook CPU (Ryzen AI / Mobile) | B19: hist split = estimate | C19: 3411 | D19: 2558 | E19: 3880 | F19: 5320 | G19: =F19*(1+G20) -> 6118 | H19: =G19*(1+H20) -> 6485.08 | I19: =H19*(1+I20) -> 6809.334 | J19: =I19*(1+J20) -> 7149.8007 | K19: =J19*(1+K20) -> 7435.7927
A20: YoY growth % | D20: =D19/C19-1 -> -0.25007329 | E20: =E19/D19-1 -> 0.51681001 | F20: =F19/E19-1 -> 0.37113402 | G20: =Scenarios!G33 -> 0.15 | H20: =Scenarios!H33 -> 0.06 | I20: =Scenarios!I33 -> 0.05 | J20: =Scenarios!J33 -> 0.05 | K20: =Scenarios!K33 -> 0.04
A21: Client total | C21: =C17+C19 -> 6201 | D21: =D17+D19 -> 4651 | E21: =E17+E19 -> 7054 | F21: =F17+F19 -> 10640 | G21: =G17+G19 -> 12236 | H21: =H17+H19 -> 12970.16 | I21: =I17+I19 -> 13618.668 | J21: =J17+J19 -> 14299.601 | K21: =K17+K19 -> 14871.585
A22: % of total revenue | C22: =C21/C47 -> 0.2627431 | D22: =D21/D47 -> 0.20507055 | E22: =E21/E47 -> 0.2735699 | F22: =F21/F47 -> 0.30716822 | G22: =G21/G47 -> 0.24731433 | H22: =H21/H47 -> 0.18765476 | I22: =I21/I47 -> 0.1557894 | J22: =J21/J47 -> 0.13926568 | K22: =K21/K47 -> 0.12986999
A23: YoY growth % | D23: =D21/C21-1 -> -0.24995968 | E23: =E21/D21-1 -> 0.51666308 | F23: =F21/E21-1 -> 0.50836405 | G23: =G21/F21-1 -> 0.15 | H23: =H21/G21-1 -> 0.06 | I23: =I21/H21-1 -> 0.05 | J23: =J21/I21-1 -> 0.05 | K23: =K21/J21-1 -> 0.04
A25: Gaming
A26: Semi-custom console SoCs | B26: hist split = estimate | C26: 5444 | D26: 5280 | E26: 1946 | F26: 2540 | G26: =F26*(1+G27) -> 1778 | H26: =G26*(1+H27) -> 1778 | I26: =H26*(1+I27) -> 2133.6 | J26: =I26*(1+J27) -> 2346.96 | K26: =J26*(1+K27) -> 2229.612
A27: YoY growth % | D27: =D26/C26-1 -> -0.030124908 | E27: =E26/D26-1 -> -0.63143939 | F27: =F26/E26-1 -> 0.30524152 | G27: =Scenarios!G39 -> -0.3 | H27: =Scenarios!H39 -> 0 | I27: =Scenarios!I39 -> 0.2 | J27: =Scenarios!J39 -> 0.1 | K27: =Scenarios!K39 -> -0.05
A28: Radeon discrete GPUs | B28: hist split = estimate | C28: 1361 | D28: 932 | E28: 649 | F28: 1370 | G28: =F28*(1+G29) -> 1260.4 | H28: =G28*(1+H29) -> 1323.42 | I28: =H28*(1+I29) -> 1376.3568 | J28: =I28*(1+J29) -> 1417.6475 | K28: =J28*(1+K29) -> 1460.1769
A29: YoY growth % | D29: =D28/C28-1 -> -0.3152094 | E29: =E28/D28-1 -> -0.30364807 | F29: =F28/E28-1 -> 1.1109399 | G29: =Scenarios!G45 -> -0.08 | H29: =Scenarios!H45 -> 0.05 | I29: =Scenarios!I45 -> 0.04 | J29: =Scenarios!J45 -> 0.03 | K29: =Scenarios!K45 -> 0.03
A30: Gaming total | C30: =C26+C28 -> 6805 | D30: =D26+D28 -> 6212 | E30: =E26+E28 -> 2595 | F30: =F26+F28 -> 3910 | G30: =G26+G28 -> 3038.4 | H30: =H26+H28 -> 3101.42 | I30: =I26+I28 -> 3509.9568 | J30: =J26+J28 -> 3764.6075 | K30: =K26+K28 -> 3689.7889
A31: % of total revenue | C31: =C30/C47 -> 0.28833524 | D31: =D30/D47 -> 0.27389771 | E31: =E30/E47 -> 0.10063991 | F31: =F30/F47 -> 0.11287855 | G31: =G30/G47 -> 0.061412214 | H31: =H30/H47 -> 0.044871938 | I31: =I30/I47 -> 0.040151802 | J31: =J30/J47 -> 0.036664003 | K31: =K30/K47 -> 0.032222041
A32: YoY growth % | D32: =D30/C30-1 -> -0.087141807 | E32: =E30/D30-1 -> -0.58226014 | F32: =F30/E30-1 -> 0.50674374 | G32: =G30/F30-1 -> -0.2229156 | H32: =H30/G30-1 -> 0.02074118 | I32: =I30/H30-1 -> 0.13172573 | J32: =J30/I30-1 -> 0.072550951 | K32: =K30/J30-1 -> -0.019874203
A34: Embedded
A35: FPGA & adaptive SoC (Xilinx) | B35: hist split = estimate | C35: 3869 | D35: 4523 | E35: 3023 | F35: 2936 | G35: =F35*(1+G36) -> 3376.4 | H35: =G35*(1+H36) -> 3714.04 | I35: =H35*(1+I36) -> 4011.1632 | J35: =I35*(1+J36) -> 4291.9446 | K35: =J35*(1+K36) -> 4549.4613
A36: YoY growth % | D36: =D35/C35-1 -> 0.16903593 | E36: =E35/D35-1 -> -0.33163829 | F36: =F35/E35-1 -> -0.028779358 | G36: =Scenarios!G51 -> 0.15 | H36: =Scenarios!H51 -> 0.1 | I36: =Scenarios!I51 -> 0.08 | J36: =Scenarios!J51 -> 0.07 | K36: =Scenarios!K51 -> 0.06
A37: Embedded x86 (EPYC/Ryzen Embedded) | B37: hist split = estimate | C37: 683 | D37: 798 | E37: 534 | F37: 518 | G37: =F37*(1+G38) -> 595.7 | H37: =G37*(1+H38) -> 655.27 | I37: =H37*(1+I38) -> 707.6916 | J37: =I37*(1+J38) -> 757.23001 | K37: =J37*(1+K38) -> 802.66381
A38: YoY growth % | D38: =D37/C37-1 -> 0.16837482 | E38: =E37/D37-1 -> -0.33082707 | F38: =F37/E37-1 -> -0.029962547 | G38: =Scenarios!G57 -> 0.15 | H38: =Scenarios!H57 -> 0.1 | I38: =Scenarios!I57 -> 0.08 | J38: =Scenarios!J57 -> 0.07 | K38: =Scenarios!K57 -> 0.06
A39: Embedded total | C39: =C35+C37 -> 4552 | D39: =D35+D37 -> 5321 | E39: =E35+E37 -> 3557 | F39: =F35+F37 -> 3454 | G39: =G35+G37 -> 3972.1 | H39: =H35+H37 -> 4369.31 | I39: =I35+I37 -> 4718.8548 | J39: =J35+J37 -> 5049.1746 | K39: =K35+K37 -> 5352.1251
A40: % of total revenue | C40: =C39/C47 -> 0.19287318 | D40: =D39/D47 -> 0.23461199 | E40: =E39/E47 -> 0.13794842 | F40: =F39/F47 -> 0.099714195 | G40: =G39/G47 -> 0.080284181 | H40: =H39/H47 -> 0.063216013 | I40: =I39/I47 -> 0.053980871 | J40: =J39/J47 -> 0.049174569 | K40: =K39/K47 -> 0.046738824
A41: YoY growth % | D41: =D39/C39-1 -> 0.16893673 | E41: =E39/D39-1 -> -0.33151663 | F41: =F39/E39-1 -> -0.028956986 | G41: =G39/F39-1 -> 0.15 | H41: =H39/G39-1 -> 0.1 | I41: =I39/H39-1 -> 0.08 | J41: =J39/I39-1 -> 0.07 | K41: =K39/J39-1 -> 0.06
A43: Reporting-segment view
A44: Client and Gaming segment (reported combined from FY2025) | C44: =C21+C30 -> 13006 | D44: =D21+D30 -> 10863 | E44: =E21+E30 -> 9649 | F44: =F21+F30 -> 14550 | G44: =G21+G30 -> 15274.4 | H44: =H21+H30 -> 16071.58 | I44: =I21+I30 -> 17128.625 | J44: =J21+J30 -> 18064.209 | K44: =K21+K30 -> 18561.374
A45: Data Center AI-related (GPU + networking) | C45: =C8+C10 -> 550 | D45: =D8+D10 -> 900 | E45: =E8+E10 -> 5250 | F45: =F8+F10 -> 6900 | G45: =G8+G10 -> 16600 | H45: =H8+H10 -> 31640 | I45: =I8+I10 -> 45978 | J45: =J8+J10 -> 57622.5 | K45: =K8+K10 -> 66460.875
...

Sheet Income Statement
A1: AMD - Income Statement (GAAP)
A2: USD millions except per share. FY2022A-FY2025A from 10-K / Q4 earnings releases (FY2024 & FY2025 MG&A shown net of licensing gains, as recast).
A4: USD millions | C4: FY2022A | D4: FY2023A | E4: FY2024A | F4: FY2025A | G4: FY2026E | H4: FY2027E | I4: FY2028E | J4: FY2029E | K4: FY2030E
A5: Revenue
A6: Data Center | C6: ='Revenue Model'!C12 -> 6043 | D6: ='Revenue Model'!D12 -> 6496 | E6: ='Revenue Model'!E12 -> 12579 | F6: ='Revenue Model'!F12 -> 16635 | G6: ='Revenue Model'!G12 -> 30229 | H6: ='Revenue Model'!H12 -> 48676.25 | I6: ='Revenue Model'!I12 -> 65569.688 | J6: ='Revenue Model'!J12 -> 79565.19 | K6: ='Revenue Model'!K12 -> 90597.834
A7: Client | C7: ='Revenue Model'!C21 -> 6201 | D7: ='Revenue Model'!D21 -> 4651 | E7: ='Revenue Model'!E21 -> 7054 | F7: ='Revenue Model'!F21 -> 10640 | G7: ='Revenue Model'!G21 -> 12236 | H7: ='Revenue Model'!H21 -> 12970.16 | I7: ='Revenue Model'!I21 -> 13618.668 | J7: ='Revenue Model'!J21 -> 14299.601 | K7: ='Revenue Model'!K21 -> 14871.585
A8: Gaming | C8: ='Revenue Model'!C30 -> 6805 | D8: ='Revenue Model'!D30 -> 6212 | E8: ='Revenue Model'!E30 -> 2595 | F8: ='Revenue Model'!F30 -> 3910 | G8: ='Revenue Model'!G30 -> 3038.4 | H8: ='Revenue Model'!H30 -> 3101.42 | I8: ='Revenue Model'!I30 -> 3509.9568 | J8: ='Revenue Model'!J30 -> 3764.6075 | K8: ='Revenue Model'!K30 -> 3689.7889
A9: Embedded | C9: ='Revenue Model'!C39 -> 4552 | D9: ='Revenue Model'!D39 -> 5321 | E9: ='Revenue Model'!E39 -> 3557 | F9: ='Revenue Model'!F39 -> 3454 | G9: ='Revenue Model'!G39 -> 3972.1 | H9: ='Revenue Model'!H39 -> 4369.31 | I9: ='Revenue Model'!I39 -> 4718.8548 | J9: ='Revenue Model'!J39 -> 5049.1746 | K9: ='Revenue Model'!K39 -> 5352.1251
A10: Total net revenue | C10: =C6+C7+C8+C9 -> 23601 | D10: =D6+D7+D8+D9 -> 22680 | E10: =E6+E7+E8+E9 -> 25785 | F10: =F6+F7+F8+F9 -> 34639 | G10: =G6+G7+G8+G9 -> 49475.5 | H10: =H6+H7+H8+H9 -> 69117.14 | I10: =I6+I7+I8+I9 -> 87417.167 | J10: =J6+J7+J8+J9 -> 102678.57 | K10: =K6+K7+K8+K9 -> 114511.33
A11: YoY growth % | D11: =D10/C10-1 -> -0.03902377 | E11: =E10/D10-1 -> 0.13690476 | F11: =F10/E10-1 -> 0.34337793 | G11: =G10/F10-1 -> 0.42831779 | H11: =H10/G10-1 -> 0.3969973 | I11: =I10/H10-1 -> 0.26476829 | J11: =J10/I10-1 -> 0.17458134 | K11: =K10/J10-1 -> 0.11524079
A13: Cost of sales
A14: Cost of sales ex-amortization % of revenue (driver) | C14: =C15/C10 -> 0.48938604 | D14: =D15/D10 -> 0.49726631 | E14: =E15/E10 -> 0.46980803 | F14: =F15/F10 -> 0.47507145 | G14: =Scenarios!G63 -> 0.455 | H14: =Scenarios!H63 -> 0.45 | I14: =Scenarios!I63 -> 0.445 | J14: =Scenarios!J63 -> 0.44 | K14: =Scenarios!K63 -> 0.44
A15: Cost of sales (ex-amortization) | C15: 11550 | D15: 11278 | E15: 12114 | F15: 16456 | G15: =G10*G14 -> 22511.353 | H15: =H10*H14 -> 31102.713 | I15: =I10*I14 -> 38900.639 | J15: =J10*J14 -> 45178.572 | K15: =K10*K14 -> 50384.987
A16: Amortization of acquisition-related intangibles (COGS) | C16: 1448 | D16: 942 | E16: 946 | F16: 1031 | G16: =G70*G71 -> 945 | H16: =H70*H71 -> 855 | I16: =I70*I71 -> 765 | J16: =J70*J71 -> 675 | K16: =K70*K71 -> 585
A17: Total cost of sales | C17: =C15+C16 -> 12998 | D17: =D15+D16 -> 12220 | E17: =E15+E16 -> 13060 | F17: =F15+F16 -> 17487 | G17: =G15+G16 -> 23456.353 | H17: =H15+H16 -> 31957.713 | I17: =I15+I16 -> 39665.639 | J17: =J15+J16 -> 45853.572 | K17: =K15+K16 -> 50969.987
A18: Gross profit | C18: =C10-C17 -> 10603 | D18: =D10-D17 -> 10460 | E18: =E10-E17 -> 12725 | F18: =F10-F17 -> 17152 | G18: =G10-G17 -> 26019.147 | H18: =H10-H17 -> 37159.427 | I18: =I10-I17 -> 47751.528 | J18: =J10-J17 -> 56825.001 | K18: =K10-K17 -> 63541.347
A19: Gross margin % (GAAP) | C19: =C18/C10 -> 0.44926062 | D19: =D18/D10 -> 0.46119929 | E19: =E18/E10 -> 0.49350398 | F19: =F18/F10 -> 0.49516441 | G19: =G18/G10 -> 0.52589964 | H19: =H18/H10 -> 0.5376297 | I19: =I18/I10 -> 0.54624886 | J19: =J18/J10 -> 0.55342609 | K19: =K18/K10 -> 0.55489134
A20: Gross margin % ex-amortization | C20: =1-C15/C10 -> 0.51061396 | D20: =1-D15/D10 -> 0.50273369 | E20: =1-E15/E10 -> 0.53019197 | F20: =1-F15/F10 -> 0.52492855 | G20: =1-G15/G10 -> 0.545 | H20: =1-H15/H10 -> 0.55 | I20: =1-I15/I10 -> 0.555 | J20: =1-J15/J10 -> 0.56 | K20: =1-K15/K10 -> 0.56
A22: Operating expenses
A23: R&D % of revenue (driver) | C23: =C24/C10 -> 0.21206729 | D23: =D24/D10 -> 0.25890653 | E23: =E24/E10 -> 0.25037813 | F23: =F24/F10 -> 0.23358065 | G23: =Scenarios!G69 -> 0.215 | H23: =Scenarios!H69 -> 0.185 | I23: =Scenarios!I69 -> 0.17 | J23: =Scenarios!J69 -> 0.16 | K23: =Scenarios!K69 -> 0.155
A24: Research and development | C24: 5005 | D24: 5872 | E24: 6456 | F24: 8091 | G24: =G10*G23 -> 10637.233 | H24: =H10*H23 -> 12786.671 | I24: =I10*I23 -> 14860.918 | J24: =J10*J23 -> 16428.572 | K24: =K10*K23 -> 17749.257
A25: MG&A % of revenue (driver) | C25: =C26/C10 -> 0.094657006 | D25: =D26/D10 -> 0.10220459 | E25: =E26/E10 -> 0.10606942 | F25: =F26/F10 -> 0.11963394 | G25: =Scenarios!G75 -> 0.115 | H25: =Scenarios!H75 -> 0.1 | I25: =Scenarios!I75 -> 0.09 | J25: =Scenarios!J75 -> 0.085 | K25: =Scenarios!K75 -> 0.08
A26: Marketing, general & administrative (net of licensing gain) | B26: FY22/23 net of 102/34 licensing gain | C26: 2234 | D26: 2318 | E26: 2735 | F26: 4144 | G26: =G10*G25 -> 5689.6825 | H26: =H10*H25 -> 6911.714 | I26: =I10*I25 -> 7867.545 | J26: =J10*J25 -> 8727.6788 | K26: =K10*K25 -> 9160.9067
A27: Amortization of acquisition-related intangibles (opex) | C27: 2100 | D27: 1869 | E27: 1448 | F27: 1223 | G27: =G70-G16 -> 1155 | H27: =H70-H16 -> 1045 | I27: =I70-I16 -> 935 | J27: =J70-J16 -> 825 | K27: =K70-K16 -> 715
A28: Restructuring charges | C28: 0 | D28: 0 | E28: 186 | F28: 0 | G28: 0 | H28: 0 | I28: 0 | J28: 0 | K28: 0
A29: Total operating expenses | C29: =C24+C26+C27+C28 -> 9339 | D29: =D24+D26+D27+D28 -> 10059 | E29: =E24+E26+E27+E28 -> 10825 | F29: =F24+F26+F27+F28 -> 13458 | G29: =G24+G26+G27+G28 -> 17481.915 | H29: =H24+H26+H27+H28 -> 20743.385 | I29: =I24+I26+I27+I28 -> 23663.463 | J29: =J24+J26+J27+J28 -> 25981.251 | K29: =K24+K26+K27+K28 -> 27625.163
A30: Opex % of revenue | C30: =C29/C10 -> 0.39570357 | D30: =D29/D10 -> 0.44351852 | E30: =E29/E10 -> 0.41981772 | F30: =F29/F10 -> 0.38852161 | G30: =G29/G10 -> 0.35334489 | H30: =H29/H10 -> 0.30011926 | I30: =I29/I10 -> 0.27069584 | J30: =J29/J10 -> 0.25303478 | K30: =K29/K10 -> 0.24124392
A32: Operating income (EBIT) | C32: =C18-C29 -> 1264 | D32: =D18-D29 -> 401 | E32: =E18-E29 -> 1900 | F32: =F18-F29 -> 3694 | G32: =G18-G29 -> 8537.2325 | H32: =H18-H29 -> 16416.042 | I32: =I18-I29 -> 24088.064 | J32: =J18-J29 -> 30843.751 | K32: =K18-K29 -> 35916.183
A33: Operating margin % | C33: =C32/C10 -> 0.053557053 | D33: =D32/D10 -> 0.017680776 | E33: =E32/E10 -> 0.073686252 | F33: =F32/F10 -> 0.1066428 | G33: =G32/G10 -> 0.17255475 | H33: =H32/H10 -> 0.23751044 | I33: =I32/I10 -> 0.27555302 | J33: =J32/J10 -> 0.3003913 | K33: =K32/K10 -> 0.31364741
A34: D&A (ex-acquired intangibles) % of revenue | C34: =C35/C10 -> 0.0265243 | D34: =D35/D10 -> 0.028306878 | E34: =E35/E10 -> 0.026022882 | F34: =F35/F10 -> 0.021651895 | G34: 0.02 | H34: 0.02 | I34: 0.02 | J34: 0.02 | K34: 0.02
A35: Depreciation & amortization (ex-acquired intangibles) | B35: FY22 = 4,174 total less 3,548 intangibles | C35: 626 | D35: 642 | E35: 671 | F35: 750 | G35: =G10*G34 -> 989.51 | H35: =H10*H34 -> 1382.3428 | I35: =I10*I34 -> 1748.3433 | J35: =J10*J34 -> 2053.5715 | K35: =K10*K34 -> 2290.2267
A36: Amortization of acquired intangibles (total) | C36: =C16+C27 -> 3548 | D36: =D16+D27 -> 2811 | E36: =E16+E27 -> 2394 | F36: =F16+F27 -> 2254 | G36: =G16+G27 -> 2100 | H36: =H16+H27 -> 1900 | I36: =I16+I27 -> 1700 | J36: =J16+J27 -> 1500 | K36: =K16+K27 -> 1300
A37: EBITDA | C37: =C32+C35+C36 -> 5438 | D37: =D32+D35+D36 -> 3854 | E37: =E32+E35+E36 -> 4965 | F37: =F32+F35+F36 -> 6698 | G37: =G32+G35+G36 -> 11626.743 | H37: =H32+H35+H36 -> 19698.385 | I37: =I32+I35+I36 -> 27536.408 | J37: =J32+J35+J36 -> 34397.322 | K37: =K32+K35+K36 -> 39506.41
A38: EBITDA margin % | C38: =C37/C10 -> 0.23041397 | D38: =D37/D10 -> 0.16992945 | E38: =E37/E10 -> 0.19255381 | F38: =F37/F10 -> 0.19336586 | G38: =G37/G10 -> 0.235 | H38: =H37/H10 -> 0.285 | I38: =I37/I10 -> 0.315 | J38: =J37/J10 -> 0.335 | K38: =K37/K10 -> 0.345
A39: Stock-based compensation % of revenue | C39: =C40/C10 -> 0.045803144 | D39: =D40/D10 -> 0.061022928 | E39: =E40/E10 -> 0.054566608 | F39: =F40/F10 -> 0.047287739 | G39: 0.04 | H39: 0.035 | I39: 0.032 | J39: 0.03 | K39: 0.03
A40: Stock-based compensation (memo) | C40: 1081 | D40: 1384 | E40: 1407 | F40: 1638 | G40: =G10*G39 -> 1979.02 | H40: =H10*H39 -> 2419.0999 | I40: =I10*I39 -> 2797.3493 | J40: =J10*J39 -> 3080.3572 | K40: =K10*K39 -> 3435.34
A41: Adjusted EBITDA (EBITDA + SBC + restructuring) | C41: =C37+C40+C28 -> 6519 | D41: =D37+D40+D28 -> 5238 | E41: =E37+E40+E28 -> 6558 | F41: =F37+F40+F28 -> 8336 | G41: =G37+G40+G28 -> 13605.763 | H41: =H37+H40+H28 -> 22117.485 | I41: =I37+I40+I28 -> 30333.757 | J41: =J37+J40+J28 -> 37477.679 | K41: =K37+K40+K28 -> 42941.75
A42: Approx. non-GAAP operating income (EBIT + amort + SBC + restr.) | B42: excl. inventory/acq. adj. | C42: =C32+C36+C40+C28 -> 5893 | D42: =D32+D36+D40+D28 -> 4596 | E42: =E32+E36+E40+E28 -> 5887 | F42: =F32+F36+F40+F28 -> 7586 | G42: =G32+G36+G40+G28 -> 12616.253 | H42: =H32+H36+H40+H28 -> 20735.142 | I42: =I32+I36+I40+I28 -> 28585.414 | J42: =J32+J36+J40+J28 -> 35424.108 | K42: =K32+K36+K40+K28 -> 40651.523
A43: Approx. non-GAAP operating margin % | C43: =C42/C10 -> 0.24969281 | D43: =D42/D10 -> 0.2026455 | E43: =E42/E10 -> 0.22831103 | F43: =F42/F10 -> 0.2190017 | G43: =G42/G10 -> 0.255 | H43: =H42/H10 -> 0.3 | I43: =I42/I10 -> 0.327 | J43: =J42/J10 -> 0.345 | K43: =K42/K10 -> 0.355
A45: Below the line
...

Sheet Cash Flow
A1: AMD - Cash Flow Statement
A2: USD millions. Historical lines condensed from reported statements; projections derived from Income Statement and Balance Sheet.
A4: USD millions | C4: FY2022A | D4: FY2023A | E4: FY2024A | F4: FY2025A | G4: FY2026E | H4: FY2027E | I4: FY2028E | J4: FY2029E | K4: FY2030E
A5: OPERATING ACTIVITIES
A6: Net income | C6: ='Income Statement'!C56 -> 1320 | D6: ='Income Statement'!D56 -> 854 | E6: ='Income Statement'!E56 -> 1641 | F6: ='Income Statement'!F56 -> 4335 | G6: ='Income Statement'!G56 -> 7666.5751 | H6: ='Income Statement'!H56 -> 14233.881 | I6: ='Income Statement'!I56 -> 20921.51 | J6: ='Income Statement'!J56 -> 26952.504 | K6: ='Income Statement'!K56 -> 31649.779
A7: (Income) loss from discontinued operations | C7: =-'Income Statement'!C55 -> 0 | D7: =-'Income Statement'!D55 -> 0 | E7: =-'Income Statement'!E55 -> 0 | F7: =-'Income Statement'!F55 -> -66 | G7: =-'Income Statement'!G55 -> 0 | H7: =-'Income Statement'!H55 -> 0 | I7: =-'Income Statement'!I55 -> 0 | J7: =-'Income Statement'!J55 -> 0 | K7: =-'Income Statement'!K55 -> 0
A8: Depreciation & amortization (ex-intangibles) | C8: ='Income Statement'!C35 -> 626 | D8: ='Income Statement'!D35 -> 642 | E8: ='Income Statement'!E35 -> 671 | F8: ='Income Statement'!F35 -> 750 | G8: ='Income Statement'!G35 -> 989.51 | H8: ='Income Statement'!H35 -> 1382.3428 | I8: ='Income Statement'!I35 -> 1748.3433 | J8: ='Income Statement'!J35 -> 2053.5715 | K8: ='Income Statement'!K35 -> 2290.2267
A9: Amortization of acquisition-related intangibles | B9: FY24 CF shows 2,393 | C9: 3548 | D9: 2811 | E9: 2393 | F9: 2254 | G9: ='Income Statement'!G36 -> 2100 | H9: ='Income Statement'!H36 -> 1900 | I9: ='Income Statement'!I36 -> 1700 | J9: ='Income Statement'!J36 -> 1500 | K9: ='Income Statement'!K36 -> 1300
A10: Stock-based compensation | C10: ='Income Statement'!C40 -> 1081 | D10: ='Income Statement'!D40 -> 1384 | E10: ='Income Statement'!E40 -> 1407 | F10: ='Income Statement'!F40 -> 1638 | G10: ='Income Statement'!G40 -> 1979.02 | H10: ='Income Statement'!H40 -> 2419.0999 | I10: ='Income Statement'!I40 -> 2797.3493 | J10: ='Income Statement'!J40 -> 3080.3572 | K10: ='Income Statement'!K40 -> 3435.34
A11: Deferred income taxes | C11: -1505 | D11: -1019 | E11: -1163 | F11: 248 | G11: 0 | H11: 0 | I11: 0 | J11: 0 | K11: 0
A12: Other non-cash items | C12: 341 | D12: 44 | E12: 190 | F12: -288 | G12: 0 | H12: 0 | I12: 0 | J12: 0 | K12: 0
A13: Changes in working capital
A14: Accounts receivable | C14: -1091 | D14: -1339 | E14: -1865 | F14: -121 | G14: =-('Balance Sheet'!G16-'Balance Sheet'!F16) -> -2089.0575 | H14: =-('Balance Sheet'!H16-'Balance Sheet'!G16) -> -3336.3882 | I14: =-('Balance Sheet'!I16-'Balance Sheet'!H16) -> -3108.4978 | J14: =-('Balance Sheet'!J16-'Balance Sheet'!I16) -> -2592.3485 | K14: =-('Balance Sheet'!K16-'Balance Sheet'!J16) -> -2009.9483
A15: Inventories | C15: -1401 | D15: -580 | E15: -1458 | F15: -2189 | G15: =-('Balance Sheet'!G17-'Balance Sheet'!F17) -> -1331.2408 | H15: =-('Balance Sheet'!H17-'Balance Sheet'!G17) -> -2252.5024 | I15: =-('Balance Sheet'!I17-'Balance Sheet'!H17) -> -1818.3936 | J15: =-('Balance Sheet'!J17-'Balance Sheet'!I17) -> -1531.0925 | K15: =-('Balance Sheet'!K17-'Balance Sheet'!J17) -> -1021.4926
A16: Prepaid expenses & other assets | C16: -1210 | D16: -383 | E16: 339 | F16: -11 | G16: =-('Balance Sheet'!G18-'Balance Sheet'!F18) -> -561.1525 | H16: =-('Balance Sheet'!H18-'Balance Sheet'!G18) -> -1080.2902 | I16: =-('Balance Sheet'!I18-'Balance Sheet'!H18) -> -1006.5015 | J16: =-('Balance Sheet'!J18-'Balance Sheet'!I18) -> -839.37735 | K16: =-('Balance Sheet'!K18-'Balance Sheet'!J18) -> -650.8018
A17: Accounts payable (incl. related parties) | C17: 1310 | D17: -526 | E17: 3 | F17: 410 | G17: ='Balance Sheet'!G29-'Balance Sheet'!F29 -> 1388.2457 | H17: ='Balance Sheet'!H29-'Balance Sheet'!G29 -> 1647.6582 | I17: ='Balance Sheet'!I29-'Balance Sheet'!H29 -> 1495.4927 | J17: ='Balance Sheet'!J29-'Balance Sheet'!I29 -> 1203.9872 | K17: ='Balance Sheet'!K29-'Balance Sheet'!J29 -> 998.49043
A18: Accrued & other liabilities | C18: 546 | D18: -221 | E18: 883 | F18: -467 | G18: ='Balance Sheet'!G30-'Balance Sheet'!F30+'Balance Sheet'!G32-'Balance Sheet'!F32 -> 2115.6535 | H18: ='Balance Sheet'!H30-'Balance Sheet'!G30+'Balance Sheet'!H32-'Balance Sheet'!G32 -> 3083.7375 | I18: ='Balance Sheet'!I30-'Balance Sheet'!H30+'Balance Sheet'!I32-'Balance Sheet'!H32 -> 2873.1043 | J18: ='Balance Sheet'!J30-'Balance Sheet'!I30+'Balance Sheet'!J32-'Balance Sheet'!I32 -> 2396.0408 | K18: ='Balance Sheet'!K30-'Balance Sheet'!J30+'Balance Sheet'!K32-'Balance Sheet'!J32 -> 1857.7433
A19: Cash from operations - continuing | C19: =SUM(C6:C12)+SUM(C14:C18) -> 3565 | D19: =SUM(D6:D12)+SUM(D14:D18) -> 1667 | E19: =SUM(E6:E12)+SUM(E14:E18) -> 3041 | F19: =SUM(F6:F12)+SUM(F14:F18) -> 6493 | G19: =SUM(G6:G12)+SUM(G14:G18) -> 12257.553 | H19: =SUM(H6:H12)+SUM(H14:H18) -> 17997.539 | I19: =SUM(I6:I12)+SUM(I14:I18) -> 25602.407 | J19: =SUM(J6:J12)+SUM(J14:J18) -> 32223.642 | K19: =SUM(K6:K12)+SUM(K14:K18) -> 37849.337
A20: Cash from operations - discontinued | C20: 0 | D20: 0 | E20: 0 | F20: 1216 | G20: 0 | H20: 0 | I20: 0 | J20: 0 | K20: 0
A21: CASH FROM OPERATIONS | C21: =C19+C20 -> 3565 | D21: =D19+D20 -> 1667 | E21: =E19+E20 -> 3041 | F21: =F19+F20 -> 7709 | G21: =G19+G20 -> 12257.553 | H21: =H19+H20 -> 17997.539 | I21: =I19+I20 -> 25602.407 | J21: =J19+J20 -> 32223.642 | K21: =K19+K20 -> 37849.337
A23: INVESTING ACTIVITIES
A24: Capital expenditures | C24: -450 | D24: -546 | E24: -636 | F24: -974 | G24: =-'Income Statement'!G10*Scenarios!G81 -> -2473.775 | H24: =-'Income Statement'!H10*Scenarios!H81 -> -3110.2713 | I24: =-'Income Statement'!I10*Scenarios!I81 -> -3496.6867 | J24: =-'Income Statement'!J10*Scenarios!J81 -> -3593.7501 | K24: =-'Income Statement'!K10*Scenarios!K81 -> -4007.8967
A25: Net (purchases) / maturities of ST investments | C25: 1643 | D25: -735 | E25: 539 | F25: -3625 | G25: =-('Balance Sheet'!G15-'Balance Sheet'!F15) -> 0 | H25: =-('Balance Sheet'!H15-'Balance Sheet'!G15) -> 0 | I25: =-('Balance Sheet'!I15-'Balance Sheet'!H15) -> 0 | J25: =-('Balance Sheet'!J15-'Balance Sheet'!I15) -> 0 | K25: =-('Balance Sheet'!K15-'Balance Sheet'!J15) -> 0
A26: Acquisitions, net (FY22 incl. +2,366 Xilinx cash acquired) | C26: 822 | D26: -131 | E26: -548 | F26: -1760 | G26: 0 | H26: 0 | I26: 0 | J26: 0 | K26: 0
A27: Strategic / LT investments & other | B27: FY26E incl. post-Q2 commitments | C27: -16 | D27: -11 | E27: -456 | F27: -492 | G27: -3000 | H27: -1500 | I27: -1000 | J27: -1000 | K27: -1000
A28: Investing - discontinued ops (ZT divestiture) | C28: 0 | D28: 0 | E28: 0 | F28: 1318 | G28: 0 | H28: 0 | I28: 0 | J28: 0 | K28: 0
A29: CASH FROM INVESTING | C29: =SUM(C24:C28) -> 1999 | D29: =SUM(D24:D28) -> -1423 | E29: =SUM(E24:E28) -> -1101 | F29: =SUM(F24:F28) -> -5533 | G29: =SUM(G24:G28) -> -5473.775 | H29: =SUM(H24:H28) -> -4610.2713 | I29: =SUM(I24:I28) -> -4496.6867 | J29: =SUM(J24:J28) -> -4593.7501 | K29: =SUM(K24:K28) -> -5007.8967
A31: FREE CASH FLOW (CFO continuing + capex) | B31: AMD definition | C31: =C19+C24 -> 3115 | D31: =D19+D24 -> 1121 | E31: =E19+E24 -> 2405 | F31: =F19+F24 -> 5519 | G31: =G19+G24 -> 9783.7785 | H31: =H19+H24 -> 14887.267 | I31: =I19+I24 -> 22105.721 | J31: =J19+J24 -> 28629.892 | K31: =K19+K24 -> 33841.44
A32: FCF margin % | C32: =C31/'Income Statement'!C10 -> 0.13198593 | D32: =D31/'Income Statement'!D10 -> 0.049426808 | E32: =E31/'Income Statement'!E10 -> 0.093271282 | F32: =F31/'Income Statement'!F10 -> 0.15932908 | G32: =G31/'Income Statement'!G10 -> 0.19774997 | H32: =H31/'Income Statement'!H10 -> 0.21539183 | I32: =I31/'Income Statement'!I10 -> 0.2528762 | J32: =J31/'Income Statement'!J10 -> 0.27883025 | K32: =K31/'Income Statement'!K10 -> 0.29552918
A34: FINANCING ACTIVITIES
A35: Debt issuance | C35: 991 | D35: 0 | E35: 0 | F35: 2441 | G35: 0 | H35: 0 | I35: 0 | J35: 0 | K35: 0
A36: Debt repayment | C36: -312 | D36: 0 | E36: -750 | F36: -950 | G36: 0 | H36: 0 | I36: 0 | J36: 0 | K36: 0
A37: Proceeds from employee equity plans | C37: 167 | D37: 268 | E37: 279 | F37: 285 | G37: 300 | H37: 300 | I37: 300 | J37: 300 | K37: 300
A38: Repurchases of common stock | C38: -3702 | D38: -985 | E38: -862 | F38: -1316 | G38: =-MAX(0,G31)*G49 -> -4891.8892 | H38: =-MAX(0,H31)*H49 -> -7443.6336 | I38: =-MAX(0,I31)*I49 -> -11052.86 | J38: =-MAX(0,J31)*J49 -> -14314.946 | K38: =-MAX(0,K31)*K49 -> -16920.72
A39: Tax withholding on employee equity plans | C39: -406 | D39: -427 | E39: -728 | F39: -607 | G39: -650 | H39: -650 | I39: -650 | J39: -650 | K39: -650
A40: Other financing (FY25: contingent consideration) | C40: -2 | D40: -2 | E40: -1 | F40: -284 | G40: 0 | H40: 0 | I40: 0 | J40: 0 | K40: 0
A41: CASH FROM FINANCING | C41: =SUM(C35:C40) -> -3264 | D41: =SUM(D35:D40) -> -1146 | E41: =SUM(E35:E40) -> -2062 | F41: =SUM(F35:F40) -> -431 | G41: =SUM(G35:G40) -> -5241.8892 | H41: =SUM(H35:H40) -> -7793.6336 | I41: =SUM(I35:I40) -> -11402.86 | J41: =SUM(J35:J40) -> -14664.946 | K41: =SUM(K35:K40) -> -17270.72
A43: NET CHANGE IN CASH | C43: =C21+C29+C41 -> 2300 | D43: =D21+D29+D41 -> -902 | E43: =E21+E29+E41 -> -122 | F43: =F21+F29+F41 -> 1745 | G43: =G21+G29+G41 -> 1541.8892 | H43: =H21+H29+H41 -> 5593.6336 | I43: =I21+I29+I41 -> 9702.8603 | J43: =J21+J29+J41 -> 12964.946 | K43: =K21+K29+K41 -> 15570.72
A44: Beginning cash (incl. restricted, hist.) | B44: FY26E starts from BS cash | C44: 2535 | D44: =C45 -> 4835 | E44: =D45 -> 3933 | F44: =E45 -> 3811 | G44: ='Balance Sheet'!F14 -> 5539 | H44: =G45 -> 7080.8892 | I44: =H45 -> 12674.523 | J44: =I45 -> 22377.383 | K44: =J45 -> 35342.329
A45: Ending cash | C45: =C44+C43 -> 4835 | D45: =D44+D43 -> 3933 | E45: =E44+E43 -> 3811 | F45: =F44+F43 -> 5556 | G45: =G44+G43 -> 7080.8892 | H45: =H44+H43 -> 12674.523 | I45: =I44+I43 -> 22377.383 | J45: =J44+J43 -> 35342.329 | K45: =K44+K43 -> 50913.049
...

Sheet Balance Sheet
A1: AMD - Balance Sheet
A2: USD millions, fiscal year-end. FY2022-FY2023 related-party receivables/payables, ROU assets and equity-method investments folded into 'other' lines.
A4: USD millions | C4: FY2022A | D4: FY2023A | E4: FY2024A | F4: FY2025A | G4: FY2026E | H4: FY2027E | I4: FY2028E | J4: FY2029E | K4: FY2030E
A5: Working-capital drivers
A6: DSO (receivables / revenue x 365) | C6: =C16/'Income Statement'!C10*365 -> 63.810432 | D6: =D16/'Income Statement'!D10*365 -> 69.57209 | E6: =E16/'Income Statement'!E10*365 -> 87.65096 | F6: =F16/'Income Statement'!F10*365 -> 66.54277 | G6: 62 | H6: 62 | I6: 62 | J6: 62 | K6: 62
A7: DIO (inventory / cost of sales ex-amort. x 365) | C7: =C17/'Income Statement'!C15*365 -> 119.17013 | D7: =D17/'Income Statement'!D15*365 -> 140.8153 | E7: =E17/'Income Statement'!E15*365 -> 172.76787 | F7: =F17/'Income Statement'!F15*365 -> 175.66845 | G7: 150 | H7: 135 | I7: 125 | J7: 120 | K7: 115
A8: DPO (payables / cost of sales ex-amort. x 365) | C8: =C29/'Income Statement'!C15*365 -> 78.783117 | D8: =D29/'Income Statement'!D15*365 -> 66.507803 | E8: =E29/'Income Statement'!E15*365 -> 74.301634 | F8: =F29/'Income Statement'!F15*365 -> 64.966274 | G8: 70 | H8: 70 | I8: 70 | J8: 70 | K8: 70
A9: Prepaid & other current assets % revenue | C9: =C18/'Income Statement'!C10 -> 0.053684166 | D9: =D18/'Income Statement'!D10 -> 0.10233686 | E9: =E18/'Income Statement'!E10 -> 0.077215435 | F9: =F18/'Income Statement'!F10 -> 0.062357458 | G9: 0.055 | H9: 0.055 | I9: 0.055 | J9: 0.055 | K9: 0.055
A10: Accrued liabilities % revenue | C10: =C30/'Income Statement'!C10 -> 0.14999364 | D10: =D30/'Income Statement'!D10 -> 0.15189594 | E10: =E30/'Income Statement'!E10 -> 0.16521233 | F10: =F30/'Income Statement'!F10 -> 0.15156327 | G10: 0.145 | H10: 0.145 | I10: 0.145 | J10: 0.145 | K10: 0.145
A11: Other current liabilities % revenue | C11: =C32/'Income Statement'!C10 -> 0.014236685 | D11: =D32/'Income Statement'!D10 -> 0.019312169 | E11: =E32/'Income Statement'!E10 -> 0.021524142 | F11: =F32/'Income Statement'!F10 -> 0.011605416 | G11: 0.012 | H11: 0.012 | I11: 0.012 | J11: 0.012 | K11: 0.012
A13: ASSETS
A14: Cash and cash equivalents | C14: 4835 | D14: 3933 | E14: 3787 | F14: 5539 | G14: ='Cash Flow'!G45 -> 7080.8892 | H14: ='Cash Flow'!H45 -> 12674.523 | I14: ='Cash Flow'!I45 -> 22377.383 | J14: ='Cash Flow'!J45 -> 35342.329 | K14: ='Cash Flow'!K45 -> 50913.049
A15: Short-term investments | C15: 1020 | D15: 1840 | E15: 1345 | F15: 5013 | G15: =F15 -> 5013 | H15: =G15 -> 5013 | I15: =H15 -> 5013 | J15: =I15 -> 5013 | K15: =J15 -> 5013
A16: Accounts receivable, net | B16: FY23 as recast | C16: 4126 | D16: 4323 | E16: 6192 | F16: 6315 | G16: ='Income Statement'!G10*G6/365 -> 8404.0575 | H16: ='Income Statement'!H10*H6/365 -> 11740.446 | I16: ='Income Statement'!I10*I6/365 -> 14848.943 | J16: ='Income Statement'!J10*J6/365 -> 17441.292 | K16: ='Income Statement'!K10*K6/365 -> 19451.24
A17: Inventories | C17: 3771 | D17: 4351 | E17: 5734 | F17: 7920 | G17: ='Income Statement'!G15*G7/365 -> 9251.2408 | H17: ='Income Statement'!H15*H7/365 -> 11503.743 | I17: ='Income Statement'!I15*I7/365 -> 13322.137 | J17: ='Income Statement'!J15*J7/365 -> 14853.229 | K17: ='Income Statement'!K15*K7/365 -> 15874.722
A18: Prepaid expenses & other current assets | C18: 1267 | D18: 2321 | E18: 1991 | F18: 2160 | G18: ='Income Statement'!G10*G9 -> 2721.1525 | H18: ='Income Statement'!H10*H9 -> 3801.4427 | I18: ='Income Statement'!I10*I9 -> 4807.9442 | J18: ='Income Statement'!J10*J9 -> 5647.3215 | K18: ='Income Statement'!K10*K9 -> 6298.1233
A19: Total current assets | C19: =SUM(C14:C18) -> 15019 | D19: =SUM(D14:D18) -> 16768 | E19: =SUM(E14:E18) -> 19049 | F19: =SUM(F14:F18) -> 26947 | G19: =SUM(G14:G18) -> 32470.34 | H19: =SUM(H14:H18) -> 44733.154 | I19: =SUM(I14:I18) -> 60369.408 | J19: =SUM(J14:J18) -> 78297.172 | K19: =SUM(K14:K18) -> 97550.135
A20: Property and equipment, net | C20: 1513 | D20: 1589 | E20: 1802 | F20: 2312 | G20: =F20-'Cash Flow'!G24-'Income Statement'!G35 -> 3796.265 | H20: =G20-'Cash Flow'!H24-'Income Statement'!H35 -> 5524.1935 | I20: =H20-'Cash Flow'!I24-'Income Statement'!I35 -> 7272.5368 | J20: =I20-'Cash Flow'!J24-'Income Statement'!J35 -> 8812.7154 | K20: =J20-'Cash Flow'!K24-'Income Statement'!K35 -> 10530.385
A21: Goodwill | C21: 24177 | D21: 24262 | E21: 24839 | F21: 25126 | G21: =F21 -> 25126 | H21: =G21 -> 25126 | I21: =H21 -> 25126 | J21: =I21 -> 25126 | K21: =J21 -> 25126
A22: Acquisition-related intangibles, net | C22: 24118 | D22: 21363 | E22: 18930 | F22: 16705 | G22: =F22-'Income Statement'!G36 -> 14605 | H22: =G22-'Income Statement'!H36 -> 12705 | I22: =H22-'Income Statement'!I36 -> 11005 | J22: =I22-'Income Statement'!J36 -> 9505 | K22: =J22-'Income Statement'!K36 -> 8205
A23: Deferred tax assets | C23: 58 | D23: 366 | E23: 688 | F23: 384 | G23: =F23 -> 384 | H23: =G23 -> 384 | I23: =H23 -> 384 | J23: =I23 -> 384 | K23: =J23 -> 384
A24: Other non-current assets (incl. ROU, equity-method, LT investments) | C24: 2695 | D24: 3537 | E24: 3918 | F24: 5452 | G24: =F24-'Cash Flow'!G27 -> 8452 | H24: =G24-'Cash Flow'!H27 -> 9952 | I24: =H24-'Cash Flow'!I27 -> 10952 | J24: =I24-'Cash Flow'!J27 -> 11952 | K24: =J24-'Cash Flow'!K27 -> 12952
A25: Total non-current assets | C25: =SUM(C20:C24) -> 52561 | D25: =SUM(D20:D24) -> 51117 | E25: =SUM(E20:E24) -> 50177 | F25: =SUM(F20:F24) -> 49979 | G25: =SUM(G20:G24) -> 52363.265 | H25: =SUM(H20:H24) -> 53691.194 | I25: =SUM(I20:I24) -> 54739.537 | J25: =SUM(J20:J24) -> 55779.715 | K25: =SUM(K20:K24) -> 57197.385
A26: TOTAL ASSETS | C26: =C19+C25 -> 67580 | D26: =D19+D25 -> 67885 | E26: =E19+E25 -> 69226 | F26: =F19+F25 -> 76926 | G26: =G19+G25 -> 84833.605 | H26: =H19+H25 -> 98424.348 | I26: =I19+I25 -> 115108.94 | J26: =J19+J25 -> 134076.89 | K26: =K19+K25 -> 154747.52
A28: LIABILITIES
A29: Accounts payable | C29: 2493 | D29: 2055 | E29: 2466 | F29: 2929 | G29: ='Income Statement'!G15*G8/365 -> 4317.2457 | H29: ='Income Statement'!H15*H8/365 -> 5964.9039 | I29: ='Income Statement'!I15*I8/365 -> 7460.3966 | J29: ='Income Statement'!J15*J8/365 -> 8664.3837 | K29: ='Income Statement'!K15*K8/365 -> 9662.8742
A30: Accrued liabilities (incl. related-party payables) | C30: 3540 | D30: 3445 | E30: 4260 | F30: 5250 | G30: ='Income Statement'!G10*G10 -> 7173.9475 | H30: ='Income Statement'!H10*H10 -> 10021.985 | I30: ='Income Statement'!I10*I10 -> 12675.489 | J30: ='Income Statement'!J10*J10 -> 14888.393 | K30: ='Income Statement'!K10*K10 -> 16604.143
A31: Current portion of long-term debt | C31: 0 | D31: 751 | E31: 0 | F31: 874 | G31: =F31 -> 874 | H31: =G31 -> 874 | I31: =H31 -> 874 | J31: =I31 -> 874 | K31: =J31 -> 874
A32: Other current liabilities | C32: 336 | D32: 438 | E32: 555 | F32: 402 | G32: ='Income Statement'!G10*G11 -> 593.706 | H32: ='Income Statement'!H10*H11 -> 829.40568 | I32: ='Income Statement'!I10*I11 -> 1049.006 | J32: ='Income Statement'!J10*J11 -> 1232.1429 | K32: ='Income Statement'!K10*K11 -> 1374.136
A33: Total current liabilities | C33: =SUM(C29:C32) -> 6369 | D33: =SUM(D29:D32) -> 6689 | E33: =SUM(E29:E32) -> 7281 | F33: =SUM(F29:F32) -> 9455 | G33: =SUM(G29:G32) -> 12958.899 | H33: =SUM(H29:H32) -> 17690.295 | I33: =SUM(I29:I32) -> 22058.892 | J33: =SUM(J29:J32) -> 25658.92 | K33: =SUM(K29:K32) -> 28515.154
A34: Long-term debt, net of current portion | C34: 2467 | D34: 1717 | E34: 1721 | F34: 2348 | G34: =F34+'Cash Flow'!G35+'Cash Flow'!G36 -> 2348 | H34: =G34+'Cash Flow'!H35+'Cash Flow'!H36 -> 2348 | I34: =H34+'Cash Flow'!I35+'Cash Flow'!I36 -> 2348 | J34: =I34+'Cash Flow'!J35+'Cash Flow'!J36 -> 2348 | K34: =J34+'Cash Flow'!K35+'Cash Flow'!K36 -> 2348
A35: Long-term operating lease liabilities | C35: 396 | D35: 535 | E35: 491 | F35: 625 | G35: =F35 -> 625 | H35: =G35 -> 625 | I35: =H35 -> 625 | J35: =I35 -> 625 | K35: =J35 -> 625
A36: Deferred tax liabilities | C36: 1934 | D36: 1202 | E36: 349 | F36: 313 | G36: =F36 -> 313 | H36: =G36 -> 313 | I36: =H36 -> 313 | J36: =I36 -> 313 | K36: =J36 -> 313
A37: Other long-term liabilities | C37: 1664 | D37: 1850 | E37: 1816 | F37: 1186 | G37: =F37 -> 1186 | H37: =G37 -> 1186 | I37: =H37 -> 1186 | J37: =I37 -> 1186 | K37: =J37 -> 1186
A38: Total non-current liabilities | C38: =SUM(C34:C37) -> 6461 | D38: =SUM(D34:D37) -> 5304 | E38: =SUM(E34:E37) -> 4377 | F38: =SUM(F34:F37) -> 4472 | G38: =SUM(G34:G37) -> 4472 | H38: =SUM(H34:H37) -> 4472 | I38: =SUM(I34:I37) -> 4472 | J38: =SUM(J34:J37) -> 4472 | K38: =SUM(K34:K37) -> 4472
A39: TOTAL LIABILITIES | C39: =C33+C38 -> 12830 | D39: =D33+D38 -> 11993 | E39: =E33+E38 -> 11658 | F39: =F33+F38 -> 13927 | G39: =G33+G38 -> 17430.899 | H39: =H33+H38 -> 22162.295 | I39: =I33+I38 -> 26530.892 | J39: =J33+J38 -> 30130.92 | K39: =K33+K38 -> 32987.154
A41: STOCKHOLDERS' EQUITY
A42: Common stock, par value | C42: 16 | D42: 17 | E42: 17 | F42: 17 | G42: =F42 -> 17 | H42: =G42 -> 17 | I42: =H42 -> 17 | J42: =I42 -> 17 | K42: =J42 -> 17
A43: Additional paid-in capital | C43: 58005 | D43: 59676 | E43: 61362 | F43: 63365 | G43: =F43+'Income Statement'!G40+'Cash Flow'!G37+'Cash Flow'!G39 -> 64994.02 | H43: =G43+'Income Statement'!H40+'Cash Flow'!H37+'Cash Flow'!H39 -> 67063.12 | I43: =H43+'Income Statement'!I40+'Cash Flow'!I37+'Cash Flow'!I39 -> 69510.469 | J43: =I43+'Income Statement'!J40+'Cash Flow'!J37+'Cash Flow'!J39 -> 72240.826 | K43: =J43+'Income Statement'!K40+'Cash Flow'!K37+'Cash Flow'!K39 -> 75326.166
A44: Treasury stock, at cost | C44: -3099 | D44: -4514 | E44: -6106 | F44: -7079 | G44: =F44+'Cash Flow'!G38 -> -11970.889 | H44: =G44+'Cash Flow'!H38 -> -19414.523 | I44: =H44+'Cash Flow'!I38 -> -30467.383 | J44: =I44+'Cash Flow'!J38 -> -44782.329 | K44: =J44+'Cash Flow'!K38 -> -61703.049
...

Sheet Scenarios
A1: AMD - Scenario Drivers (Bull / Base / Bear)
A2: Change the selector in C3 to switch the whole model. Live rows feed the Revenue Model, Income Statement and Cash Flow.
A3: Scenario selector (1 = Bull, 2 = Base, 3 = Bear) | C3: 2 | D3: =CHOOSE($C$3,"Bull","Base","Bear") -> Base
A4: Driver / case | G4: FY2026E | H4: FY2027E | I4: FY2028E | J4: FY2029E | K4: FY2030E
A5: Server CPU (EPYC) revenue growth
A6: Bull | G6: 0.45 | H6: 0.3 | I6: 0.2 | J6: 0.15 | K6: 0.12
A7: Base | G7: 0.4 | H7: 0.25 | I7: 0.15 | J7: 0.12 | K7: 0.1
A8: Bear | G8: 0.35 | H8: 0.12 | I8: 0.06 | J8: 0.05 | K8: 0.04
A9: Live (selected) | G9: =CHOOSE($C$3,G6,G7,G8) -> 0.4 | H9: =CHOOSE($C$3,H6,H7,H8) -> 0.25 | I9: =CHOOSE($C$3,I6,I7,I8) -> 0.15 | J9: =CHOOSE($C$3,J6,J7,J8) -> 0.12 | K9: =CHOOSE($C$3,K6,K7,K8) -> 0.1
A11: Data Center GPU (Instinct) revenue growth
A12: Bull | G12: 1.55 | H12: 1.2 | I12: 0.6 | J12: 0.35 | K12: 0.2
A13: Base | G13: 1.4 | H13: 0.9 | I13: 0.45 | J13: 0.25 | K13: 0.15
A14: Bear | G14: 1.25 | H14: 0.4 | I14: 0.15 | J14: 0.08 | K14: 0.05
A15: Live (selected) | G15: =CHOOSE($C$3,G12,G13,G14) -> 1.4 | H15: =CHOOSE($C$3,H12,H13,H14) -> 0.9 | I15: =CHOOSE($C$3,I12,I13,I14) -> 0.45 | J15: =CHOOSE($C$3,J12,J13,J14) -> 0.25 | K15: =CHOOSE($C$3,K12,K13,K14) -> 0.15
A17: DC networking, rack-scale & other growth
A18: Bull | G18: 1.75 | H18: 1.2 | I18: 0.7 | J18: 0.4 | K18: 0.25
A19: Base | G19: 1.5 | H19: 1 | I19: 0.5 | J19: 0.3 | K19: 0.2
A20: Bear | G20: 1 | H20: 0.5 | I20: 0.2 | J20: 0.1 | K20: 0.05
A21: Live (selected) | G21: =CHOOSE($C$3,G18,G19,G20) -> 1.5 | H21: =CHOOSE($C$3,H18,H19,H20) -> 1 | I21: =CHOOSE($C$3,I18,I19,I20) -> 0.5 | J21: =CHOOSE($C$3,J18,J19,J20) -> 0.3 | K21: =CHOOSE($C$3,K18,K19,K20) -> 0.2
A23: Client desktop CPU growth
A24: Bull | G24: 0.17 | H24: 0.1 | I24: 0.08 | J24: 0.07 | K24: 0.06
A25: Base | G25: 0.15 | H25: 0.06 | I25: 0.05 | J25: 0.05 | K25: 0.04
A26: Bear | G26: 0.12 | H26: -0.02 | I26: 0.02 | J26: 0.03 | K26: 0.03
A27: Live (selected) | G27: =CHOOSE($C$3,G24,G25,G26) -> 0.15 | H27: =CHOOSE($C$3,H24,H25,H26) -> 0.06 | I27: =CHOOSE($C$3,I24,I25,I26) -> 0.05 | J27: =CHOOSE($C$3,J24,J25,J26) -> 0.05 | K27: =CHOOSE($C$3,K24,K25,K26) -> 0.04
A29: Client notebook CPU growth
A30: Bull | G30: 0.17 | H30: 0.1 | I30: 0.08 | J30: 0.07 | K30: 0.06
A31: Base | G31: 0.15 | H31: 0.06 | I31: 0.05 | J31: 0.05 | K31: 0.04
A32: Bear | G32: 0.12 | H32: -0.02 | I32: 0.02 | J32: 0.03 | K32: 0.03
A33: Live (selected) | G33: =CHOOSE($C$3,G30,G31,G32) -> 0.15 | H33: =CHOOSE($C$3,H30,H31,H32) -> 0.06 | I33: =CHOOSE($C$3,I30,I31,I32) -> 0.05 | J33: =CHOOSE($C$3,J30,J31,J32) -> 0.05 | K33: =CHOOSE($C$3,K30,K31,K32) -> 0.04
A35: Gaming semi-custom SoC growth
A36: Bull | G36: -0.28 | H36: 0.1 | I36: 0.25 | J36: 0.12 | K36: 0
A37: Base | G37: -0.3 | H37: 0 | I37: 0.2 | J37: 0.1 | K37: -0.05
A38: Bear | G38: -0.32 | H38: -0.1 | I38: 0.05 | J38: 0.05 | K38: -0.1
A39: Live (selected) | G39: =CHOOSE($C$3,G36,G37,G38) -> -0.3 | H39: =CHOOSE($C$3,H36,H37,H38) -> 0 | I39: =CHOOSE($C$3,I36,I37,I38) -> 0.2 | J39: =CHOOSE($C$3,J36,J37,J38) -> 0.1 | K39: =CHOOSE($C$3,K36,K37,K38) -> -0.05
A41: Gaming Radeon discrete GPU growth
A42: Bull | G42: -0.06 | H42: 0.1 | I42: 0.08 | J42: 0.06 | K42: 0.05
A43: Base | G43: -0.08 | H43: 0.05 | I43: 0.04 | J43: 0.03 | K43: 0.03
A44: Bear | G44: -0.12 | H44: 0 | I44: 0 | J44: 0.02 | K44: 0.02
A45: Live (selected) | G45: =CHOOSE($C$3,G42,G43,G44) -> -0.08 | H45: =CHOOSE($C$3,H42,H43,H44) -> 0.05 | I45: =CHOOSE($C$3,I42,I43,I44) -> 0.04 | J45: =CHOOSE($C$3,J42,J43,J44) -> 0.03 | K45: =CHOOSE($C$3,K42,K43,K44) -> 0.03
A47: Embedded FPGA / adaptive SoC growth
...

Sheet DCF Inputs
A1: AMD - DCF Inputs (for Task 3 valuation)
A2: Unlevered FCF built from GAAP EBIT; SBC is treated as a real expense (not added back). USD millions.
A4: USD millions | C4: FY2022A | D4: FY2023A | E4: FY2024A | F4: FY2025A | G4: FY2026E | H4: FY2027E | I4: FY2028E | J4: FY2029E | K4: FY2030E
A5: Revenue | C5: ='Income Statement'!C10 -> 23601 | D5: ='Income Statement'!D10 -> 22680 | E5: ='Income Statement'!E10 -> 25785 | F5: ='Income Statement'!F10 -> 34639 | G5: ='Income Statement'!G10 -> 49475.5 | H5: ='Income Statement'!H10 -> 69117.14 | I5: ='Income Statement'!I10 -> 87417.167 | J5: ='Income Statement'!J10 -> 102678.57 | K5: ='Income Statement'!K10 -> 114511.33
A6: Revenue growth % | D6: =D5/C5-1 -> -0.03902377 | E6: =E5/D5-1 -> 0.13690476 | F6: =F5/E5-1 -> 0.34337793 | G6: =G5/F5-1 -> 0.42831779 | H6: =H5/G5-1 -> 0.3969973 | I6: =I5/H5-1 -> 0.26476829 | J6: =J5/I5-1 -> 0.17458134 | K6: =K5/J5-1 -> 0.11524079
A7: EBITDA | C7: ='Income Statement'!C37 -> 5438 | D7: ='Income Statement'!D37 -> 3854 | E7: ='Income Statement'!E37 -> 4965 | F7: ='Income Statement'!F37 -> 6698 | G7: ='Income Statement'!G37 -> 11626.743 | H7: ='Income Statement'!H37 -> 19698.385 | I7: ='Income Statement'!I37 -> 27536.408 | J7: ='Income Statement'!J37 -> 34397.322 | K7: ='Income Statement'!K37 -> 39506.41
A8: EBIT (GAAP operating income) | C8: ='Income Statement'!C32 -> 1264 | D8: ='Income Statement'!D32 -> 401 | E8: ='Income Statement'!E32 -> 1900 | F8: ='Income Statement'!F32 -> 3694 | G8: ='Income Statement'!G32 -> 8537.2325 | H8: ='Income Statement'!H32 -> 16416.042 | I8: ='Income Statement'!I32 -> 24088.064 | J8: ='Income Statement'!J32 -> 30843.751 | K8: ='Income Statement'!K32 -> 35916.183
A9: EBIT margin % | C9: =C8/C5 -> 0.053557053 | D9: =D8/D5 -> 0.017680776 | E9: =E8/E5 -> 0.073686252 | F9: =F8/F5 -> 0.1066428 | G9: =G8/G5 -> 0.17255475 | H9: =H8/H5 -> 0.23751044 | I9: =I8/I5 -> 0.27555302 | J9: =J8/J5 -> 0.3003913 | K9: =K8/K5 -> 0.31364741
A10: Tax rate % (projection: model rate; hist: 15% normalized) | C10: 0.15 | D10: 0.15 | E10: 0.15 | F10: 0.15 | G10: ='Income Statement'!G51 -> 0.13 | H10: ='Income Statement'!H51 -> 0.15 | I10: ='Income Statement'!I51 -> 0.15 | J10: ='Income Statement'!J51 -> 0.15 | K10: ='Income Statement'!K51 -> 0.15
A11: NOPAT | C11: =C8*(1-C10) -> 1074.4 | D11: =D8*(1-D10) -> 340.85 | E11: =E8*(1-E10) -> 1615 | F11: =F8*(1-F10) -> 3139.9 | G11: =G8*(1-G10) -> 7427.3923 | H11: =H8*(1-H10) -> 13953.636 | I11: =I8*(1-I10) -> 20474.855 | J11: =J8*(1-J10) -> 26217.188 | K11: =K8*(1-K10) -> 30528.756
A12: Add: D&A (ex-intangibles) | C12: ='Income Statement'!C35 -> 626 | D12: ='Income Statement'!D35 -> 642 | E12: ='Income Statement'!E35 -> 671 | F12: ='Income Statement'!F35 -> 750 | G12: ='Income Statement'!G35 -> 989.51 | H12: ='Income Statement'!H35 -> 1382.3428 | I12: ='Income Statement'!I35 -> 1748.3433 | J12: ='Income Statement'!J35 -> 2053.5715 | K12: ='Income Statement'!K35 -> 2290.2267
A13: Add: amortization of acquired intangibles | C13: ='Income Statement'!C36 -> 3548 | D13: ='Income Statement'!D36 -> 2811 | E13: ='Income Statement'!E36 -> 2394 | F13: ='Income Statement'!F36 -> 2254 | G13: ='Income Statement'!G36 -> 2100 | H13: ='Income Statement'!H36 -> 1900 | I13: ='Income Statement'!I36 -> 1700 | J13: ='Income Statement'!J36 -> 1500 | K13: ='Income Statement'!K36 -> 1300
A14: Less: capital expenditures | C14: ='Cash Flow'!C24 -> -450 | D14: ='Cash Flow'!D24 -> -546 | E14: ='Cash Flow'!E24 -> -636 | F14: ='Cash Flow'!F24 -> -974 | G14: ='Cash Flow'!G24 -> -2473.775 | H14: ='Cash Flow'!H24 -> -3110.2713 | I14: ='Cash Flow'!I24 -> -3496.6867 | J14: ='Cash Flow'!J24 -> -3593.7501 | K14: ='Cash Flow'!K24 -> -4007.8967
A15: Less: increase in net working capital | C15: =SUM('Cash Flow'!C14:C18) -> -1846 | D15: =SUM('Cash Flow'!D14:D18) -> -3049 | E15: =SUM('Cash Flow'!E14:E18) -> -2098 | F15: =SUM('Cash Flow'!F14:F18) -> -2378 | G15: =SUM('Cash Flow'!G14:G18) -> -477.5516 | H15: =SUM('Cash Flow'!H14:H18) -> -1937.7851 | I15: =SUM('Cash Flow'!I14:I18) -> -1564.7959 | J15: =SUM('Cash Flow'!J14:J18) -> -1362.7904 | K15: =SUM('Cash Flow'!K14:K18) -> -826.0089
A16: UNLEVERED FREE CASH FLOW | C16: =C11+C12+C13+C14+C15 -> 2952.4 | D16: =D11+D12+D13+D14+D15 -> 198.85 | E16: =E11+E12+E13+E14+E15 -> 1946 | F16: =F11+F12+F13+F14+F15 -> 2791.9 | G16: =G11+G12+G13+G14+G15 -> 7565.5757 | H16: =H11+H12+H13+H14+H15 -> 12187.922 | I16: =I11+I12+I13+I14+I15 -> 18861.715 | J16: =J11+J12+J13+J14+J15 -> 24814.219 | K16: =K11+K12+K13+K14+K15 -> 29285.077
A17: UFCF margin % | C17: =C16/C5 -> 0.12509639 | D17: =D16/D5 -> 0.0087676367 | E17: =E16/E5 -> 0.075470235 | F17: =F16/F5 -> 0.080599902 | G17: =G16/G5 -> 0.1529156 | H17: =H16/H5 -> 0.17633719 | I17: =I16/I5 -> 0.21576672 | J17: =J16/J5 -> 0.24166891 | K17: =K16/K5 -> 0.25573955
A18: Memo: stock-based compensation (already deducted in EBIT) | C18: ='Income Statement'!C40 -> 1081 | D18: ='Income Statement'!D40 -> 1384 | E18: ='Income Statement'!E40 -> 1407 | F18: ='Income Statement'!F40 -> 1638 | G18: ='Income Statement'!G40 -> 1979.02 | H18: ='Income Statement'!H40 -> 2419.0999 | I18: ='Income Statement'!I40 -> 2797.3493 | J18: ='Income Statement'!J40 -> 3080.3572 | K18: ='Income Statement'!K40 -> 3435.34
A20: Terminal-year metrics (FY2030E)
A21: FY2030E revenue | C21: =K5 -> 114511.33
A22: FY2030E EBITDA | C22: =K7 -> 39506.41
A23: FY2030E EBIT | C23: =K8 -> 35916.183
A24: FY2030E unlevered FCF | C24: =K16 -> 29285.077
A25: FY2030E NOPAT | C25: =K11 -> 30528.756
A27: Capital structure & market inputs (latest)
A28: Share price (USD), 2026-10-14 | B28: stock-data get_quote | C28: 605.53
A29: Basic shares outstanding (M), 2026-06-27 | B29: 10-Q 2026-08-05 | C29: 1632
A30: Diluted weighted shares (M), Q2 FY2026 | B30: 10-Q 2026-08-05 | C30: 1659
A31: Market capitalization (price x basic shares) | C31: =C28*C29 -> 988224.96
A32: Cash and cash equivalents, 2026-06-27 | C32: 5086
A33: Short-term investments, 2026-06-27 | C33: 8025
A34: Total debt (carrying), 2026-06-27 | C34: 3226
A35: Enterprise value (market cap - cash - STI + debt) | C35: =C31-C32-C33+C34 -> 978339.96
A36: EV / FY2026E revenue | C36: =C35/G5 -> 19.774231
A37: EV / FY2027E EBITDA | C37: =C35/H7 -> 49.665999
A38: P/E FY2027E (diluted EPS) | C38: =C28/'Income Statement'!H65 -> 70.971908
A39: OpenAI warrant: up to 160M shares (not in share count; model knowledge) | B39: excluded | C39: 160

Sheet DCF
A1: AMD - Discounted Cash Flow (two-stage: explicit FY2026E-FY2030E + 5-year fade FY2031E-FY2035E + Gordon terminal value)
A2: USD millions except per share. Valuation date 2026-10-14; balance sheet as of 2026-06-27, so only H2 FY2026E cash flow is included. Mid-period discounting.
A4: WACC BUILD
A5: Risk-free rate: 10-year UST (FRED DGS10, 2026-10-09) | C5: 0.0524
A6: Equity risk premium (assumed) | C6: 0.05
A7: Peer median unlevered beta (Comps tab, Blume-adjusted 5y monthly) | C7: =Comps!V12 -> 1.5879639
A8: AMD debt / equity (market) | C8: ='DCF Inputs'!C34/'DCF Inputs'!C31 -> 0.0032644389
A9: Tax rate for levering / Kd shield | C9: 0.15
A10: Relevered beta applied to AMD | C10: =C7*(1+(1-C9)*C8) -> 1.5923702
A11: Memo: AMD own beta, Blume-adjusted (raw 2.52) | C11: =Comps!T17 -> 2.01505
A12: Cost of equity (CAPM) | C12: =C5+C10*C6 -> 0.13201851
A13: Pre-tax cost of debt (Rf + 0.6% A-rated spread, assumed) | C13: =C5+0.006 -> 0.0584
A14: After-tax cost of debt | C14: =C13*(1-C9) -> 0.04964
A15: Equity value (market cap) | C15: ='DCF Inputs'!C31 -> 988224.96
A16: Debt (carrying, 2026-06-27) | C16: ='DCF Inputs'!C34 -> 3226
A17: E / (D + E) | C17: =C15/(C15+C16) -> 0.99674618
A18: WACC | C18: =C17*C12+(1-C17)*C14 -> 0.13175046
A19: Terminal growth rate (nominal) | C19: 0.03
A20: Net cash: cash + ST investments - debt (2026-06-27) | C20: ='DCF Inputs'!C32+'DCF Inputs'!C33-'DCF Inputs'!C34 -> 9885
A21: Diluted shares (M), Q2 FY2026 | C21: ='DCF Inputs'!C30 -> 1659
A22: Current share price (USD), 2026-10-14 | C22: ='DCF Inputs'!C28 -> 605.53
A25: BASE DCF (linked live to the model; follows Scenarios!C3 selector - keep on 2 = Base)
A26: USD millions | C26: FY2026E (H2) | D26: FY2027E | E26: FY2028E | F26: FY2029E | G26: FY2030E | H26: FY2031E | I26: FY2032E | J26: FY2033E | K26: FY2034E | L26: FY2035E
A27: Stage | C27: Explicit (model) | D27: Explicit (model) | E27: Explicit (model) | F27: Explicit (model) | G27: Explicit (model) | H27: Fade | I27: Fade | J27: Fade | K27: Fade | L27: Fade
A28: Revenue | C28: ='DCF Inputs'!G5 -> 49475.5 | D28: ='DCF Inputs'!H5 -> 69117.14 | E28: ='DCF Inputs'!I5 -> 87417.167 | F28: ='DCF Inputs'!J5 -> 102678.57 | G28: ='DCF Inputs'!K5 -> 114511.33 | H28: =G28*(1+H29) -> 126080.87 | I28: =H28*(1+I29) -> 137028.12 | J28: =I28*(1+J29) -> 146979.15 | K28: =J28*(1+K29) -> 155564.74 | L28: =K28*(1+L29) -> 162441.75
A29: Revenue growth % | C29: =C28/'Revenue Model'!F47-1 -> 0.42831779 | D29: =D28/C28-1 -> 0.3969973 | E29: =E28/D28-1 -> 0.26476829 | F29: =F28/E28-1 -> 0.17458134 | G29: =G28/F28-1 -> 0.11524079 | H29: =$G29-($G29-$C$19)*1/6 -> 0.10103399 | I29: =$G29-($G29-$C$19)*2/6 -> 0.086827194 | J29: =$G29-($G29-$C$19)*3/6 -> 0.072620395 | K29: =$G29-($G29-$C$19)*4/6 -> 0.058413597 | L29: =$G29-($G29-$C$19)*5/6 -> 0.044206798
A30: Unlevered FCF (full year) | C30: ='DCF Inputs'!G16 -> 7565.5757 | D30: ='DCF Inputs'!H16 -> 12187.922 | E30: ='DCF Inputs'!I16 -> 18861.715 | F30: ='DCF Inputs'!J16 -> 24814.219 | G30: ='DCF Inputs'!K16 -> 29285.077 | H30: =H28*H31 -> 32243.865 | I30: =I28*I31 -> 35043.51 | J30: =J28*J31 -> 37588.383 | K30: =K28*K31 -> 39784.056 | L30: =L28*L31 -> 41542.781
A31: UFCF margin % | C31: =C30/C28 -> 0.1529156 | D31: =D30/D28 -> 0.17633719 | E31: =E30/E28 -> 0.21576672 | F31: =F30/F28 -> 0.24166891 | G31: =G30/G28 -> 0.25573955 | H31: =$G31 -> 0.25573955 | I31: =$G31 -> 0.25573955 | J31: =$G31 -> 0.25573955 | K31: =$G31 -> 0.25573955 | L31: =$G31 -> 0.25573955
A32: Fraction of year included | C32: 0.5 | D32: 1 | E32: 1 | F32: 1 | G32: 1 | H32: 1 | I32: 1 | J32: 1 | K32: 1 | L32: 1
A33: Cash flow discounted | C33: =C30*C32 -> 3782.7878 | D33: =D30*D32 -> 12187.922 | E33: =E30*E32 -> 18861.715 | F33: =F30*F32 -> 24814.219 | G33: =G30*G32 -> 29285.077 | H33: =H30*H32 -> 32243.865 | I33: =I30*I32 -> 35043.51 | J33: =J30*J32 -> 37588.383 | ... L33: =L30*L32 -> 41542.781
A34: Discount period (years, mid-period) | C34: 0 | D34: =(DATE(2027,7,2)-DATE(2026,10,14))/365.25 -> 0.71457906 | E34: =(DATE(2028,7,2)-DATE(2026,10,14))/365.25 -> 1.7166324 | F34: =(DATE(2029,7,2)-DATE(2026,10,14))/365.25 -> 2.715948 | G34: =(DATE(2030,7,2)-DATE(2026,10,14))/365.25 -> 3.7152635 | H34: =(DATE(2031,7,2)-DATE(2026,10,14))/365.25 -> 4.7145791 | I34: =(DATE(2032,7,2)-DATE(2026,10,14))/365.25 -> 5.7166324 | J34: =(DATE(2033,7,2)-DATE(2026,10,14))/365.25 -> 6.715948 | K34: =(DATE(2034,7,2)-DATE(2026,10,14))/365.25 -> 7.7152635 | L34: =(DATE(2035,7,2)-DATE(2026,10,14))/365.25 -> 8.7145791
A35: Discount factor | C35: =1/(1+$C$18)^C34 -> 1 | D35: =1/(1+$C$18)^D34 -> 0.91535781 | E35: =1/(1+$C$18)^E34 -> 0.80859274 | F35: =1/(1+$C$18)^F34 -> 0.71452256 | G35: =1/(1+$C$18)^G34 -> 0.63139633 | H35: =1/(1+$C$18)^H34 -> 0.55794086 | I35: =1/(1+$C$18)^I34 -> 0.49286402 | J35: =1/(1+$C$18)^J34 -> 0.43552513 | ... L35: =1/(1+$C$18)^L34 -> 0.3400834
A36: Present value | C36: =C33*C35 -> 3782.7878 | D36: =D33*D35 -> 11156.31 | E36: =E33*E35 -> 15251.446 | F36: =F33*F35 -> 17730.319 | G36: =G33*G35 -> 18490.49 | H36: =H33*H35 -> 17990.17 | I36: =I33*I35 -> 17271.685 | J36: =J33*J35 -> 16370.685 | ... L36: =L33*L35 -> 14128.011
A38: PV of explicit-period cash flows (H2 FY2026E-FY2030E) | C38: =SUM(C36:G36) -> 66411.353
A39: PV of fade-period cash flows (FY2031E-FY2035E) | C39: =SUM(H36:L36) -> 81071.721
A40: Terminal-year FCF (FY2036E = FY2035E x (1+g)) | C40: =L30*(1+$C$19) -> 42789.065
A41: Terminal value at end-FY2035E (Gordon growth) | C41: =C40/($C$18-$C$19) -> 420529.43
A42: Discount period to end-FY2035E (years) | C42: =(DATE(2035,12,31)-DATE(2026,10,14))/365.25 -> 9.2128679
A43: PV of terminal value | C43: =C41/(1+$C$18)^C42 -> 134461.66
A44: ENTERPRISE VALUE | C44: =C38+C39+C43 -> 281944.74
...

Sheet Sensitivity
A1: AMD - DCF Sensitivity Analysis (value per share, USD)
A2: Recomputes the base DCF (DCF tab) for each input pair. Fade-period revenue path held at base; terminal growth and WACC flexed.
A4: TABLE 1: WACC (rows) vs. terminal growth (columns)
B5: WACC \ g | C5: 0.02 | D5: 0.025 | E5: 0.03 | F5: 0.035 | G5: 0.04
B6: =DCF!$C$18+(-0.03) -> 0.10175046 | C6: =(SUMPRODUCT(DCF!$C$33:$L$33,(1+$B6)^(-DCF!$C$34:$L$34))+DCF!$L$30*(1+C$5)/($B6-C$5)*(1+$B6)^(-DCF!$C$42)+DCF!$C$20)/DCF!$C$21 -> 234.86935 | D6: =(SUMPRODUCT(DCF!$C$33:$L$33,(1+$B6)^(-DCF!$C$34:$L$34))+DCF!$L$30*(1+D$5)/($B6-D$5)*(1+$B6)^(-DCF!$C$42)+DCF!$C$20)/DCF!$C$21 -> 243.87311 | E6: =(SUMPRODUCT(DCF!$C$33:$L$33,(1+$B6)^(-DCF!$C$34:$L$34))+DCF!$L$30*(1+E$5)/($B6-E$5)*(1+$B6)^(-DCF!$C$42)+DCF!$C$20)/DCF!$C$21 -> 254.13174 | F6: =(SUMPRODUCT(DCF!$C$33:$L$33,(1+$B6)^(-DCF!$C$34:$L$34))+DCF!$L$30*(1+F$5)/($B6-F$5)*(1+$B6)^(-DCF!$C$42)+DCF!$C$20)/DCF!$C$21 -> 265.92723 | G6: =(SUMPRODUCT(DCF!$C$33:$L$33,(1+$B6)^(-DCF!$C$34:$L$34))+DCF!$L$30*(1+G$5)/($B6-G$5)*(1+$B6)^(-DCF!$C$42)+DCF!$C$20)/DCF!$C$21 -> 279.63291
B7: =DCF!$C$18+(-0.02) -> 0.11175046 | C7: =(SUMPRODUCT(DCF!$C$33:$L$33,(1+$B7)^(-DCF!$C$34:$L$34))+DCF!$L$30*(1+C$5)/($B7-C$5)*(1+$B7)^(-DCF!$C$42)+DCF!$C$20)/DCF!$C$21 -> 207.54013 | D7: =(SUMPRODUCT(DCF!$C$33:$L$33,(1+$B7)^(-DCF!$C$34:$L$34))+DCF!$L$30*(1+D$5)/($B7-D$5)*(1+$B7)^(-DCF!$C$42)+DCF!$C$20)/DCF!$C$21 -> 214.13015 | E7: =(SUMPRODUCT(DCF!$C$33:$L$33,(1+$B7)^(-DCF!$C$34:$L$34))+DCF!$L$30*(1+E$5)/($B7-E$5)*(1+$B7)^(-DCF!$C$42)+DCF!$C$20)/DCF!$C$21 -> 221.52629 | F7: =(SUMPRODUCT(DCF!$C$33:$L$33,(1+$B7)^(-DCF!$C$34:$L$34))+DCF!$L$30*(1+F$5)/($B7-F$5)*(1+$B7)^(-DCF!$C$42)+DCF!$C$20)/DCF!$C$21 -> 229.88609 | G7: =(SUMPRODUCT(DCF!$C$33:$L$33,(1+$B7)^(-DCF!$C$34:$L$34))+DCF!$L$30*(1+G$5)/($B7-G$5)*(1+$B7)^(-DCF!$C$42)+DCF!$C$20)/DCF!$C$21 -> 239.41101
B8: =DCF!$C$18+(-0.01) -> 0.12175046 | C8: =(SUMPRODUCT(DCF!$C$33:$L$33,(1+$B8)^(-DCF!$C$34:$L$34))+DCF!$L$30*(1+C$5)/($B8-C$5)*(1+$B8)^(-DCF!$C$42)+DCF!$C$20)/DCF!$C$21 -> 185.72706 | D8: =(SUMPRODUCT(DCF!$C$33:$L$33,(1+$B8)^(-DCF!$C$34:$L$34))+DCF!$L$30*(1+D$5)/($B8-D$5)*(1+$B8)^(-DCF!$C$42)+DCF!$C$20)/DCF!$C$21 -> 190.67744 | E8: =(SUMPRODUCT(DCF!$C$33:$L$33,(1+$B8)^(-DCF!$C$34:$L$34))+DCF!$L$30*(1+E$5)/($B8-E$5)*(1+$B8)^(-DCF!$C$42)+DCF!$C$20)/DCF!$C$21 -> 196.16737 | F8: =(SUMPRODUCT(DCF!$C$33:$L$33,(1+$B8)^(-DCF!$C$34:$L$34))+DCF!$L$30*(1+F$5)/($B8-F$5)*(1+$B8)^(-DCF!$C$42)+DCF!$C$20)/DCF!$C$21 -> 202.29013 | G8: =(SUMPRODUCT(DCF!$C$33:$L$33,(1+$B8)^(-DCF!$C$34:$L$34))+DCF!$L$30*(1+G$5)/($B8-G$5)*(1+$B8)^(-DCF!$C$42)+DCF!$C$20)/DCF!$C$21 -> 209.16186
B9: =DCF!$C$18+(0) -> 0.13175046 | C9: =(SUMPRODUCT(DCF!$C$33:$L$33,(1+$B9)^(-DCF!$C$34:$L$34))+DCF!$L$30*(1+C$5)/($B9-C$5)*(1+$B9)^(-DCF!$C$42)+DCF!$C$20)/DCF!$C$21 -> 167.93779 | D9: =(SUMPRODUCT(DCF!$C$33:$L$33,(1+$B9)^(-DCF!$C$34:$L$34))+DCF!$L$30*(1+D$5)/($B9-D$5)*(1+$B9)^(-DCF!$C$42)+DCF!$C$20)/DCF!$C$21 -> 171.73577 | E9: =(SUMPRODUCT(DCF!$C$33:$L$33,(1+$B9)^(-DCF!$C$34:$L$34))+DCF!$L$30*(1+E$5)/($B9-E$5)*(1+$B9)^(-DCF!$C$42)+DCF!$C$20)/DCF!$C$21 -> 175.90701 | F9: =(SUMPRODUCT(DCF!$C$33:$L$33,(1+$B9)^(-DCF!$C$34:$L$34))+DCF!$L$30*(1+F$5)/($B9-F$5)*(1+$B9)^(-DCF!$C$42)+DCF!$C$20)/DCF!$C$21 -> 180.50939 | G9: =(SUMPRODUCT(DCF!$C$33:$L$33,(1+$B9)^(-DCF!$C$34:$L$34))+DCF!$L$30*(1+G$5)/($B9-G$5)*(1+$B9)^(-DCF!$C$42)+DCF!$C$20)/DCF!$C$21 -> 185.61339
B10: =DCF!$C$18+(0.01) -> 0.14175046 | C10: =(SUMPRODUCT(DCF!$C$33:$L$33,(1+$B10)^(-DCF!$C$34:$L$34))+DCF!$L$30*(1+C$5)/($B10-C$5)*(1+$B10)^(-DCF!$C$42)+DCF!$C$20)/DCF!$C$21 -> 153.17136 | D10: =(SUMPRODUCT(DCF!$C$33:$L$33,(1+$B10)^(-DCF!$C$34:$L$34))+DCF!$L$30*(1+D$5)/($B10-D$5)*(1+$B10)^(-DCF!$C$42)+DCF!$C$20)/DCF!$C$21 -> 156.13664 | E10: =(SUMPRODUCT(DCF!$C$33:$L$33,(1+$B10)^(-DCF!$C$34:$L$34))+DCF!$L$30*(1+E$5)/($B10-E$5)*(1+$B10)^(-DCF!$C$42)+DCF!$C$20)/DCF!$C$21 -> 159.36727 | F10: =(SUMPRODUCT(DCF!$C$33:$L$33,(1+$B10)^(-DCF!$C$34:$L$34))+DCF!$L$30*(1+F$5)/($B10-F$5)*(1+$B10)^(-DCF!$C$42)+DCF!$C$20)/DCF!$C$21 -> 162.90052 | G10: =(SUMPRODUCT(DCF!$C$33:$L$33,(1+$B10)^(-DCF!$C$34:$L$34))+DCF!$L$30*(1+G$5)/($B10-G$5)*(1+$B10)^(-DCF!$C$42)+DCF!$C$20)/DCF!$C$21 -> 166.78103
