Workbook

Sheet Comps
A1: LARGE-CAP TECHNOLOGY - COMPARABLE COMPANY ANALYSIS: MICROSOFT (MSFT)
A2: Target: Microsoft (MSFT) | Peers: Alphabet (GOOGL) • Amazon (AMZN) • Meta Platforms (META) • Apple (AAPL) • Oracle (ORCL)
A3: Prices as of 2026-10-14 close | LTM to each company's latest reported quarter | USD millions except per-share data and ratios | Peer statistics exclude MSFT
A5: OPERATING STATISTICS & FINANCIAL METRICS (LTM)
A6: Company | B6: Ticker | C6: LTM through | D6: LTM revenue | E6: Revenue growth (YoY LTM) | F6: LTM EBIT | G6: EBIT margin | H6: LTM D&A | I6: LTM EBITDA | J6: EBITDA margin | K6: LTM net income | L6: Net margin
A7: Microsoft | B7: MSFT | C7: =Inputs!C5 -> 2026-06-30 | D7: =Inputs!J14 -> 331839 | E7: =Inputs!L14 -> 0.17788687 | F7: =Inputs!F23 -> 155237 | G7: =F7/D7 -> 0.46780818 | H7: =Inputs!F59 -> 38534 | I7: =F7+H7 -> 193771 | J7: =I7/D7 -> 0.58393076 | K7: =Inputs!F32 -> 133749 | L7: =K7/D7 -> 0.40305389
A9: Alphabet | B9: GOOGL | C9: =Inputs!C6 -> 2026-06-30 | D9: =Inputs!J15 -> 445867 | E9: =Inputs!L15 -> 0.20050673 | F9: =Inputs!F24 -> 147628 | G9: =F9/D9 -> 0.33110322 | H9: =Inputs!F60 -> 25237 | I9: =F9+H9 -> 172865 | J9: =I9/D9 -> 0.3877053 | K9: =Inputs!F33 -> 244205 | L9: =K9/D9 -> 0.54770817
A10: Amazon | B10: AMZN | C10: =Inputs!C7 -> 2026-06-30 | D10: =Inputs!J16 -> 775680 | E10: =Inputs!L16 -> 0.15766568 | F10: =Inputs!F25 -> 93712 | G10: =F10/D10 -> 0.12081271 | H10: =Inputs!F61 -> 75200 | I10: =F10+H10 -> 168912 | J10: =I10/D10 -> 0.2177599 | K10: =Inputs!F34 -> 135281 | L10: =K10/D10 -> 0.1744031
A11: Meta Platforms | B11: META | C11: =Inputs!C8 -> 2026-06-30 | D11: =Inputs!J17 -> 228247 | E11: =Inputs!L17 -> 0.27652066 | F11: =Inputs!F26 -> 86927 | G11: =F11/D11 -> 0.38084619 | H11: =Inputs!F62 -> 22729 | I11: =F11+H11 -> 109656 | J11: =I11/D11 -> 0.48042691 | K11: =Inputs!F35 -> 68098 | L11: =K11/D11 -> 0.29835222
A12: Apple | B12: AAPL | C12: =Inputs!C9 -> 2026-06-27 | D12: =Inputs!J18 -> 466823 | E12: =Inputs!L18 -> 0.14242398 | F12: =Inputs!F27 -> 154859 | G12: =F12/D12 -> 0.33172958 | H12: =Inputs!F63 -> 13100 | I12: =F12+H12 -> 167959 | J12: =I12/D12 -> 0.35979161 | K12: =Inputs!F36 -> 128930 | L12: =K12/D12 -> 0.27618605
A13: Oracle | B13: ORCL | C13: =Inputs!C10 -> 2026-08-31 | D13: =Inputs!J19 -> 71777 | E13: =Inputs!L19 -> 0.21618828 | F13: =Inputs!F28 -> 23056 | G13: =F13/D13 -> 0.3212171 | H13: =Inputs!F64 -> 10881 | I13: =F13+H13 -> 33937 | J13: =I13/D13 -> 0.47281162 | K13: =Inputs!F37 -> 18920 | L13: =K13/D13 -> 0.26359419
A15: Peer Maximum | E15: =MAX(E9:E13) -> 0.27652066 | G15: =MAX(G9:G13) -> 0.38084619 | J15: =MAX(J9:J13) -> 0.48042691 | L15: =MAX(L9:L13) -> 0.54770817
A16: Peer 75th Percentile | E16: =QUARTILE(E9:E13,3) -> 0.21618828 | G16: =QUARTILE(G9:G13,3) -> 0.33172958 | J16: =QUARTILE(J9:J13,3) -> 0.47281162 | L16: =QUARTILE(L9:L13,3) -> 0.29835222
A17: Peer Median | E17: =MEDIAN(E9:E13) -> 0.20050673 | G17: =MEDIAN(G9:G13) -> 0.33110322 | J17: =MEDIAN(J9:J13) -> 0.3877053 | L17: =MEDIAN(L9:L13) -> 0.27618605
A18: Peer 25th Percentile | E18: =QUARTILE(E9:E13,1) -> 0.15766568 | G18: =QUARTILE(G9:G13,1) -> 0.3212171 | J18: =QUARTILE(J9:J13,1) -> 0.35979161 | L18: =QUARTILE(L9:L13,1) -> 0.26359419
A19: Peer Minimum | E19: =MIN(E9:E13) -> 0.14242398 | G19: =MIN(G9:G13) -> 0.12081271 | J19: =MIN(J9:J13) -> 0.2177599 | L19: =MIN(L9:L13) -> 0.1744031
A20: MSFT vs peer median (pp) | E20: =E7-E17 -> -0.022619865 | G20: =G7-G17 -> 0.13670496 | J20: =J7-J17 -> 0.19622546 | L20: =L7-L17 -> 0.12686784
A22: VALUATION MULTIPLES
A23: Company | B23: Ticker | C23: Share price ($) | D23: Shares out (M) | E23: Market cap | F23: Net debt (cash) incl. pref & NCI | G23: Enterprise value | H23: EV / LTM revenue | I23: EV / LTM EBITDA | J23: P/E (LTM GAAP) | K23: LTM effective tax rate | L23: P/E (LTM EBIT after tax)
A24: Microsoft | B24: MSFT | C24: =Inputs!E5 -> 533.69 | D24: =Inputs!F5 -> 7427 | E24: =C24*D24 -> 3963715.6 | F24: =Inputs!N5 -> -36549 | G24: =E24+F24 -> 3927166.6 | H24: =G24/D7 -> 11.834554 | I24: =G24/I7 -> 20.26705 | J24: =E24/K7 -> 29.635479 | K24: =Inputs!F41/Inputs!F50 -> 0.19396266 | L24: =E24/(F7*(1-K24)) -> 31.677587
A26: Alphabet | B26: GOOGL | C26: =Inputs!E6 -> 347.64 | D26: =Inputs!F6 -> 12230 | E26: =C26*D26 -> 4251637.2 | F26: =Inputs!N6 -> -142310 | G26: =E26+F26 -> 4109327.2 | H26: =G26/D9 -> 9.2164865 | I26: =G26/I9 -> 23.771887 | J26: =E26/K9 -> 17.410115 | K26: =Inputs!F42/Inputs!F51 -> 0.183995 | L26: =E26/(F9*(1-K26)) -> 35.293493
A27: Amazon | B27: AMZN | C27: =Inputs!E7 -> 254.08 | D27: =Inputs!F7 -> 10783 | E27: =C27*D27 -> 2739744.6 | F27: =Inputs!N7 -> 9236 | G27: =E27+F27 -> 2748980.6 | H27: =G27/D10 -> 3.5439623 | I27: =G27/I10 -> 16.274632 | J27: =E27/K10 -> 20.25225 | K27: =Inputs!F43/Inputs!F52 -> 0.22577023 | L27: =E27/(F10*(1-K27)) -> 37.761133
A28: Meta Platforms | B28: META | C28: =Inputs!E8 -> 737.54 | D28: =Inputs!F8 -> 2547.506 | E28: =C28*D28 -> 1878887.6 | F28: =Inputs!N8 -> -6596 | G28: =E28+F28 -> 1872291.6 | H28: =G28/D11 -> 8.2029187 | I28: =G28/I11 -> 17.074228 | J28: =E28/K11 -> 27.590936 | K28: =Inputs!F44/Inputs!F53 -> 0.22195944 | L28: =E28/(F11*(1-K28)) -> 27.780744
A29: Apple | B29: AAPL | C29: =Inputs!E9 -> 342.96 | D29: =Inputs!F9 -> 14608.963 | E29: =C29*D29 -> 5010290 | F29: =Inputs!N9 -> 21945 | G29: =E29+F29 -> 5032235 | H29: =G29/D12 -> 10.779749 | I29: =G29/I12 -> 29.961091 | J29: =E29/K12 -> 38.860544 | K29: =Inputs!F45/Inputs!F54 -> 0.17302734 | L29: =E29/(F12*(1-K29)) -> 39.12328
A30: Oracle | B30: ORCL | C30: =Inputs!E10 -> 130.55 | D30: =Inputs!F10 -> 3024 | E30: =C30*D30 -> 394783.2 | F30: =Inputs!N10 -> 93638 | G30: =E30+F30 -> 488421.2 | H30: =G30/D13 -> 6.8047035 | I30: =G30/I13 -> 14.391997 | J30: =E30/K13 -> 20.86592 | K30: =Inputs!F46/Inputs!F55 -> 0.12947456 | L30: =E30/(F13*(1-K30)) -> 19.669496
A32: Peer Maximum | H32: =MAX(H26:H30) -> 10.779749 | I32: =MAX(I26:I30) -> 29.961091 | J32: =MAX(J26:J30) -> 38.860544 | K32: =MAX(K26:K30) -> 0.22577023 | L32: =MAX(L26:L30) -> 39.12328
A33: Peer 75th Percentile | H33: =QUARTILE(H26:H30,3) -> 9.2164865 | I33: =QUARTILE(I26:I30,3) -> 23.771887 | J33: =QUARTILE(J26:J30,3) -> 27.590936 | K33: =QUARTILE(K26:K30,3) -> 0.22195944 | L33: =QUARTILE(L26:L30,3) -> 37.761133
A34: Peer Median | H34: =MEDIAN(H26:H30) -> 8.2029187 | I34: =MEDIAN(I26:I30) -> 17.074228 | J34: =MEDIAN(J26:J30) -> 20.86592 | K34: =MEDIAN(K26:K30) -> 0.183995 | L34: =MEDIAN(L26:L30) -> 35.293493
A35: Peer 25th Percentile | H35: =QUARTILE(H26:H30,1) -> 6.8047035 | I35: =QUARTILE(I26:I30,1) -> 16.274632 | J35: =QUARTILE(J26:J30,1) -> 20.25225 | K35: =QUARTILE(K26:K30,1) -> 0.17302734 | L35: =QUARTILE(L26:L30,1) -> 27.780744
A36: Peer Minimum | H36: =MIN(H26:H30) -> 3.5439623 | I36: =MIN(I26:I30) -> 14.391997 | J36: =MIN(J26:J30) -> 17.410115 | K36: =MIN(K26:K30) -> 0.12947456 | L36: =MIN(L26:L30) -> 19.669496
A37: MSFT premium / (discount) to peer median | H37: =H24/H34-1 -> 0.4427248 | I37: =I24/I34-1 -> 0.18699657 | J37: =J24/J34-1 -> 0.42028145 | L37: =L24/L34-1 -> -0.1024525
A39: IMPLIED MSFT VALUE PER SHARE AT PEER MULTIPLES (USD)
A40: Multiple | B40: MSFT LTM metric | C40: Peer 25th pct | D40: Peer median | E40: Peer 75th pct | F40: Implied price @25th | G40: Implied price @median | H40: Implied price @75th | I40: Current price | J40: Upside/(down) @median
A41: EV / LTM revenue | B41: =D7 -> 331839 | C41: =H35 -> 6.8047035 | D41: =H34 -> 8.2029187 | E41: =H33 -> 9.2164865 | F41: =($B41*C41-$F$24)/$D$24 -> 308.95584 | G41: =($B41*D41-$F$24)/$D$24 -> 371.42821 | H41: =($B41*E41-$F$24)/$D$24 -> 416.71451 | I41: =$C$24 -> 533.69 | J41: =G41/I41-1 -> -0.30403753
A42: EV / LTM EBITDA | B42: =I7 -> 193771 | C42: =I35 -> 16.274632 | D42: =I34 -> 17.074228 | E42: =I33 -> 23.771887 | F42: =($B42*C42-$F$24)/$D$24 -> 429.5275 | G42: =($B42*D42-$F$24)/$D$24 -> 450.38902 | H42: =($B42*E42-$F$24)/$D$24 -> 625.13145 | I42: =$C$24 -> 533.69 | J42: =G42/I42-1 -> -0.15608495
A43: P/E (LTM GAAP) | B43: =K7 -> 133749 | C43: =J35 -> 20.25225 | D43: =J34 -> 20.86592 | E43: =J33 -> 27.590936 | F43: =$B43*C43/$D$24 -> 364.71229 | G43: =$B43*D43/$D$24 -> 375.76355 | H43: =$B43*E43/$D$24 -> 496.87089 | I43: =$C$24 -> 533.69 | J43: =G43/I43-1 -> -0.2959142
A44: P/E (LTM EBIT after tax) | B44: =F7*(1-K24) -> 125126.82 | C44: =L35 -> 27.780744 | D44: =L34 -> 35.293493 | E44: =L33 -> 37.761133 | F44: =$B44*C44/$D$24 -> 468.03771 | G44: =$B44*D44/$D$24 -> 594.6092 | H44: =$B44*E44/$D$24 -> 636.1829 | I44: =$C$24 -> 533.69 | J44: =G44/I44-1 -> 0.11414716

Sheet Inputs
A1: INPUTS - MARKET DATA, BALANCE SHEET AND QUARTERLY FINANCIALS (USD millions except per-share)
A2: Blue = hard-coded input (each has a cell comment with its source); black = formula.
A3: A. MARKET DATA & BALANCE SHEET (latest reported balance sheet)
A4: Ticker | B4: Company | C4: Latest Q end (LTM) | D4: Fiscal period | E4: Share price ($) | F4: Shares out (M) | G4: Cash & equiv. | H4: ST investments | I4: Debt - current | J4: Debt - non-current | K4: Preferred stock | L4: Noncontrolling int. | M4: Total debt | N4: Net debt (cash)
A5: MSFT | B5: Microsoft | C5: 2026-06-30 | D5: FY26 Q4 | E5: 533.69 | F5: 7427 | G5: 20935 | H5: 55908 | I5: 9227 | J5: 31067 | K5: 0 | L5: 0 | M5: =I5+J5 -> 40294 | N5: =M5+K5+L5-G5-H5 -> -36549
A6: GOOGL | B6: Alphabet | C6: 2026-06-30 | D6: Q2 CY26 | E6: 347.64 | F6: 12230 | G6: 55911 | H6: 186563 | I6: 1999 | J6: 98165 | K6: 0 | L6: 0 | M6: =I6+J6 -> 100164 | N6: =M6+K6+L6-G6-H6 -> -142310
A7: AMZN | B7: Amazon | C7: 2026-06-30 | D7: Q2 CY26 | E7: 254.08 | F7: 10783 | G7: 78213 | H7: 44775 | I7: 3330 | J7: 128894 | K7: 0 | L7: 0 | M7: =I7+J7 -> 132224 | N7: =M7+K7+L7-G7-H7 -> 9236
A8: META | B8: Meta Platforms | C8: 2026-06-30 | D8: Q2 CY26 | E8: 737.54 | F8: 2547.506 | G8: 15462 | H8: 74798 | I8: 0 | J8: 83664 | K8: 0 | L8: 0 | M8: =I8+J8 -> 83664 | N8: =M8+K8+L8-G8-H8 -> -6596
A9: AAPL | B9: Apple | C9: 2026-06-27 | D9: FY26 Q3 | E9: 342.96 | F9: 14608.963 | G9: 39544 | H9: 22855 | I9: 13004 | J9: 71340 | K9: 0 | L9: 0 | M9: =I9+J9 -> 84344 | N9: =M9+K9+L9-G9-H9 -> 21945
A10: ORCL | B10: Oracle | C10: 2026-08-31 | D10: FY27 Q1 | E10: 130.55 | F10: 3024 | G10: 36369 | H10: 708 | I10: 7625 | J10: 117712 | K10: 4954 | L10: 424 | M10: =I10+J10 -> 125337 | N10: =M10+K10+L10-G10-H10 -> 93638
A12: B. QUARTERLY REVENUE (oldest to newest; Q-7 .. Q0 where Q0 = latest reported quarter)
A13: Ticker | B13: Q-7 | C13: Q-6 | D13: Q-5 | E13: Q-4 | F13: Q-3 | G13: Q-2 | H13: Q-1 | I13: Q0 | J13: LTM revenue | K13: Prior LTM revenue | L13: LTM growth % | M13: Q0 end
A14: MSFT | B14: 65585 | C14: 69632 | D14: 70066 | E14: 76441 | F14: 77673 | G14: 81273 | H14: 82886 | I14: 90007 | J14: =SUM(F14:I14) -> 331839 | K14: =SUM(B14:E14) -> 281724 | L14: =J14/K14-1 -> 0.17788687 | M14: =Inputs!C5 -> 2026-06-30
A15: GOOGL | B15: 88268 | C15: 96469 | D15: 90234 | E15: 96428 | F15: 102346 | G15: 113829 | H15: 109896 | I15: 119796 | J15: =SUM(F15:I15) -> 445867 | K15: =SUM(B15:E15) -> 371399 | L15: =J15/K15-1 -> 0.20050673 | M15: =Inputs!C6 -> 2026-06-30
A16: AMZN | B16: 158877 | C16: 187792 | D16: 155667 | E16: 167702 | F16: 180169 | G16: 213386 | H16: 181519 | I16: 200606 | J16: =SUM(F16:I16) -> 775680 | K16: =SUM(B16:E16) -> 670038 | L16: =J16/K16-1 -> 0.15766568 | M16: =Inputs!C7 -> 2026-06-30
A17: META | B17: 40589 | C17: 48385 | D17: 42314 | E17: 47516 | F17: 51242 | G17: 59893 | H17: 56311 | I17: 60801 | J17: =SUM(F17:I17) -> 228247 | K17: =SUM(B17:E17) -> 178804 | L17: =J17/K17-1 -> 0.27652066 | M17: =Inputs!C8 -> 2026-06-30
A18: AAPL | B18: 94930 | C18: 124300 | D18: 95359 | E18: 94036 | F18: 102466 | G18: 143756 | H18: 111184 | I18: 109417 | J18: =SUM(F18:I18) -> 466823 | K18: =SUM(B18:E18) -> 408625 | L18: =J18/K18-1 -> 0.14242398 | M18: =Inputs!C9 -> 2026-06-27
A19: ORCL | B19: 14059 | C19: 14130 | D19: 15903 | E19: 14926 | F19: 16058 | G19: 17190 | H19: 19184 | I19: 19345 | J19: =SUM(F19:I19) -> 71777 | K19: =SUM(B19:E19) -> 59018 | L19: =J19/K19-1 -> 0.21618828 | M19: =Inputs!C10 -> 2026-08-31
A21: C. OPERATING INCOME (GAAP, last 4 quarters)
A22: Ticker | B22: Q-3 | C22: Q-2 | D22: Q-1 | E22: Q0 | F22: LTM operating income
A23: MSFT | B23: 37961 | C23: 38275 | D23: 38398 | E23: 40603 | F23: =SUM(B23:E23) -> 155237
A24: GOOGL | B24: 31228 | C24: 35934 | D24: 39696 | E24: 40770 | F24: =SUM(B24:E24) -> 147628
A25: AMZN | B25: 17422 | C25: 24977 | D25: 23852 | E25: 27461 | F25: =SUM(B25:E25) -> 93712
A26: META | B26: 20535 | C26: 24745 | D26: 22872 | E26: 18775 | F26: =SUM(B26:E26) -> 86927
A27: AAPL | B27: 32427 | C27: 50852 | D27: 35885 | E27: 35695 | F27: =SUM(B27:E27) -> 154859
A28: ORCL | B28: 4731 | C28: 5464 | D28: 6133 | E28: 6728 | F28: =SUM(B28:E28) -> 23056
A30: D. NET INCOME ATTRIBUTABLE TO COMMON (GAAP, last 4 quarters)
A31: Ticker | B31: Q-3 | C31: Q-2 | D31: Q-1 | E31: Q0 | F31: LTM net income
A32: MSFT | B32: 27747 | C32: 38458 | D32: 31778 | E32: 35766 | F32: =SUM(B32:E32) -> 133749
A33: GOOGL | B33: 34979 | C33: 34455 | D33: 62578 | E33: 112193 | F33: =SUM(B33:E33) -> 244205
A34: AMZN | B34: 21187 | C34: 21192 | D34: 30255 | E34: 62647 | F34: =SUM(B34:E34) -> 135281
A35: META | B35: 2709 | C35: 22768 | D35: 26773 | E35: 15848 | F35: =SUM(B35:E35) -> 68098
A36: AAPL | B36: 27466 | C36: 42097 | D36: 29578 | E36: 29789 | F36: =SUM(B36:E36) -> 128930
A37: ORCL | B37: 6135 | C37: 3721 | D37: 4304 | E37: 4760 | F37: =SUM(B37:E37) -> 18920
A39: E. INCOME TAX EXPENSE (last 4 quarters)
A40: Ticker | B40: Q-3 | C40: Q-2 | D40: Q-1 | E40: Q0 | F40: LTM income tax
A41: MSFT | B41: 6554 | C41: 9788 | D41: 7562 | E41: 8281 | F41: =SUM(B41:E41) -> 32185
A42: GOOGL | B42: 9008 | C42: 4662 | D42: 14834 | E42: 26560 | F42: =SUM(B42:E42) -> 55064
A43: AMZN | B43: 6910 | C43: 4946 | D43: 9560 | E43: 18199 | F43: =SUM(B43:E43) -> 39615
A44: META | B44: 18954 | C44: 2586 | D44: -5021 | E44: 2908 | F44: =SUM(B44:E44) -> 19427
...

Sheet Notes
A1: NOTES & METHODOLOGY
A2: Purpose: trading comparables for an investment-committee valuation of Microsoft (MSFT). Peer set as specified: GOOGL, AMZN, META, AAPL, ORCL. Statistics (max / 75th / median / 25th / min) are computed on the five peers only; MSFT is shown as the target and benchmarked against the peer median.
A4: Data sources
A5: Share prices and quote market caps: stock-data get_quote (Yahoo Finance), 2026-10-14 session, fetched 2026-10-15T01:58Z.
A6: Income statement, balance sheet and cash-flow lines: stock-data get_financials (standardized SEC XBRL, quarterly). Fourth fiscal quarters are derived by the tool as full year less 9M YTD.
A7: Items not available in the data tool were taken from SEC EDGAR filings via WebFetch: MSFT D&A (earnings release Ex.99.1, 8-K filed 2026-07-29); GOOGL depreciation (10-K filed 2026-02-05; 10-Q filed 2026-07-23); ORCL D&A, debt, preferred and NCI (10-K filed 2026-06-22; 10-Q filed 2026-09-11); AAPL commercial paper (10-Q filed 2026-07-31); META shares outstanding (10-Q cover, filed 2026-07-30).
A9: Definitions
A10: LTM = sum of the four most recent reported fiscal quarters for each company. Latest quarter ends: MSFT 2026-06-30 (FY26 Q4), GOOGL/AMZN/META 2026-06-30, AAPL 2026-06-27 (FY26 Q3), ORCL 2026-08-31 (FY27 Q1). Fiscal calendars are not aligned; ORCL is two months later than the others.
A11: Revenue growth = LTM revenue / prior-year LTM revenue (the four quarters before) - 1.
A12: EBITDA = GAAP operating income + depreciation & amortization from the cash flow statement. Stock-based compensation is NOT added back; no one-off adjustments. MSFT D&A line is 'Depreciation, amortization, and other' and includes minor other non-cash items. GOOGL uses 'Depreciation of property and equipment' only (intangible amortization not separately disclosed in the cash flow statement).
A13: Market cap = share price x basic shares outstanding from the latest balance sheet / 10-Q cover (no treasury-method dilution).
A14: Enterprise value = market cap + total debt (current + non-current, excl. lease liabilities) + preferred stock + noncontrolling interests - cash & equivalents - current short-term investments / marketable securities. Non-current marketable securities and strategic equity stakes (e.g., AAPL non-current securities of 84,118; GOOGL/AMZN/MSFT AI-lab stakes) are excluded from cash.
... A20: Formatting: blue font = hard-coded inputs (each with a cell comment documenting its source); black = formulas. All derived values are live formulas.
