Workbook

Sheet Revenue Model
A1: AMD - Revenue Model
A2: USD millions. Historical segment data from 10-K FY2025 segment note; projections driven by the active scenario on the Scenarios tab.
A4: USD millions | C4: FY2023A | D4: FY2024A | E4: FY2025A | F4: FY2026E | G4: FY2027E | H4: FY2028E | I4: FY2029E | J4: FY2030E | K4: Notes / sources
A5: REVENUE BY SEGMENT / PRODUCT
A6: Data Center
A7: Data Center AI - Instinct GPUs / Helios racks (est.) | C7: 400 | D7: 5000 | E7: 6500 | F7: =E7*(1+F8) -> 17550 | G7: =F7*(1+G8) -> 33345 | H7: =G7*(1+H8) -> 48350.25 | I7: =H7*(1+I8) -> 62855.325 | J7: =I7*(1+J8) -> 75426.39 | K7: ESTIMATE: AMD does not disclose the GPU/CPU split. FY2023 ~400 (MI300 launch Dec-2023), FY2024 >5,000 per mgmt commentary (model knowledge), FY2025 ~6,500 est. (net of MI308 export-control impact).
A8: YoY growth % | D8: =D7/C7-1 -> 11.5 | E8: =E7/D7-1 -> 0.3 | F8: =Scenarios!F11 -> 1.7 | G8: =Scenarios!G11 -> 0.9 | H8: =Scenarios!H11 -> 0.45 | I8: =Scenarios!I11 -> 0.3 | J8: =Scenarios!J11 -> 0.2
A9: Server CPU (EPYC), DPU/NIC & other Data Center (derived) | C9: =C11-C7 -> 6096 | D9: =D11-D7 -> 7579 | E9: =E11-E7 -> 10135 | F9: =E9*(1+F10) -> 12364.7 | G9: =F9*(1+G10) -> 14590.346 | H9: =G9*(1+H10) -> 16632.994 | I9: =H9*(1+I10) -> 18628.954 | J9: =I9*(1+J10) -> 20491.849 | K9: Historical = reported Data Center segment revenue less estimated AI GPU revenue.
A10: YoY growth % | D10: =D9/C9-1 -> 0.24327428 | E10: =E9/D9-1 -> 0.33724766 | F10: =Scenarios!F16 -> 0.22 | G10: =Scenarios!G16 -> 0.18 | H10: =Scenarios!H16 -> 0.14 | I10: =Scenarios!I16 -> 0.12 | J10: =Scenarios!J16 -> 0.1
A11: Data Center - reported segment revenue | C11: 6496 | D11: 12579 | E11: 16635 | K11: Source: AMD 10-K FY2025, Note: Segment Reporting (XBRL R52/R54), https://www.sec.gov/Archives/edgar/data/2488/000000248826000018/R52.htm
A12: Data Center total | C12: =C11 -> 6496 | D12: =D11 -> 12579 | E12: =E11 -> 16635 | F12: =F7+F9 -> 29914.7 | G12: =G7+G9 -> 47935.346 | H12: =H7+H9 -> 64983.244 | I12: =I7+I9 -> 81484.279 | J12: =J7+J9 -> 95918.239
A13: YoY growth % | D13: =D12/C12-1 -> 0.93642241 | E13: =E12/D12-1 -> 0.32244217 | F13: =F12/E12-1 -> 0.79829877 | G13: =G12/F12-1 -> 0.60240103 | H13: =H12/G12-1 -> 0.35564359 | I13: =I12/H12-1 -> 0.25392752 | J13: =J12/I12-1 -> 0.17713798
A14: % of total revenue | C14: =C12/C37 -> 0.28641975 | D14: =D12/D37 -> 0.48784177 | E14: =E12/E37 -> 0.48023904 | F14: =F12/F37 -> 0.60824835 | G14: =G12/G37 -> 0.69995746 | H14: =H12/H37 -> 0.74399038 | I14: =I12/I37 -> 0.77562695 | J14: =J12/J37 -> 0.79979476
A15: AI GPU share of Data Center % | C15: =C7/C12 -> 0.061576355 | D15: =D7/D12 -> 0.39748788 | E15: =E7/E12 -> 0.39074241 | F15: =F7/F12 -> 0.58666809 | G15: =G7/G12 -> 0.69562448 | H15: =H7/H12 -> 0.7440418 | I15: =I7/I12 -> 0.77137978 | J15: =J7/J12 -> 0.78636129
A17: Client & Gaming
A18: Client - Ryzen desktop & notebook CPUs/APUs | C18: 4651 | D18: 7054 | E18: 10640 | F18: =E18*(1+F19) -> 12236 | G18: =F18*(1+G19) -> 12970.16 | H18: =G18*(1+H19) -> 13618.668 | I18: =H18*(1+I19) -> 14299.601 | J18: =I18*(1+J19) -> 14871.585 | K18: Source: AMD 10-K FY2025, Note: Segment Reporting (XBRL R52/R54), https://www.sec.gov/Archives/edgar/data/2488/000000248826000018/R52.htm
A19: YoY growth % | D19: =D18/C18-1 -> 0.51666308 | E19: =E18/D18-1 -> 0.50836405 | F19: =Scenarios!F21 -> 0.15 | G19: =Scenarios!G21 -> 0.06 | H19: =Scenarios!H21 -> 0.05 | I19: =Scenarios!I21 -> 0.05 | J19: =Scenarios!J21 -> 0.04
A20: Gaming - semi-custom console SoCs & Radeon GPUs | C20: 6212 | D20: 2595 | E20: 3910 | F20: =E20*(1+F21) -> 3128 | G20: =F20*(1+G21) -> 3284.4 | H20: =G20*(1+H21) -> 4105.5 | I20: =H20*(1+I21) -> 4310.775 | J20: =I20*(1+J21) -> 3879.6975 | K20: Source: AMD 10-K FY2025, Note: Segment Reporting (XBRL R52/R54), https://www.sec.gov/Archives/edgar/data/2488/000000248826000018/R52.htm
A21: YoY growth % | D21: =D20/C20-1 -> -0.58226014 | E21: =E20/D20-1 -> 0.50674374 | F21: =Scenarios!F26 -> -0.2 | G21: =Scenarios!G26 -> 0.05 | H21: =Scenarios!H26 -> 0.25 | I21: =Scenarios!I26 -> 0.05 | J21: =Scenarios!J26 -> -0.1
A22: Client & Gaming total (reportable segment) | C22: =C18+C20 -> 10863 | D22: =D18+D20 -> 9649 | E22: =E18+E20 -> 14550 | F22: =F18+F20 -> 15364 | G22: =G18+G20 -> 16254.56 | H22: =H18+H20 -> 17724.168 | I22: =I18+I20 -> 18610.376 | J22: =J18+J20 -> 18751.283
A23: YoY growth % | D23: =D22/C22-1 -> -0.1117555 | E23: =E22/D22-1 -> 0.50792828 | F23: =F22/E22-1 -> 0.055945017 | G23: =G22/F22-1 -> 0.057964072 | H23: =H22/G22-1 -> 0.090412044 | I23: =I22/H22-1 -> 0.05 | J23: =J22/I22-1 -> 0.0075713974
A24: % of total revenue | C24: =C22/C37 -> 0.47896825 | D24: =D22/D37 -> 0.37420981 | E24: =E22/E37 -> 0.42004677 | F24: =F22/F37 -> 0.31239249 | G24: =G22/G37 -> 0.23735096 | H24: =H22/H37 -> 0.20292324 | I24: =I22/I37 -> 0.17714717 | J24: =J22/J37 -> 0.15635377
A26: Embedded
A27: Embedded - Versal/Zynq adaptive SoCs, FPGAs, embedded x86 | C27: 5321 | D27: 3557 | E27: 3454 | F27: =E27*(1+F28) -> 3903.02 | G27: =F27*(1+G28) -> 4293.322 | H27: =G27*(1+H28) -> 4636.7878 | I27: =H27*(1+I28) -> 4961.3629 | J27: =I27*(1+J28) -> 5259.0447 | K27: Source: AMD 10-K FY2025, Note: Segment Reporting (XBRL R52/R54), https://www.sec.gov/Archives/edgar/data/2488/000000248826000018/R52.htm
A28: YoY growth % | D28: =D27/C27-1 -> -0.33151663 | E28: =E27/D27-1 -> -0.028956986 | F28: =Scenarios!F31 -> 0.13 | G28: =Scenarios!G31 -> 0.1 | H28: =Scenarios!H31 -> 0.08 | I28: =Scenarios!I31 -> 0.07 | J28: =Scenarios!J31 -> 0.06
A29: % of total revenue | C29: =C27/C37 -> 0.23461199 | D29: =D27/D37 -> 0.13794842 | E29: =E27/E37 -> 0.099714195 | F29: =F27/F37 -> 0.07935916 | G29: =G27/G37 -> 0.062691583 | H29: =H27/H37 -> 0.053086384 | I29: =I27/I37 -> 0.04722588 | J29: =J27/J37 -> 0.043851476
A31: Mix memo
A32: Client % of total | C32: =C18/C37 -> 0.20507055 | D32: =D18/D37 -> 0.2735699 | E32: =E18/E37 -> 0.30716822 | F32: =F18/F37 -> 0.24879162 | G32: =G18/G37 -> 0.18939177 | H32: =H18/H37 -> 0.15591955 | I32: =I18/I37 -> 0.13611406 | J32: =J18/J37 -> 0.1240037
A33: Gaming % of total | C33: =C20/C37 -> 0.27389771 | D33: =D20/D37 -> 0.10063991 | E33: =E20/E37 -> 0.11287855 | F33: =F20/F37 -> 0.063600866 | G33: =G20/G37 -> 0.047959188 | H33: =H20/H37 -> 0.047003693 | I33: =I20/I37 -> 0.041033109 | J33: =J20/J37 -> 0.03235007
A34: Data Center AI % of total | C34: =C7/C37 -> 0.017636684 | D34: =D7/D37 -> 0.19391119 | E34: =E7/E37 -> 0.18764976 | F34: =F7/F37 -> 0.3568399 | G34: =G7/G37 -> 0.48690754 | H34: =H7/H37 -> 0.55355994 | I34: =I7/I37 -> 0.59830294 | J34: =J7/J37 -> 0.62892764
A37: TOTAL NET REVENUE | C37: =C12+C22+C27 -> 22680 | D37: =D12+D22+D27 -> 25785 | E37: =E12+E22+E27 -> 34639 | F37: =F12+F22+F27 -> 49181.72 | G37: =G12+G22+G27 -> 68483.228 | H37: =H12+H22+H27 -> 87344.2 | I37: =I12+I22+I27 -> 105056.02 | J37: =J12+J22+J27 -> 119928.57
A38: Total revenue growth % | D38: =D37/C37-1 -> 0.13690476 | E38: =E37/D37-1 -> 0.34337793 | F38: =F37/E37-1 -> 0.4198366 | G38: =G37/F37-1 -> 0.39245289 | H38: =H37/G37-1 -> 0.27541009 | I38: =I37/H37-1 -> 0.20278184 | J38: =J37/I37-1 -> 0.14156779
A39: Check: reported net revenue (10-K) | C39: 22680 | D39: 25785 | E39: 34639 | K39: Source: AMD Form 10-K FY2025 (filed 2026-02-04), Item 8, https://www.sec.gov/Archives/edgar/data/2488/000000248826000018/amd-20251227.htm
A40: Check: segment sum less reported (should be 0) | C40: =C37-C39 -> 0 | D40: =D37-D39 -> 0 | E40: =E37-E39 -> 0
A42: SEGMENT OPERATING INCOME (historical, as reported)
A43: Data Center operating income | C43: 1267 | D43: 3482 | E43: 3603 | K43: Source: AMD 10-K FY2025, Note: Segment Reporting (XBRL R52/R54), https://www.sec.gov/Archives/edgar/data/2488/000000248826000018/R52.htm
A44: Data Center operating margin % | C44: =C43/C12 -> 0.1950431 | D44: =D43/D12 -> 0.27681056 | E44: =E43/E12 -> 0.21659152
A45: Client & Gaming operating income | C45: 925 | D45: 1187 | E45: 2855
A46: Client & Gaming operating margin % | C46: =C45/C22 -> 0.085151431 | D46: =D45/D22 -> 0.12301793 | E46: =E45/E22 -> 0.19621993
A47: Embedded operating income | C47: 2628 | D47: 1421 | E47: 1243
...

Sheet Income Statement
A1: AMD - Income Statement (GAAP)
A2: USD millions except per-share. FY ends last Saturday of December. Historical per 10-K FY2025 / FY2024; projections driven by Scenarios tab.
A4: USD millions | C4: FY2023A | D4: FY2024A | E4: FY2025A | F4: FY2026E | G4: FY2027E | H4: FY2028E | I4: FY2029E | J4: FY2030E | K4: Notes / sources
A5: REVENUE
A6: Data Center | C6: ='Revenue Model'!C12 -> 6496 | D6: ='Revenue Model'!D12 -> 12579 | E6: ='Revenue Model'!E12 -> 16635 | F6: ='Revenue Model'!F12 -> 29914.7 | G6: ='Revenue Model'!G12 -> 47935.346 | H6: ='Revenue Model'!H12 -> 64983.244 | I6: ='Revenue Model'!I12 -> 81484.279 | J6: ='Revenue Model'!J12 -> 95918.239
A7: Client & Gaming | C7: ='Revenue Model'!C22 -> 10863 | D7: ='Revenue Model'!D22 -> 9649 | E7: ='Revenue Model'!E22 -> 14550 | F7: ='Revenue Model'!F22 -> 15364 | G7: ='Revenue Model'!G22 -> 16254.56 | H7: ='Revenue Model'!H22 -> 17724.168 | I7: ='Revenue Model'!I22 -> 18610.376 | J7: ='Revenue Model'!J22 -> 18751.283
A8: Embedded | C8: ='Revenue Model'!C27 -> 5321 | D8: ='Revenue Model'!D27 -> 3557 | E8: ='Revenue Model'!E27 -> 3454 | F8: ='Revenue Model'!F27 -> 3903.02 | G8: ='Revenue Model'!G27 -> 4293.322 | H8: ='Revenue Model'!H27 -> 4636.7878 | I8: ='Revenue Model'!I27 -> 4961.3629 | J8: ='Revenue Model'!J27 -> 5259.0447
A9: Net revenue | C9: =SUM(C6:C8) -> 22680 | D9: =SUM(D6:D8) -> 25785 | E9: =SUM(E6:E8) -> 34639 | F9: =SUM(F6:F8) -> 49181.72 | G9: =SUM(G6:G8) -> 68483.228 | H9: =SUM(H6:H8) -> 87344.2 | I9: =SUM(I6:I8) -> 105056.02 | J9: =SUM(J6:J8) -> 119928.57 | K9: Source: AMD Form 10-K FY2025 (filed 2026-02-04), Item 8, https://www.sec.gov/Archives/edgar/data/2488/000000248826000018/amd-20251227.htm
A10: YoY growth % | D10: =D9/C9-1 -> 0.13690476 | E10: =E9/D9-1 -> 0.34337793 | F10: =F9/E9-1 -> 0.4198366 | G10: =G9/F9-1 -> 0.39245289 | H10: =H9/G9-1 -> 0.27541009 | I10: =I9/H9-1 -> 0.20278184 | J10: =J9/I9-1 -> 0.14156779
A12: COST OF SALES
A13: Cost of sales (ex-amortization) | C13: 11278 | D13: 12114 | E13: 16456 | F13: =F9*F14 -> 22377.683 | G13: =G9*G14 -> 30817.453 | H13: =H9*H14 -> 38868.169 | I13: =I9*I14 -> 46224.648 | J13: =J9*J14 -> 52768.569
A14: % of revenue | C14: =C13/C9 -> 0.49726631 | D14: =D13/D9 -> 0.46980803 | E14: =E13/E9 -> 0.47507145 | F14: =Scenarios!F36 -> 0.455 | G14: =Scenarios!G36 -> 0.45 | H14: =Scenarios!H36 -> 0.445 | I14: =Scenarios!I36 -> 0.44 | J14: =Scenarios!J36 -> 0.44
A15: Amortization of acquisition-related intangibles (COGS) | C15: 942 | D15: 946 | E15: 1031 | F15: 1040 | G15: 950 | H15: 850 | I15: 700 | J15: 600 | K15: Projection input: H1 FY2026A COGS amortization 521; declining as Xilinx intangibles roll off (estimate).
A16: Total cost of sales | C16: =C13+C15 -> 12220 | D16: =D13+D15 -> 13060 | E16: =E13+E15 -> 17487 | F16: =F13+F15 -> 23417.683 | G16: =G13+G15 -> 31767.453 | H16: =H13+H15 -> 39718.169 | I16: =I13+I15 -> 46924.648 | J16: =J13+J15 -> 53368.569
A17: GROSS PROFIT | C17: =C9-C16 -> 10460 | D17: =D9-D16 -> 12725 | E17: =E9-E16 -> 17152 | F17: =F9-F16 -> 25764.037 | G17: =G9-G16 -> 36715.775 | H17: =H9-H16 -> 47626.031 | I17: =I9-I16 -> 58131.37 | J17: =J9-J16 -> 66559.997
A18: Gross margin % (GAAP) | C18: =C17/C9 -> 0.46119929 | D18: =D17/D9 -> 0.49350398 | E18: =E17/E9 -> 0.49516441 | F18: =F17/F9 -> 0.52385393 | G18: =G17/G9 -> 0.53612799 | H18: =H17/H9 -> 0.54526839 | I18: =I17/I9 -> 0.55333689 | J18: =J17/J9 -> 0.55499702
A19: Gross margin % ex-amortization | C19: =1-C14 -> 0.50273369 | D19: =1-D14 -> 0.53019197 | E19: =1-E14 -> 0.52492855 | F19: =1-F14 -> 0.545 | G19: =1-G14 -> 0.55 | H19: =1-H14 -> 0.555 | I19: =1-I14 -> 0.56 | J19: =1-J14 -> 0.56
A21: OPERATING EXPENSES
A22: Research and development | C22: 5872 | D22: 6456 | E22: 8091 | F22: =F9*F23 -> 10328.161 | G22: =G9*G23 -> 13354.229 | H22: =H9*H23 -> 15721.956 | I22: =I9*I23 -> 17859.523 | J22: =J9*J23 -> 19788.214
A23: % of revenue | C23: =C22/C9 -> 0.25890653 | D23: =D22/D9 -> 0.25037813 | E23: =E22/E9 -> 0.23358065 | F23: =Scenarios!F41 -> 0.21 | G23: =Scenarios!G41 -> 0.195 | H23: =Scenarios!H41 -> 0.18 | I23: =Scenarios!I41 -> 0.17 | J23: =Scenarios!J41 -> 0.165
A24: Marketing, general & administrative (net of licensing gain) | C24: 2318 | D24: 2735 | E24: 4144 | F24: =F9*F25 -> 5655.8978 | G24: =G9*G25 -> 7190.7389 | H24: =H9*H25 -> 8297.699 | I24: =I9*I25 -> 9455.0416 | J24: =J9*J25 -> 10193.928 | K24: FY2023/FY2024 shown net of licensing gain (34 / 48) to match FY2025 10-K presentation.
A25: % of revenue | C25: =C24/C9 -> 0.10220459 | D25: =D24/D9 -> 0.10606942 | E25: =E24/E9 -> 0.11963394 | F25: =Scenarios!F46 -> 0.115 | G25: =Scenarios!G46 -> 0.105 | H25: =Scenarios!H46 -> 0.095 | I25: =Scenarios!I46 -> 0.09 | J25: =Scenarios!J46 -> 0.085
A26: Amortization of acquisition-related intangibles (opex) | C26: 1869 | D26: 1448 | E26: 1223 | F26: 1140 | G26: 900 | H26: 700 | I26: 500 | J26: 400 | K26: Projection input: H1 FY2026A opex amortization 574 (estimate of run-off).
A27: Restructuring charges | C27: 0 | D27: 186 | E27: 0 | F27: 0 | G27: 0 | H27: 0 | I27: 0 | J27: 0
A28: Total operating expenses | C28: =C22+C24+C26+C27 -> 10059 | D28: =D22+D24+D26+D27 -> 10825 | E28: =E22+E24+E26+E27 -> 13458 | F28: =F22+F24+F26+F27 -> 17124.059 | G28: =G22+G24+G26+G27 -> 21444.968 | H28: =H22+H24+H26+H27 -> 24719.655 | I28: =I22+I24+I26+I27 -> 27814.565 | J28: =J22+J24+J26+J27 -> 30382.142
A29: % of revenue | C29: =C28/C9 -> 0.44351852 | D29: =D28/D9 -> 0.41981772 | E29: =E28/E9 -> 0.38852161 | F29: =F28/F9 -> 0.34817934 | G29: =G28/G9 -> 0.3131419 | H29: =H28/H9 -> 0.28301427 | I29: =I28/I9 -> 0.26475937 | J29: =J28/J9 -> 0.25333532
A31: OPERATING INCOME (EBIT) | C31: =C17-C28 -> 401 | D31: =D17-D28 -> 1900 | E31: =E17-E28 -> 3694 | F31: =F17-F28 -> 8639.9784 | G31: =G17-G28 -> 15270.807 | H31: =H17-H28 -> 22906.376 | I31: =I17-I28 -> 30316.805 | J31: =J17-J28 -> 36177.856
A32: Operating margin % | C32: =C31/C9 -> 0.017680776 | D32: =D31/D9 -> 0.073686252 | E32: =E31/E9 -> 0.1066428 | F32: =F31/F9 -> 0.17567459 | G32: =G31/G9 -> 0.22298609 | H32: =H31/H9 -> 0.26225412 | I32: =I31/I9 -> 0.28857752 | J32: =J31/J9 -> 0.3016617
A33: Check: reported operating income | C33: 401 | D33: 1900 | E33: 3694
A34: Check: difference (should be 0) | C34: =C31-C33 -> 0 | D34: =D31-D33 -> 0 | E34: =E31-E33 -> 0
A36: EBITDA & NON-GAAP BRIDGE (memo)
A37: Depreciation & amortization of PP&E (from cash flow) | C37: ='Cash Flow Statement'!C8 -> 642 | D37: ='Cash Flow Statement'!D8 -> 671 | E37: ='Cash Flow Statement'!E8 -> 750 | F37: ='Cash Flow Statement'!F8 -> 855.44 | G37: ='Cash Flow Statement'!G8 -> 1448.789 | H37: ='Cash Flow Statement'!H8 -> 2052.9828 | I37: ='Cash Flow Statement'!I8 -> 2586.0733 | J37: ='Cash Flow Statement'!J8 -> 2989.7016
A38: Amortization of acquisition-related intangibles (total) | C38: =C15+C26 -> 2811 | D38: =D15+D26 -> 2394 | E38: =E15+E26 -> 2254 | F38: =F15+F26 -> 2180 | G38: =G15+G26 -> 1850 | H38: =H15+H26 -> 1550 | I38: =I15+I26 -> 1200 | J38: =J15+J26 -> 1000
A39: EBITDA | C39: =C31+C37+C38 -> 3854 | D39: =D31+D37+D38 -> 4965 | E39: =E31+E37+E38 -> 6698 | F39: =F31+F37+F38 -> 11675.418 | G39: =G31+G37+G38 -> 18569.596 | H39: =H31+H37+H38 -> 26509.359 | I39: =I31+I37+I38 -> 34102.879 | J39: =J31+J37+J38 -> 40167.557
A40: EBITDA margin % | C40: =C39/C9 -> 0.16992945 | D40: =D39/D9 -> 0.19255381 | E40: =E39/E9 -> 0.19336586 | F40: =F39/F9 -> 0.23739345 | G40: =G39/G9 -> 0.27115538 | H40: =H39/H9 -> 0.30350451 | I40: =I39/I9 -> 0.32461614 | J40: =J39/J9 -> 0.33492902
A41: Stock-based compensation (from cash flow) | C41: ='Cash Flow Statement'!C11 -> 1384 | D41: ='Cash Flow Statement'!D11 -> 1407 | E41: ='Cash Flow Statement'!E11 -> 1638 | F41: ='Cash Flow Statement'!F11 -> 2213.1774 | G41: ='Cash Flow Statement'!G11 -> 2739.3291 | H41: ='Cash Flow Statement'!H11 -> 3231.7354 | I41: ='Cash Flow Statement'!I11 -> 3676.9606 | J41: ='Cash Flow Statement'!J11 -> 3957.6427
A42: Adjusted operating income (EBIT + amortization + SBC + restructuring) | C42: =C31+C38+C41+C27 -> 4596 | D42: =D31+D38+D41+D27 -> 5887 | E42: =E31+E38+E41+E27 -> 7586 | F42: =F31+F38+F41+F27 -> 13033.156 | G42: =G31+G38+G41+G27 -> 19860.136 | H42: =H31+H38+H41+H27 -> 27688.111 | I42: =I31+I38+I41+I27 -> 35193.766 | J42: =J31+J38+J41+J27 -> 41135.498 | K42: Approximation of AMD non-GAAP operating income (FY2025 reported non-GAAP 7,768 also excludes MI308 inventory charges and other items).
A43: Adjusted operating margin % | C43: =C42/C9 -> 0.2026455 | D43: =D42/D9 -> 0.22831103 | E43: =E42/E9 -> 0.2190017 | F43: =F42/F9 -> 0.265 | G43: =G42/G9 -> 0.29 | H43: =H42/H9 -> 0.317 | I43: =I42/I9 -> 0.335 | J43: =J42/J9 -> 0.343
A45: BELOW THE LINE
A46: Interest expense | C46: -106 | D46: -92 | E46: -131 | F46: =-F47*'Balance Sheet'!E51 -> -144.99 | G46: =-G47*'Balance Sheet'!F51 -> -105.66 | H46: =-H47*'Balance Sheet'!G51 -> -105.66 | I46: =-I47*'Balance Sheet'!H51 -> -105.66 | J46: =-J47*'Balance Sheet'!I51 -> -105.66
...

Sheet Cash Flow Statement
A1: AMD - Cash Flow Statement
A2: USD millions. Historical per 10-K FY2025 (Item 8); projections link to Income Statement / Balance Sheet drivers.
A4: USD millions | C4: FY2023A | D4: FY2024A | E4: FY2025A | F4: FY2026E | G4: FY2027E | H4: FY2028E | I4: FY2029E | J4: FY2030E | K4: Notes / sources
A5: OPERATING ACTIVITIES
A6: Net income | C6: ='Income Statement'!C56 -> 854 | D6: ='Income Statement'!D56 -> 1641 | E6: ='Income Statement'!E56 -> 4335 | F6: ='Income Statement'!F56 -> 7736.9483 | G6: ='Income Statement'!G56 -> 13411.414 | H6: ='Income Statement'!H56 -> 20204.656 | I6: ='Income Statement'!I56 -> 26977.517 | J6: ='Income Statement'!J56 -> 32588.981
A7: Less: income from discontinued operations | C7: 0 | D7: 0 | E7: -66 | F7: =-'Income Statement'!F55 -> 0 | G7: =-'Income Statement'!G55 -> 0 | H7: =-'Income Statement'!H55 -> 0 | I7: =-'Income Statement'!I55 -> 0 | J7: =-'Income Statement'!J55 -> 0
A8: Depreciation & amortization (PP&E and other) | C8: 642 | D8: 671 | E8: 750 | F8: ='Balance Sheet'!E15*F9 -> 855.44 | G8: ='Balance Sheet'!F15*G9 -> 1448.789 | H8: ='Balance Sheet'!G15*H9 -> 2052.9828 | I8: ='Balance Sheet'!H15*I9 -> 2586.0733 | J8: ='Balance Sheet'!I15*J9 -> 2989.7016
A9: D&A as % of beginning net PP&E | D9: =D8/'Balance Sheet'!C15 -> 0.42227816 | E9: =E8/'Balance Sheet'!D15 -> 0.41620422 | F9: 0.37 | G9: 0.37 | H9: 0.37 | I9: 0.37 | J9: 0.37 | K9: FY2025A 41.6%; H1 FY2026A annualised ~37% of opening PP&E.
A10: Amortization of acquisition-related intangibles | C10: 2811 | D10: 2393 | E10: 2254 | F10: ='Income Statement'!F38 -> 2180 | G10: ='Income Statement'!G38 -> 1850 | H10: ='Income Statement'!H38 -> 1550 | I10: ='Income Statement'!I38 -> 1200 | J10: ='Income Statement'!J38 -> 1000 | K10: Historical cash-flow amortization line (includes small non-intangible items vs. P&L amortization).
A11: Stock-based compensation | C11: 1384 | D11: 1407 | E11: 1638 | F11: ='Income Statement'!F9*F12 -> 2213.1774 | G11: ='Income Statement'!G9*G12 -> 2739.3291 | H11: ='Income Statement'!H9*H12 -> 3231.7354 | I11: ='Income Statement'!I9*I12 -> 3676.9606 | J11: ='Income Statement'!J9*J12 -> 3957.6427
A12: SBC % of revenue | C12: =C11/'Income Statement'!C9 -> 0.061022928 | D12: =D11/'Income Statement'!D9 -> 0.054566608 | E12: =E11/'Income Statement'!E9 -> 0.047287739 | F12: 0.045 | G12: 0.04 | H12: 0.037 | I12: 0.035 | J12: 0.033 | K12: H1 FY2026A 4.5%.
A13: Deferred income taxes | C13: -1019 | D13: -1163 | E13: 248 | F13: 0 | G13: 0 | H13: 0 | I13: 0 | J13: 0
A14: (Gains) losses on investments, net | C14: -1 | D14: 0 | E14: -341 | F14: 0 | G14: 0 | H14: 0 | I14: 0 | J14: 0
A15: Other non-cash items (incl. contract-manufacturer inventory loss) | C15: 45 | D15: 190 | E15: 53 | F15: 0 | G15: 0 | H15: 0 | I15: 0 | J15: 0
A16: Changes in operating assets and liabilities:
A17: Accounts receivable, net | C17: -1339 | D17: -1865 | E17: -121 | F17: =-('Balance Sheet'!F8-'Balance Sheet'!E8) -> -2443.3885 | G17: =-('Balance Sheet'!G8-'Balance Sheet'!F8) -> -3437.2548 | H17: =-('Balance Sheet'!H8-'Balance Sheet'!G8) -> -3358.8033 | I17: =-('Balance Sheet'!I8-'Balance Sheet'!H8) -> -3154.1593 | J17: =-('Balance Sheet'!J8-'Balance Sheet'!I8) -> -2648.5361
A18: Inventories | C18: -580 | D18: -1458 | E18: -2189 | F18: =-('Balance Sheet'!F10-'Balance Sheet'!E10) -> -1889.3951 | G18: =-('Balance Sheet'!G10-'Balance Sheet'!F10) -> -2855.3114 | H18: =-('Balance Sheet'!H10-'Balance Sheet'!G10) -> -2243.6323 | I18: =-('Balance Sheet'!I10-'Balance Sheet'!H10) -> -2188.4488 | J18: =-('Balance Sheet'!J10-'Balance Sheet'!I10) -> -1697.4974
A19: Prepaid expenses and other assets | C19: -390 | D19: 339 | E19: -11 | F19: =-('Balance Sheet'!F12-'Balance Sheet'!E12) -> -790.9032 | G19: =-('Balance Sheet'!G12-'Balance Sheet'!F12) -> -1158.0905 | H19: =-('Balance Sheet'!H12-'Balance Sheet'!G12) -> -1131.6583 | I19: =-('Balance Sheet'!I12-'Balance Sheet'!H12) -> -1062.7091 | J19: =-('Balance Sheet'!J12-'Balance Sheet'!I12) -> -892.35292
A20: Accounts payable | C20: -519 | D20: 3 | E20: 410 | F20: ='Balance Sheet'!F23-'Balance Sheet'!E23 -> 1669.154 | G20: ='Balance Sheet'!G23-'Balance Sheet'!F23 -> 1734.1993 | H20: ='Balance Sheet'!H23-'Balance Sheet'!G23 -> 1654.2568 | I20: ='Balance Sheet'!I23-'Balance Sheet'!H23 -> 1511.6052 | J20: ='Balance Sheet'!J23-'Balance Sheet'!I23 -> 1344.6414
A21: Accrued and other liabilities | C21: -221 | D21: 883 | E21: -467 | F21: =('Balance Sheet'!F25-'Balance Sheet'!E25)+('Balance Sheet'!F28-'Balance Sheet'!E28) -> 1823.6214 | G21: =('Balance Sheet'!G25-'Balance Sheet'!F25)+('Balance Sheet'!G28-'Balance Sheet'!F28) -> 2933.8292 | H21: =('Balance Sheet'!H25-'Balance Sheet'!G25)+('Balance Sheet'!H28-'Balance Sheet'!G28) -> 2866.8678 | I21: =('Balance Sheet'!I25-'Balance Sheet'!H25)+('Balance Sheet'!I28-'Balance Sheet'!H28) -> 2692.1963 | J21: =('Balance Sheet'!J25-'Balance Sheet'!I25)+('Balance Sheet'!J28-'Balance Sheet'!I28) -> 2260.6274
A22: Cash from operations - continuing | C22: =SUM(C6:C21)-C9-C12 -> 1667 | D22: =SUM(D6:D21)-D9-D12 -> 3041 | E22: =SUM(E6:E21)-E9-E12 -> 6493 | F22: =SUM(F6:F21)-F9-F12 -> 11354.654 | G22: =SUM(G6:G21)-G9-G12 -> 16666.904 | H22: =SUM(H6:H21)-H9-H12 -> 24826.405 | I22: =SUM(I6:I21)-I9-I12 -> 32239.035 | J22: =SUM(J6:J21)-J9-J12 -> 38903.208
A23: Cash from operations - discontinued | C23: 0 | D23: 0 | E23: 1216 | F23: 0 | G23: 0 | H23: 0 | I23: 0 | J23: 0
A24: NET CASH FROM OPERATING ACTIVITIES | C24: =C22+C23 -> 1667 | D24: =D22+D23 -> 3041 | E24: =E22+E23 -> 7709 | F24: =F22+F23 -> 11354.654 | G24: =G22+G23 -> 16666.904 | H24: =H22+H23 -> 24826.405 | I24: =I22+I23 -> 32239.035 | J24: =J22+J23 -> 38903.208
A26: INVESTING ACTIVITIES
A27: Purchases of property and equipment (capex) | C27: -546 | D27: -636 | E27: -974 | F27: =-'Income Statement'!F9*F28 -> -2459.086 | G27: =-'Income Statement'!G9*G28 -> -3081.7453 | H27: =-'Income Statement'!H9*H28 -> -3493.768 | I27: =-'Income Statement'!I9*I28 -> -3676.9606 | J27: =-'Income Statement'!J9*J28 -> -4197.4998
A28: Capex % of revenue | C28: =-C27/'Income Statement'!C9 -> 0.024074074 | D28: =-D27/'Income Statement'!D9 -> 0.024665503 | E28: =-E27/'Income Statement'!E9 -> 0.028118595 | F28: 0.05 | G28: 0.045 | H28: 0.04 | I28: 0.035 | J28: 0.035 | K28: H1 FY2026A 5.5% (1,197 / 21,789) as rack-scale/test capacity builds.
A29: Purchases of short-term investments | C29: -3722 | D29: -1493 | E29: -5470 | F29: 0 | G29: 0 | H29: 0 | I29: 0 | J29: 0 | K29: Projection default: short-term investments held flat; excess cash accumulates in cash & equivalents.
A30: Proceeds from maturities & sales of short-term investments | C30: 2987 | D30: 2032 | E30: 1845 | F30: 0 | G30: 0 | H30: 0 | I30: 0 | J30: 0
A31: Acquisitions, net of cash acquired | C31: -131 | D31: -548 | E31: -1760 | F31: 0 | G31: 0 | H31: 0 | I31: 0 | J31: 0 | K31: No M&A assumed in projections.
A32: Purchases of long-term / equity-method investments | C32: -11 | D32: -458 | E32: -502 | F32: 0 | G32: 0 | H32: 0 | I32: 0 | J32: 0
A33: Other investing | C33: 0 | D33: 2 | E33: 10 | F33: 0 | G33: 0 | H33: 0 | I33: 0 | J33: 0
A34: Cash from investing - continuing | C34: =SUM(C27:C33)-C28 -> -1423 | D34: =SUM(D27:D33)-D28 -> -1101 | E34: =SUM(E27:E33)-E28 -> -6851 | F34: =SUM(F27:F33)-F28 -> -2459.086 | G34: =SUM(G27:G33)-G28 -> -3081.7453 | H34: =SUM(H27:H33)-H28 -> -3493.768 | I34: =SUM(I27:I33)-I28 -> -3676.9606 | J34: =SUM(J27:J33)-J28 -> -4197.4998
A35: Cash from investing - discontinued (Sanmina divestiture) | C35: 0 | D35: 0 | E35: 1318 | F35: 0 | G35: 0 | H35: 0 | I35: 0 | J35: 0
A36: NET CASH FROM INVESTING ACTIVITIES | C36: =C34+C35 -> -1423 | D36: =D34+D35 -> -1101 | E36: =E34+E35 -> -5533 | F36: =F34+F35 -> -2459.086 | G36: =G34+G35 -> -3081.7453 | H36: =H34+H35 -> -3493.768 | I36: =I34+I35 -> -3676.9606 | J36: =J34+J35 -> -4197.4998
A38: FINANCING ACTIVITIES
A39: Proceeds from debt / commercial paper issuance | C39: 0 | D39: 0 | E39: 2441 | F39: 0 | G39: 0 | H39: 0 | I39: 0 | J39: 0
A40: Repayment of debt / commercial paper | C40: 0 | D40: -750 | E40: -950 | F40: -874 | G40: 0 | H40: 0 | I40: 0 | J40: 0 | K40: FY2026: current portion (874) assumed repaid without refinancing; maturities thereafter not modelled (assumption).
A41: Proceeds from employee equity plans | C41: 268 | D41: 279 | E41: 285 | F41: 300 | G41: 300 | H41: 300 | I41: 300 | J41: 300
A42: Repurchases of common stock | C42: -985 | D42: -862 | E42: -1316 | F42: -1500 | G42: -3000 | H42: -5000 | I42: -7000 | J42: -9000 | K42: Buyback assumption (H1 FY2026A 221). Scenario-independent.
A43: Tax withholding on employee equity plans | C43: -427 | D43: -728 | E43: -607 | F43: -700 | G43: -700 | H43: -700 | I43: -700 | J43: -700
...

Sheet Balance Sheet
A1: AMD - Balance Sheet
A2: USD millions. FY2023 per 10-K FY2024; FY2024-FY2025 per 10-K FY2025 (FY2025 line-item presentation). Cash is the model plug via the cash flow statement.
A4: USD millions | C4: FY2023A | D4: FY2024A | E4: FY2025A | F4: FY2026E | G4: FY2027E | H4: FY2028E | I4: FY2029E | J4: FY2030E | K4: Notes / sources
A5: ASSETS
A6: Cash and cash equivalents | C6: 3933 | D6: 3787 | E6: 5539 | F6: ='Cash Flow Statement'!F49 -> 11660.568 | G6: ='Cash Flow Statement'!G49 -> 21845.727 | H6: ='Cash Flow Statement'!H49 -> 37778.363 | I6: ='Cash Flow Statement'!I49 -> 58940.438 | J6: ='Cash Flow Statement'!J49 -> 84246.146 | K6: Source: AMD Form 10-K FY2025 (filed 2026-02-04), Item 8, https://www.sec.gov/Archives/edgar/data/2488/000000248826000018/amd-20251227.htm
A7: Short-term investments | C7: 1840 | D7: 1345 | E7: 5013 | F7: =E7-'Cash Flow Statement'!F29-'Cash Flow Statement'!F30 -> 5013 | G7: =F7-'Cash Flow Statement'!G29-'Cash Flow Statement'!G30 -> 5013 | H7: =G7-'Cash Flow Statement'!H29-'Cash Flow Statement'!H30 -> 5013 | I7: =H7-'Cash Flow Statement'!I29-'Cash Flow Statement'!I30 -> 5013 | J7: =I7-'Cash Flow Statement'!J29-'Cash Flow Statement'!J30 -> 5013
A8: Accounts receivable, net | C8: 4323 | D8: 6192 | E8: 6315 | F8: ='Income Statement'!F9*F9/365 -> 8758.3885 | G8: ='Income Statement'!G9*G9/365 -> 12195.643 | H8: ='Income Statement'!H9*H9/365 -> 15554.447 | I8: ='Income Statement'!I9*I9/365 -> 18708.606 | J8: ='Income Statement'!J9*J9/365 -> 21357.142
A9: DSO (days of revenue) | C9: =C8/'Income Statement'!C9*365 -> 69.57209 | D9: =D8/'Income Statement'!D9*365 -> 87.65096 | E9: =E8/'Income Statement'!E9*365 -> 66.54277 | F9: 65 | G9: 65 | H9: 65 | I9: 65 | J9: 65
A10: Inventories | C10: 4351 | D10: 5734 | E10: 7920 | F10: ='Income Statement'!F13*F11/365 -> 9809.3951 | G10: ='Income Statement'!G13*G11/365 -> 12664.707 | H10: ='Income Statement'!H13*H11/365 -> 14908.339 | I10: ='Income Statement'!I13*I11/365 -> 17096.788 | J10: ='Income Statement'!J13*J11/365 -> 18794.285
A11: DIO (days of cost of sales ex-amortization) | C11: =C10/'Income Statement'!C13*365 -> 140.8153 | D11: =D10/'Income Statement'!D13*365 -> 172.76787 | E11: =E10/'Income Statement'!E13*365 -> 175.66845 | F11: 160 | G11: 150 | H11: 140 | I11: 135 | J11: 130 | K11: FY2025A 175.7 days; inventory build ahead of MI450/Helios ramp expected to turn.
A12: Prepaid expenses and other current assets | C12: 2321 | D12: 1991 | E12: 2160 | F12: ='Income Statement'!F9*F13 -> 2950.9032 | G12: ='Income Statement'!G9*G13 -> 4108.9937 | H12: ='Income Statement'!H9*H13 -> 5240.652 | I12: ='Income Statement'!I9*I13 -> 6303.3611 | J12: ='Income Statement'!J9*J13 -> 7195.714 | K12: FY2023 = prepaid 2,312 + other receivables 9 (FY2025 presentation).
A13: % of revenue | C13: =C12/'Income Statement'!C9 -> 0.10233686 | D13: =D12/'Income Statement'!D9 -> 0.077215435 | E13: =E12/'Income Statement'!E9 -> 0.062357458 | F13: 0.06 | G13: 0.06 | H13: 0.06 | I13: 0.06 | J13: 0.06
A14: Total current assets | C14: =C6+C7+C8+C10+C12 -> 16768 | D14: =D6+D7+D8+D10+D12 -> 19049 | E14: =E6+E7+E8+E10+E12 -> 26947 | F14: =F6+F7+F8+F10+F12 -> 38192.255 | G14: =G6+G7+G8+G10+G12 -> 55828.07 | H14: =H6+H7+H8+H10+H12 -> 78494.801 | I14: =I6+I7+I8+I10+I12 -> 106062.19 | J14: =J6+J7+J8+J10+J12 -> 136606.29
A15: Property and equipment, net | C15: 1589 | D15: 1802 | E15: 2312 | F15: =E15-'Cash Flow Statement'!F27-'Cash Flow Statement'!F8 -> 3915.646 | G15: =F15-'Cash Flow Statement'!G27-'Cash Flow Statement'!G8 -> 5548.6022 | H15: =G15-'Cash Flow Statement'!H27-'Cash Flow Statement'!H8 -> 6989.3874 | I15: =H15-'Cash Flow Statement'!I27-'Cash Flow Statement'!I8 -> 8080.2747 | J15: =I15-'Cash Flow Statement'!J27-'Cash Flow Statement'!J8 -> 9288.0729
A16: Goodwill | C16: 24262 | D16: 24839 | E16: 25126 | F16: =E16 -> 25126 | G16: =F16 -> 25126 | H16: =G16 -> 25126 | I16: =H16 -> 25126 | J16: =I16 -> 25126
A17: Acquisition-related intangibles, net | C17: 21363 | D17: 18930 | E17: 16705 | F17: =E17-'Cash Flow Statement'!F10 -> 14525 | G17: =F17-'Cash Flow Statement'!G10 -> 12675 | H17: =G17-'Cash Flow Statement'!H10 -> 11125 | I17: =H17-'Cash Flow Statement'!I10 -> 9925 | J17: =I17-'Cash Flow Statement'!J10 -> 8925
A18: Deferred tax assets, net | C18: 366 | D18: 688 | E18: 384 | F18: =E18 -> 384 | G18: =F18 -> 384 | H18: =G18 -> 384 | I18: =H18 -> 384 | J18: =I18 -> 384
A19: Other non-current assets (incl. ROU assets, equity-method investment) | C19: 3537 | D19: 3918 | E19: 5452 | F19: =E19-'Cash Flow Statement'!F32-'Cash Flow Statement'!F31-'Cash Flow Statement'!F33 -> 5452 | G19: =F19-'Cash Flow Statement'!G32-'Cash Flow Statement'!G31-'Cash Flow Statement'!G33 -> 5452 | H19: =G19-'Cash Flow Statement'!H32-'Cash Flow Statement'!H31-'Cash Flow Statement'!H33 -> 5452 | I19: =H19-'Cash Flow Statement'!I32-'Cash Flow Statement'!I31-'Cash Flow Statement'!I33 -> 5452 | J19: =I19-'Cash Flow Statement'!J32-'Cash Flow Statement'!J31-'Cash Flow Statement'!J33 -> 5452 | K19: FY2023 = ROU 633 + equity-method 99 + other 2,805; FY2024 = 623 + 149 + 3,146.
A20: TOTAL ASSETS | C20: =C14+C15+C16+C17+C18+C19 -> 67885 | D20: =D14+D15+D16+D17+D18+D19 -> 69226 | E20: =E14+E15+E16+E17+E18+E19 -> 76926 | F20: =F14+F15+F16+F17+F18+F19 -> 87594.901 | G20: =G14+G15+G16+G17+G18+G19 -> 105013.67 | H20: =H14+H15+H16+H17+H18+H19 -> 127571.19 | I20: =I14+I15+I16+I17+I18+I19 -> 155029.47 | J20: =J14+J15+J16+J17+J18+J19 -> 185781.36
A22: LIABILITIES
A23: Accounts payable | C23: 2418 | D23: 2466 | E23: 2929 | F23: ='Income Statement'!F13*F24/365 -> 4598.154 | G23: ='Income Statement'!G13*G24/365 -> 6332.3533 | H23: ='Income Statement'!H13*H24/365 -> 7986.6101 | I23: ='Income Statement'!I13*I24/365 -> 9498.2153 | J23: ='Income Statement'!J13*J24/365 -> 10842.857 | K23: FY2023/FY2024 include 'accounts payable, other' (363 / 476) to match FY2025 presentation.
A24: DPO (days of cost of sales ex-amortization) | C24: =C23/'Income Statement'!C13*365 -> 78.255896 | D24: =D23/'Income Statement'!D13*365 -> 74.301634 | E24: =E23/'Income Statement'!E13*365 -> 64.966274 | F24: 75 | G24: 75 | H24: 75 | I24: 75 | J24: 75 | K24: FY2025A 65.0; Q2 FY2026A payables 5,359 (elevated).
A25: Accrued liabilities | C25: 3082 | D25: 4260 | E25: 5250 | F25: ='Income Statement'!F9*F26 -> 6885.4408 | G25: ='Income Statement'!G9*G26 -> 9587.6519 | H25: ='Income Statement'!H9*H26 -> 12228.188 | I25: ='Income Statement'!I9*I26 -> 14707.843 | J25: ='Income Statement'!J9*J26 -> 16789.999
A26: % of revenue | C26: =C25/'Income Statement'!C9 -> 0.13589065 | D26: =D25/'Income Statement'!D9 -> 0.16521233 | E26: =E25/'Income Statement'!E9 -> 0.15156327 | F26: 0.14 | G26: 0.14 | H26: 0.14 | I26: 0.14 | J26: 0.14
A27: Current portion of long-term debt, net | C27: 751 | D27: 0 | E27: 874 | F27: 0 | G27: 0 | H27: 0 | I27: 0 | J27: 0
A28: Other current liabilities | C28: 438 | D28: 555 | E28: 402 | F28: ='Income Statement'!F9*F29 -> 590.18064 | G28: ='Income Statement'!G9*G29 -> 821.79874 | H28: ='Income Statement'!H9*H29 -> 1048.1304 | I28: ='Income Statement'!I9*I29 -> 1260.6722 | J28: ='Income Statement'!J9*J29 -> 1439.1428
A29: % of revenue | C29: =C28/'Income Statement'!C9 -> 0.019312169 | D29: =D28/'Income Statement'!D9 -> 0.021524142 | E29: =E28/'Income Statement'!E9 -> 0.011605416 | F29: 0.012 | G29: 0.012 | H29: 0.012 | I29: 0.012 | J29: 0.012
A30: Total current liabilities | C30: =C23+C25+C27+C28 -> 6689 | D30: =D23+D25+D27+D28 -> 7281 | E30: =E23+E25+E27+E28 -> 9455 | F30: =F23+F25+F27+F28 -> 12073.775 | G30: =G23+G25+G27+G28 -> 16741.804 | H30: =H23+H25+H27+H28 -> 21262.929 | I30: =I23+I25+I27+I28 -> 25466.73 | J30: =J23+J25+J27+J28 -> 29071.999
A31: Long-term debt, net of current portion | C31: 1717 | D31: 1721 | E31: 2348 | F31: =E31+E27-F27+'Cash Flow Statement'!F39+'Cash Flow Statement'!F40 -> 2348 | G31: =F31+F27-G27+'Cash Flow Statement'!G39+'Cash Flow Statement'!G40 -> 2348 | H31: =G31+G27-H27+'Cash Flow Statement'!H39+'Cash Flow Statement'!H40 -> 2348 | I31: =H31+H27-I27+'Cash Flow Statement'!I39+'Cash Flow Statement'!I40 -> 2348 | J31: =I31+I27-J27+'Cash Flow Statement'!J39+'Cash Flow Statement'!J40 -> 2348
A32: Long-term operating lease liabilities | C32: 535 | D32: 491 | E32: 625 | F32: =E32 -> 625 | G32: =F32 -> 625 | H32: =G32 -> 625 | I32: =H32 -> 625 | J32: =I32 -> 625
A33: Deferred tax liabilities | C33: 1202 | D33: 349 | E33: 313 | F33: =E33 -> 313 | G33: =F33 -> 313 | H33: =G33 -> 313 | I33: =H33 -> 313 | J33: =I33 -> 313
A34: Other long-term liabilities | C34: 1850 | D34: 1816 | E34: 1186 | F34: =E34 -> 1186 | G34: =F34 -> 1186 | H34: =G34 -> 1186 | I34: =H34 -> 1186 | J34: =I34 -> 1186
A35: TOTAL LIABILITIES | C35: =C30+C31+C32+C33+C34 -> 11993 | D35: =D30+D31+D32+D33+D34 -> 11658 | E35: =E30+E31+E32+E33+E34 -> 13927 | F35: =F30+F31+F32+F33+F34 -> 16545.775 | G35: =G30+G31+G32+G33+G34 -> 21213.804 | H35: =H30+H31+H32+H33+H34 -> 25734.929 | I35: =I30+I31+I32+I33+I34 -> 29938.73 | J35: =J30+J31+J32+J33+J34 -> 33543.999
A37: STOCKHOLDERS' EQUITY
A38: Common stock + additional paid-in capital | C38: 59693 | D38: 61379 | E38: 63382 | F38: =E38+'Cash Flow Statement'!F11+'Cash Flow Statement'!F41+'Cash Flow Statement'!F43 -> 65195.177 | G38: =F38+'Cash Flow Statement'!G11+'Cash Flow Statement'!G41+'Cash Flow Statement'!G43 -> 67534.507 | H38: =G38+'Cash Flow Statement'!H11+'Cash Flow Statement'!H41+'Cash Flow Statement'!H43 -> 70366.242 | I38: =H38+'Cash Flow Statement'!I11+'Cash Flow Statement'!I41+'Cash Flow Statement'!I43 -> 73643.203 | J38: =I38+'Cash Flow Statement'!J11+'Cash Flow Statement'!J41+'Cash Flow Statement'!J43 -> 77200.845 | K38: Common stock (17) + APIC. Tax withholding charged to APIC in projections (historically to treasury).
A39: Treasury stock | C39: -4514 | D39: -6106 | E39: -7079 | F39: =E39+'Cash Flow Statement'!F42 -> -8579 | G39: =F39+'Cash Flow Statement'!G42 -> -11579 | H39: =G39+'Cash Flow Statement'!H42 -> -16579 | I39: =H39+'Cash Flow Statement'!I42 -> -23579 | J39: =I39+'Cash Flow Statement'!J42 -> -32579 | K39: AMD retired 7,655 of treasury stock in Q2 FY2026 (reclass within equity, no effect on total); not modelled.
A40: Retained earnings | C40: 723 | D40: 2364 | E40: 6699 | F40: =E40+'Income Statement'!F56 -> 14435.948 | G40: =F40+'Income Statement'!G56 -> 27847.362 | H40: =G40+'Income Statement'!H56 -> 48052.018 | I40: =H40+'Income Statement'!I56 -> 75029.534 | J40: =I40+'Income Statement'!J56 -> 107618.52
A41: Accumulated other comprehensive loss | C41: -10 | D41: -69 | E41: -3 | F41: =E41 -> -3 | G41: =F41 -> -3 | H41: =G41 -> -3 | I41: =H41 -> -3 | J41: =I41 -> -3
A42: TOTAL STOCKHOLDERS' EQUITY | C42: =C38+C39+C40+C41 -> 55892 | D42: =D38+D39+D40+D41 -> 57568 | E42: =E38+E39+E40+E41 -> 62999 | F42: =F38+F39+F40+F41 -> 71049.126 | G42: =G38+G39+G40+G41 -> 83799.868 | H42: =H38+H39+H40+H41 -> 101836.26 | I42: =I38+I39+I40+I41 -> 125090.74 | J42: =J38+J39+J40+J41 -> 152237.36
A43: TOTAL LIABILITIES + EQUITY | C43: =C35+C42 -> 67885 | D43: =D35+D42 -> 69226 | E43: =E35+E42 -> 76926 | F43: =F35+F42 -> 87594.901 | G43: =G35+G42 -> 105013.67 | H43: =H35+H42 -> 127571.19 | I43: =I35+I42 -> 155029.47 | J43: =J35+J42 -> 185781.36
...

Sheet Scenarios
A1: AMD - Scenarios (Bull / Base / Bear)
A2: USD millions. Blue = input. Change cell C4 to switch the scenario that flows through all three statements.
A4: ACTIVE SCENARIO (1 = Bull, 2 = Base, 3 = Bear) | C4: 2 | D4: =CHOOSE($C$4,"Bull","Base","Bear") -> Base
A6: Scenario drivers | C6: FY2023A | D6: FY2024A | E6: FY2025A | F6: FY2026E | G6: FY2027E | H6: FY2028E | I6: FY2029E | J6: FY2030E | K6: Notes / sources
A7: Data Center AI (Instinct/Helios) revenue growth
A8: Bull | F8: 2 | G8: 1.1 | H8: 0.6 | I8: 0.4 | J8: 0.25
A9: Base | F9: 1.7 | G9: 0.9 | H9: 0.45 | I9: 0.3 | J9: 0.2 | K9: Bull: OpenAI 6 GW + Anthropic 2 GW ramp on schedule, MI500 share gains. Base: 1 GW OpenAI + Anthropic/Meta/Oracle Helios in H2 2026, slower ramp than mgmt >80% CAGR target. Bear: Helios delays/customer pauses.
A10: Bear | F10: 1.5 | G10: 0.45 | H10: 0.2 | I10: 0.12 | J10: 0.08
A11: Active (feeds model) | F11: =CHOOSE($C$4,F8,F9,F10) -> 1.7 | G11: =CHOOSE($C$4,G8,G9,G10) -> 0.9 | H11: =CHOOSE($C$4,H8,H9,H10) -> 0.45 | I11: =CHOOSE($C$4,I8,I9,I10) -> 0.3 | J11: =CHOOSE($C$4,J8,J9,J10) -> 0.2
A12: Server CPU & other Data Center revenue growth
A13: Bull | F13: 0.25 | G13: 0.22 | H13: 0.18 | I13: 0.15 | J13: 0.12
A14: Base | F14: 0.22 | G14: 0.18 | H14: 0.14 | I14: 0.12 | J14: 0.1 | K14: EPYC Venice share gains toward >50% (mgmt target) + agentic-AI CPU demand; bear = Arm/Intel pressure.
A15: Bear | F15: 0.18 | G15: 0.1 | H15: 0.06 | I15: 0.05 | J15: 0.04
A16: Active (feeds model) | F16: =CHOOSE($C$4,F13,F14,F15) -> 0.22 | G16: =CHOOSE($C$4,G13,G14,G15) -> 0.18 | H16: =CHOOSE($C$4,H13,H14,H15) -> 0.14 | I16: =CHOOSE($C$4,I13,I14,I15) -> 0.12 | J16: =CHOOSE($C$4,J13,J14,J15) -> 0.1
A17: Client revenue growth
A18: Bull | F18: 0.18 | G18: 0.1 | H18: 0.08 | I18: 0.07 | J18: 0.06
A19: Base | F19: 0.15 | G19: 0.06 | H19: 0.05 | I19: 0.05 | J19: 0.04 | K19: FY2026 anchored on H1 2026 Client 5,952 (Q1 est. 2,890 + Q2 3,062).
A20: Bear | F20: 0.12 | G20: -0.02 | H20: 0 | I20: 0.02 | J20: 0.02
A21: Active (feeds model) | F21: =CHOOSE($C$4,F18,F19,F20) -> 0.15 | G21: =CHOOSE($C$4,G18,G19,G20) -> 0.06 | H21: =CHOOSE($C$4,H18,H19,H20) -> 0.05 | I21: =CHOOSE($C$4,I18,I19,I20) -> 0.05 | J21: =CHOOSE($C$4,J18,J19,J20) -> 0.04
A22: Gaming revenue growth
A23: Bull | F23: -0.18 | G23: 0.1 | H23: 0.3 | I23: 0.08 | J23: -0.05
A24: Base | F24: -0.2 | G24: 0.05 | H24: 0.25 | I24: 0.05 | J24: -0.1 | K24: Late console cycle in 2026; next-gen Sony/Microsoft console ramp assumed FY2028.
A25: Bear | F25: -0.24 | G25: -0.05 | H25: 0.15 | I25: 0 | J25: -0.15
A26: Active (feeds model) | F26: =CHOOSE($C$4,F23,F24,F25) -> -0.2 | G26: =CHOOSE($C$4,G23,G24,G25) -> 0.05 | H26: =CHOOSE($C$4,H23,H24,H25) -> 0.25 | I26: =CHOOSE($C$4,I23,I24,I25) -> 0.05 | J26: =CHOOSE($C$4,J23,J24,J25) -> -0.1
A27: Embedded revenue growth
A28: Bull | F28: 0.15 | G28: 0.13 | H28: 0.11 | I28: 0.09 | J28: 0.08
A29: Base | F29: 0.13 | G29: 0.1 | H29: 0.08 | I29: 0.07 | J29: 0.06 | K29: Cyclical recovery after FY2024-25 inventory correction; Q2 FY2026 +19% YoY.
A30: Bear | F30: 0.1 | G30: 0.05 | H30: 0.04 | I30: 0.03 | J30: 0.03
A31: Active (feeds model) | F31: =CHOOSE($C$4,F28,F29,F30) -> 0.13 | G31: =CHOOSE($C$4,G28,G29,G30) -> 0.1 | H31: =CHOOSE($C$4,H28,H29,H30) -> 0.08 | I31: =CHOOSE($C$4,I28,I29,I30) -> 0.07 | J31: =CHOOSE($C$4,J28,J29,J30) -> 0.06
A32: Cost of sales ex-amortization, % of revenue
A33: Bull | F33: 0.45 | G33: 0.44 | H33: 0.43 | I33: 0.425 | J33: 0.42
A34: Base | F34: 0.455 | G34: 0.45 | H34: 0.445 | I34: 0.44 | J34: 0.44 | K34: FY2025A 47.5%; Q2 FY2026A 44.0%. Rack-scale pass-through content (bear) dilutes margin.
A35: Bear | F35: 0.465 | G35: 0.47 | H35: 0.47 | I35: 0.47 | J35: 0.47
A36: Active (feeds model) | F36: =CHOOSE($C$4,F33,F34,F35) -> 0.455 | G36: =CHOOSE($C$4,G33,G34,G35) -> 0.45 | H36: =CHOOSE($C$4,H33,H34,H35) -> 0.445 | I36: =CHOOSE($C$4,I33,I34,I35) -> 0.44 | J36: =CHOOSE($C$4,J33,J34,J35) -> 0.44
A37: R&D, % of revenue
A38: Bull | F38: 0.205 | G38: 0.18 | H38: 0.16 | I38: 0.15 | J38: 0.145
A39: Base | F39: 0.21 | G39: 0.195 | H39: 0.18 | I39: 0.17 | J39: 0.165 | K39: FY2025A 23.4%; H1 FY2026A 22.6%.
A40: Bear | F40: 0.215 | G40: 0.215 | H40: 0.21 | I40: 0.205 | J40: 0.2
A41: Active (feeds model) | F41: =CHOOSE($C$4,F38,F39,F40) -> 0.21 | G41: =CHOOSE($C$4,G38,G39,G40) -> 0.195 | H41: =CHOOSE($C$4,H38,H39,H40) -> 0.18 | I41: =CHOOSE($C$4,I38,I39,I40) -> 0.17 | J41: =CHOOSE($C$4,J38,J39,J40) -> 0.165
A42: MG&A, % of revenue
...

Sheet DCF Inputs
A1: AMD - DCF Inputs (prepared for Task 3)
A2: USD millions. Unlevered free cash flow from the active scenario. SBC treated as a cash expense (not added back).
A4: USD millions | C4: FY2023A | D4: FY2024A | E4: FY2025A | F4: FY2026E | G4: FY2027E | H4: FY2028E | I4: FY2029E | J4: FY2030E | K4: Notes / sources
A5: UNLEVERED FREE CASH FLOW
A6: Revenue | C6: ='Income Statement'!C9 -> 22680 | D6: ='Income Statement'!D9 -> 25785 | E6: ='Income Statement'!E9 -> 34639 | F6: ='Income Statement'!F9 -> 49181.72 | G6: ='Income Statement'!G9 -> 68483.228 | H6: ='Income Statement'!H9 -> 87344.2 | I6: ='Income Statement'!I9 -> 105056.02 | J6: ='Income Statement'!J9 -> 119928.57
A7: EBITDA | C7: ='Income Statement'!C39 -> 3854 | D7: ='Income Statement'!D39 -> 4965 | E7: ='Income Statement'!E39 -> 6698 | F7: ='Income Statement'!F39 -> 11675.418 | G7: ='Income Statement'!G39 -> 18569.596 | H7: ='Income Statement'!H39 -> 26509.359 | I7: ='Income Statement'!I39 -> 34102.879 | J7: ='Income Statement'!J39 -> 40167.557
A8: EBIT (GAAP operating income) | C8: ='Income Statement'!C31 -> 401 | D8: ='Income Statement'!D31 -> 1900 | E8: ='Income Statement'!E31 -> 3694 | F8: ='Income Statement'!F31 -> 8639.9784 | G8: ='Income Statement'!G31 -> 15270.807 | H8: ='Income Statement'!H31 -> 22906.376 | I8: ='Income Statement'!I31 -> 30316.805 | J8: ='Income Statement'!J31 -> 36177.856
A9: Tax rate % | F9: ='Income Statement'!F52 -> 0.13 | G9: ='Income Statement'!G52 -> 0.15 | H9: ='Income Statement'!H52 -> 0.15 | I9: ='Income Statement'!I52 -> 0.15 | J9: ='Income Statement'!J52 -> 0.15
A10: Less: taxes on EBIT | F10: =-F8*F9 -> -1123.1972 | G10: =-G8*G9 -> -2290.6211 | H10: =-H8*H9 -> -3435.9564 | I10: =-I8*I9 -> -4547.5208 | J10: =-J8*J9 -> -5426.6784
A11: NOPAT | F11: =F8+F10 -> 7516.7812 | G11: =G8+G10 -> 12980.186 | H11: =H8+H10 -> 19470.42 | I11: =I8+I10 -> 25769.285 | J11: =J8+J10 -> 30751.177
A12: Add: D&A (PP&E) | F12: ='Cash Flow Statement'!F8 -> 855.44 | G12: ='Cash Flow Statement'!G8 -> 1448.789 | H12: ='Cash Flow Statement'!H8 -> 2052.9828 | I12: ='Cash Flow Statement'!I8 -> 2586.0733 | J12: ='Cash Flow Statement'!J8 -> 2989.7016
A13: Add: amortization of acquisition-related intangibles | F13: ='Cash Flow Statement'!F10 -> 2180 | G13: ='Cash Flow Statement'!G10 -> 1850 | H13: ='Cash Flow Statement'!H10 -> 1550 | I13: ='Cash Flow Statement'!I10 -> 1200 | J13: ='Cash Flow Statement'!J10 -> 1000
A14: Less: capex | F14: ='Cash Flow Statement'!F27 -> -2459.086 | G14: ='Cash Flow Statement'!G27 -> -3081.7453 | H14: ='Cash Flow Statement'!H27 -> -3493.768 | I14: ='Cash Flow Statement'!I27 -> -3676.9606 | J14: ='Cash Flow Statement'!J27 -> -4197.4998
A15: Less: increase in operating net working capital | F15: =-('Balance Sheet'!F56-'Balance Sheet'!E56) -> -1630.9114 | G15: =-('Balance Sheet'!G56-'Balance Sheet'!F56) -> -2782.6282 | H15: =-('Balance Sheet'!H56-'Balance Sheet'!G56) -> -2212.9693 | I15: =-('Balance Sheet'!I56-'Balance Sheet'!H56) -> -2201.5156 | J15: =-('Balance Sheet'!J56-'Balance Sheet'!I56) -> -1633.1176
A16: UNLEVERED FREE CASH FLOW | F16: =F11+F12+F13+F14+F15 -> 6462.2238 | G16: =G11+G12+G13+G14+G15 -> 10414.601 | H16: =H11+H12+H13+H14+H15 -> 17366.665 | I16: =I11+I12+I13+I14+I15 -> 23676.882 | J16: =J11+J12+J13+J14+J15 -> 28910.262
A17: UFCF margin % | F17: =F16/F6 -> 0.13139483 | G17: =G16/G6 -> 0.15207521 | H17: =H16/H6 -> 0.1988302 | I17: =I16/I6 -> 0.22537387 | J17: =J16/J6 -> 0.24106235
A18: Memo: SBC (not added back) | F18: ='Cash Flow Statement'!F11 -> 2213.1774 | G18: ='Cash Flow Statement'!G11 -> 2739.3291 | H18: ='Cash Flow Statement'!H11 -> 3231.7354 | I18: ='Cash Flow Statement'!I11 -> 3676.9606 | J18: ='Cash Flow Statement'!J11 -> 3957.6427
A20: TERMINAL YEAR (FY2030E) METRICS
A21: FY2030E revenue | C21: =J6 -> 119928.57
A22: FY2030E EBITDA | C22: =J7 -> 40167.557
A23: FY2030E EBIT | C23: =J8 -> 36177.856
A24: FY2030E unlevered FCF | C24: =J16 -> 28910.262
A25: FY2030E net income | C25: ='Income Statement'!J56 -> 32588.981
A26: FY2030E diluted EPS (USD) | C26: ='Income Statement'!J66 -> 19.883033
A28: CAPITAL STRUCTURE & MARKET DATA (for equity bridge)
A29: Share price (USD), 2026-10-13 close | C29: 605.53 | K29: Source: stockevents.app/en/stock/AMD (accessed 2026-10-14).
A30: Diluted shares (m), Q2 FY2026 weighted average | C30: 1659 | K30: Source: 10-Q Q2 FY2026 (filed 2026-08-05).
A31: Market capitalisation (USD m) | C31: =C29*C30 -> 1004574.3 | K31: Price x diluted shares.
A32: Total debt, 2026-06-27 | C32: 3226 | K32: Source: 10-Q Q2 FY2026 (875 current + 2,351 long-term).
A33: Cash + short-term investments, 2026-06-27 | C33: 13111 | K33: Source: 10-Q Q2 FY2026.
A34: Enterprise value (USD m) | C34: =C31+C32-C33 -> 994689.27 | K34: Market cap + debt - cash & STI.
A35: EV / FY2026E revenue (x) | C35: =C34/F6 -> 20.224776
A36: EV / FY2026E EBITDA (x) | C36: =C34/F7 -> 85.195171
A37: P/E FY2026E diluted (x) | C37: =C29/'Income Statement'!F66 -> 129.57756
A38: OpenAI warrant - potential shares (m), not in share count | C38: 160 | K38: Source: AMD/OpenAI press release 2025-10-06; vests on deployment + share-price milestones.

Sheet DCF
A1: AMD - Discounted Cash Flow (two-stage, mid-year convention)
A2: USD millions except per-share. Valuation date 2026-10-13. Stage 1 = FY2026E-FY2030E from model (active scenario); Stage 2 = FY2031E-FY2035E fade; Gordon-growth terminal value.
A4: WACC
A5: Risk-free rate (US 10-year Treasury, 2026-10-13) | C5: 0.0521 | N5: Source: US Treasury Daily Par Yield Curve, 10 Yr = 5.21% on 2026-10-13 (home.treasury.gov).
A6: AMD raw beta (5Y monthly vs. S&P 500) | C6: 2.45 | N6: Source: stockanalysis.com AMD statistics (accessed 2026-10-14).
A7: Blume-adjusted beta (0.67 x raw + 0.33) | C7: =0.67*C6+0.33 -> 1.9715 | N7: Adjusts raw beta toward 1.0.
A8: Peer median raw beta (NVDA, AVGO, INTC, QCOM) | C8: =Comps!I12 -> 1.935 | N8: From Comps tab.
A9: Selected beta (average of Blume-adjusted and peer median) | C9: =AVERAGE(C7,C8) -> 1.95325
A10: Equity risk premium | C10: 0.05 | N10: Assumption: 5.0% (mid of the 4.5-5.5% range commonly used).
A11: Cost of equity (CAPM) | C11: =C5+C9*C10 -> 0.1497625
A12: Credit spread over Treasury (A-rated) | C12: 0.01 | N12: Assumption.
A13: Pre-tax cost of debt | C13: =C5+C12 -> 0.0621
A14: Tax rate | C14: ='Income Statement'!G52 -> 0.15 | N14: Model long-run ETR.
A15: After-tax cost of debt | C15: =C13*(1-C14) -> 0.052785
A16: Market value of equity (USD m) | C16: ='DCF Inputs'!$C$31 -> 1004574.3 | N16: Price 605.53 x 1,659m diluted shares.
A17: Debt (USD m, book) | C17: ='DCF Inputs'!$C$32 -> 3226 | N17: Total debt 2026-06-27.
A18: Weight of equity | C18: =C16/(C16+C17) -> 0.99679897
A19: Weight of debt | C19: =C17/(C16+C17) -> 0.0032010311
A20: WACC | C20: =C18*C11+C19*C15 -> 0.14945207
A21: Terminal growth rate | C21: 0.03 | N21: Assumption: 3.0% nominal (below long-run nominal GDP + secular compute demand).
A22: Fraction of FY2026E remaining after valuation date | C22: 0.2 | N22: 2026-10-13 to FY-end 2026-12-26 = ~74 days / 365.
A23: Terminal (FY2035E) unlevered FCF margin | C23: 0.3 | N23: Assumption: stage-2 margin glides linearly from FY2030E level to 30%.
A25: UNLEVERED FREE CASH FLOW
A26: USD millions | C26: FY2026E | D26: FY2027E | E26: FY2028E | F26: FY2029E | G26: FY2030E | H26: FY2031E | I26: FY2032E | J26: FY2033E | K26: FY2034E | L26: FY2035E | N26: Notes
A27: Stage | C27: 1 | D27: 1 | E27: 1 | F27: 1 | G27: 1 | H27: 2 | I27: 2 | J27: 2 | K27: 2 | L27: 2
A28: Revenue | C28: ='DCF Inputs'!F6 -> 49181.72 | D28: ='DCF Inputs'!G6 -> 68483.228 | E28: ='DCF Inputs'!H6 -> 87344.2 | F28: ='DCF Inputs'!I6 -> 105056.02 | G28: ='DCF Inputs'!J6 -> 119928.57 | H28: =G28*(1+H29) -> 134319.99 | I28: =H28*(1+I29) -> 147751.99 | J28: =I28*(1+J29) -> 159572.15 | K28: =J28*(1+K29) -> 169146.48 | L28: =K28*(1+L29) -> 176758.07
A29: Revenue growth % | C29: ='Income Statement'!F10 -> 0.4198366 | D29: ='Income Statement'!G10 -> 0.39245289 | E29: ='Income Statement'!H10 -> 0.27541009 | F29: ='Income Statement'!I10 -> 0.20278184 | G29: ='Income Statement'!J10 -> 0.14156779 | H29: 0.12 | I29: 0.1 | J29: 0.08 | K29: 0.06 | L29: 0.045 | N29: Stage 2 growth fade (inputs): 12% / 10% / 8% / 6% / 4.5%.
A30: Unlevered FCF margin % | C30: =C31/C28 -> 0.13139483 | D30: =D31/D28 -> 0.15207521 | E30: =E31/E28 -> 0.1988302 | F30: =F31/F28 -> 0.22537387 | G30: =G31/G28 -> 0.24106235 | H30: =$G30+($C$23-$G30)*H37/5 -> 0.25284988 | I30: =$G30+($C$23-$G30)*I37/5 -> 0.26463741 | J30: =$G30+($C$23-$G30)*J37/5 -> 0.27642494 | K30: =$G30+($C$23-$G30)*K37/5 -> 0.28821247 | L30: =$G30+($C$23-$G30)*L37/5 -> 0.3
A31: Unlevered free cash flow | C31: ='DCF Inputs'!F16 -> 6462.2238 | D31: ='DCF Inputs'!G16 -> 10414.601 | E31: ='DCF Inputs'!H16 -> 17366.665 | F31: ='DCF Inputs'!I16 -> 23676.882 | G31: ='DCF Inputs'!J16 -> 28910.262 | H31: =H28*H30 -> 33962.794 | I31: =I28*I30 -> 39100.705 | J31: =J28*J30 -> 44109.723 | K31: =K28*K30 -> 48750.126 | L31: =L28*L30 -> 53027.422 | N31: Stage 1 from 'DCF Inputs' (NOPAT + D&A + amortization - capex - change in NWC; SBC treated as a cash cost).
A32: Fraction of year valued | C32: =$C$22 -> 0.2 | D32: 1 | E32: 1 | F32: 1 | G32: 1 | H32: 1 | I32: 1 | J32: 1 | K32: 1 | L32: 1
A33: UFCF valued | C33: =C31*C32 -> 1292.4448 | D33: =D31*D32 -> 10414.601 | E33: =E31*E32 -> 17366.665 | F33: =F31*F32 -> 23676.882 | G33: =G31*G32 -> 28910.262 | H33: =H31*H32 -> 33962.794 | I33: =I31*I32 -> 39100.705 | J33: =J31*J32 -> 44109.723 | ... L33: =L31*L32 -> 53027.422
A34: Discount period (years, mid-year) | C34: =$C$22/2 -> 0.1 | D34: =$C$22+0+0.5 -> 0.7 | E34: =$C$22+1+0.5 -> 1.7 | F34: =$C$22+2+0.5 -> 2.7 | G34: =$C$22+3+0.5 -> 3.7 | H34: =$C$22+4+0.5 -> 4.7 | I34: =$C$22+5+0.5 -> 5.7 | J34: =$C$22+6+0.5 -> 6.7 | K34: =$C$22+7+0.5 -> 7.7 | L34: =$C$22+8+0.5 -> 8.7 | N34: Mid-year convention; FY2026E stub discounted at half the stub.
A35: Discount factor | C35: =1/(1+$C$20)^C34 -> 0.98616802 | D35: =1/(1+$C$20)^D34 -> 0.90710256 | E35: =1/(1+$C$20)^E34 -> 0.78916084 | F35: =1/(1+$C$20)^F34 -> 0.68655393 | G35: =1/(1+$C$20)^G34 -> 0.597288 | H35: =1/(1+$C$20)^H34 -> 0.51962845 | I35: =1/(1+$C$20)^I34 -> 0.45206622 | J35: =1/(1+$C$20)^J34 -> 0.39328845 | ... L35: =1/(1+$C$20)^L34 -> 0.29766615
A36: PV of UFCF | C36: =C33*C35 -> 1274.5677 | D36: =D33*D35 -> 9447.1117 | E36: =E33*E35 -> 13705.092 | F36: =F33*F35 -> 16255.456 | G36: =G33*G35 -> 17267.752 | H36: =H33*H35 -> 17648.034 | I36: =I33*I35 -> 17676.108 | J36: =J33*J35 -> 17347.844 | ... L36: =L33*L35 -> 15784.469
A37: Stage-2 step (k) | C37: 0 | D37: 0 | E37: 0 | F37: 0 | G37: 0 | H37: 1 | I37: 2 | J37: 3 | K37: 4 | L37: 5
A39: ENTERPRISE VALUE TO EQUITY VALUE
A40: Sum of PV of UFCF (FY2026E stub - FY2035E) | C40: =SUM(C36:L36) -> 143086.44
A41: Terminal value at end-FY2035E (Gordon growth) | C41: =L31*(1+C21)/(C20-C21) -> 457239.83
A42: Discount period for terminal value (years) | C42: =C22+9 -> 9.2
A43: PV of terminal value | C43: =C41/(1+C20)^C42 -> 126948.65
...

Sheet Sensitivity
A1: AMD - DCF Sensitivity Analysis
A2: DCF value per share (USD). Every cell recomputes the full two-stage DCF from the DCF tab. Base case outlined in the centre.
A4: TABLE 1: WACC (rows) vs. TERMINAL GROWTH (columns) - value per share (USD)
B5: WACC \ g | C5: =DCF!$C$21+(-0.01) -> 0.02 | D5: =DCF!$C$21+(-0.005) -> 0.025 | E5: =DCF!$C$21+(0) -> 0.03 | F5: =DCF!$C$21+(0.005) -> 0.035 | G5: =DCF!$C$21+(0.01) -> 0.04
B6: =DCF!$C$20+(-0.04) -> 0.10945207 | C6: =(SUMPRODUCT(DCF!$C$33:$L$33/(1+$B6)^DCF!$C$34:$L$34)+DCF!$L$31*(1+C$5)/($B6-C$5)/(1+$B6)^DCF!$C$42+('DCF Inputs'!$C$33-'DCF Inputs'!$C$32))/'DCF Inputs'!$C$30 -> 249.17667 | D6: =(SUMPRODUCT(DCF!$C$33:$L$33/(1+$B6)^DCF!$C$34:$L$34)+DCF!$L$31*(1+D$5)/($B6-D$5)/(1+$B6)^DCF!$C$42+('DCF Inputs'!$C$33-'DCF Inputs'!$C$32))/'DCF Inputs'!$C$30 -> 258.20346 | E6: =(SUMPRODUCT(DCF!$C$33:$L$33/(1+$B6)^DCF!$C$34:$L$34)+DCF!$L$31*(1+E$5)/($B6-E$5)/(1+$B6)^DCF!$C$42+('DCF Inputs'!$C$33-'DCF Inputs'!$C$32))/'DCF Inputs'!$C$30 -> 268.36638 | F6: =(SUMPRODUCT(DCF!$C$33:$L$33/(1+$B6)^DCF!$C$34:$L$34)+DCF!$L$31*(1+F$5)/($B6-F$5)/(1+$B6)^DCF!$C$42+('DCF Inputs'!$C$33-'DCF Inputs'!$C$32))/'DCF Inputs'!$C$30 -> 279.89433 | G6: =(SUMPRODUCT(DCF!$C$33:$L$33/(1+$B6)^DCF!$C$34:$L$34)+DCF!$L$31*(1+G$5)/($B6-G$5)/(1+$B6)^DCF!$C$42+('DCF Inputs'!$C$33-'DCF Inputs'!$C$32))/'DCF Inputs'!$C$30 -> 293.08212
B7: =DCF!$C$20+(-0.03) -> 0.11945207 | C7: =(SUMPRODUCT(DCF!$C$33:$L$33/(1+$B7)^DCF!$C$34:$L$34)+DCF!$L$31*(1+C$5)/($B7-C$5)/(1+$B7)^DCF!$C$42+('DCF Inputs'!$C$33-'DCF Inputs'!$C$32))/'DCF Inputs'!$C$30 -> 220.47986 | D7: =(SUMPRODUCT(DCF!$C$33:$L$33/(1+$B7)^DCF!$C$34:$L$34)+DCF!$L$31*(1+D$5)/($B7-D$5)/(1+$B7)^DCF!$C$42+('DCF Inputs'!$C$33-'DCF Inputs'!$C$32))/'DCF Inputs'!$C$30 -> 227.22442 | E7: =(SUMPRODUCT(DCF!$C$33:$L$33/(1+$B7)^DCF!$C$34:$L$34)+DCF!$L$31*(1+E$5)/($B7-E$5)/(1+$B7)^DCF!$C$42+('DCF Inputs'!$C$33-'DCF Inputs'!$C$32))/'DCF Inputs'!$C$30 -> 234.72297 | F7: =(SUMPRODUCT(DCF!$C$33:$L$33/(1+$B7)^DCF!$C$34:$L$34)+DCF!$L$31*(1+F$5)/($B7-F$5)/(1+$B7)^DCF!$C$42+('DCF Inputs'!$C$33-'DCF Inputs'!$C$32))/'DCF Inputs'!$C$30 -> 243.10942 | G7: =(SUMPRODUCT(DCF!$C$33:$L$33/(1+$B7)^DCF!$C$34:$L$34)+DCF!$L$31*(1+G$5)/($B7-G$5)/(1+$B7)^DCF!$C$42+('DCF Inputs'!$C$33-'DCF Inputs'!$C$32))/'DCF Inputs'!$C$30 -> 252.55141
B8: =DCF!$C$20+(-0.02) -> 0.12945207 | C8: =(SUMPRODUCT(DCF!$C$33:$L$33/(1+$B8)^DCF!$C$34:$L$34)+DCF!$L$31*(1+C$5)/($B8-C$5)/(1+$B8)^DCF!$C$42+('DCF Inputs'!$C$33-'DCF Inputs'!$C$32))/'DCF Inputs'!$C$30 -> 197.26423 | D8: =(SUMPRODUCT(DCF!$C$33:$L$33/(1+$B8)^DCF!$C$34:$L$34)+DCF!$L$31*(1+D$5)/($B8-D$5)/(1+$B8)^DCF!$C$42+('DCF Inputs'!$C$33-'DCF Inputs'!$C$32))/'DCF Inputs'!$C$30 -> 202.41613 | E8: =(SUMPRODUCT(DCF!$C$33:$L$33/(1+$B8)^DCF!$C$34:$L$34)+DCF!$L$31*(1+E$5)/($B8-E$5)/(1+$B8)^DCF!$C$42+('DCF Inputs'!$C$33-'DCF Inputs'!$C$32))/'DCF Inputs'!$C$30 -> 208.08605 | F8: =(SUMPRODUCT(DCF!$C$33:$L$33/(1+$B8)^DCF!$C$34:$L$34)+DCF!$L$31*(1+F$5)/($B8-F$5)/(1+$B8)^DCF!$C$42+('DCF Inputs'!$C$33-'DCF Inputs'!$C$32))/'DCF Inputs'!$C$30 -> 214.35627 | G8: =(SUMPRODUCT(DCF!$C$33:$L$33/(1+$B8)^DCF!$C$34:$L$34)+DCF!$L$31*(1+G$5)/($B8-G$5)/(1+$B8)^DCF!$C$42+('DCF Inputs'!$C$33-'DCF Inputs'!$C$32))/'DCF Inputs'!$C$30 -> 221.32745
B9: =DCF!$C$20+(-0.01) -> 0.13945207 | C9: =(SUMPRODUCT(DCF!$C$33:$L$33/(1+$B9)^DCF!$C$34:$L$34)+DCF!$L$31*(1+C$5)/($B9-C$5)/(1+$B9)^DCF!$C$42+('DCF Inputs'!$C$33-'DCF Inputs'!$C$32))/'DCF Inputs'!$C$30 -> 178.13541 | D9: =(SUMPRODUCT(DCF!$C$33:$L$33/(1+$B9)^DCF!$C$34:$L$34)+DCF!$L$31*(1+D$5)/($B9-D$5)/(1+$B9)^DCF!$C$42+('DCF Inputs'!$C$33-'DCF Inputs'!$C$32))/'DCF Inputs'!$C$30 -> 182.14315 | E9: =(SUMPRODUCT(DCF!$C$33:$L$33/(1+$B9)^DCF!$C$34:$L$34)+DCF!$L$31*(1+E$5)/($B9-E$5)/(1+$B9)^DCF!$C$42+('DCF Inputs'!$C$33-'DCF Inputs'!$C$32))/'DCF Inputs'!$C$30 -> 186.51705 | F9: =(SUMPRODUCT(DCF!$C$33:$L$33/(1+$B9)^DCF!$C$34:$L$34)+DCF!$L$31*(1+F$5)/($B9-F$5)/(1+$B9)^DCF!$C$42+('DCF Inputs'!$C$33-'DCF Inputs'!$C$32))/'DCF Inputs'!$C$30 -> 191.30969 | G9: =(SUMPRODUCT(DCF!$C$33:$L$33/(1+$B9)^DCF!$C$34:$L$34)+DCF!$L$31*(1+G$5)/($B9-G$5)/(1+$B9)^DCF!$C$42+('DCF Inputs'!$C$33-'DCF Inputs'!$C$32))/'DCF Inputs'!$C$30 -> 196.58425
B10: =DCF!$C$20+(0) -> 0.14945207 | C10: =(SUMPRODUCT(DCF!$C$33:$L$33/(1+$B10)^DCF!$C$34:$L$34)+DCF!$L$31*(1+C$5)/($B10-C$5)/(1+$B10)^DCF!$C$42+('DCF Inputs'!$C$33-'DCF Inputs'!$C$32))/'DCF Inputs'!$C$30 -> 162.1315 | D10: =(SUMPRODUCT(DCF!$C$33:$L$33/(1+$B10)^DCF!$C$34:$L$34)+DCF!$L$31*(1+D$5)/($B10-D$5)/(1+$B10)^DCF!$C$42+('DCF Inputs'!$C$33-'DCF Inputs'!$C$32))/'DCF Inputs'!$C$30 -> 165.29734 | E10: =(SUMPRODUCT(DCF!$C$33:$L$33/(1+$B10)^DCF!$C$34:$L$34)+DCF!$L$31*(1+E$5)/($B10-E$5)/(1+$B10)^DCF!$C$42+('DCF Inputs'!$C$33-'DCF Inputs'!$C$32))/'DCF Inputs'!$C$30 -> 168.7282 | F10: =(SUMPRODUCT(DCF!$C$33:$L$33/(1+$B10)^DCF!$C$34:$L$34)+DCF!$L$31*(1+F$5)/($B10-F$5)/(1+$B10)^DCF!$C$42+('DCF Inputs'!$C$33-'DCF Inputs'!$C$32))/'DCF Inputs'!$C$30 -> 172.45882 | G10: =(SUMPRODUCT(DCF!$C$33:$L$33/(1+$B10)^DCF!$C$34:$L$34)+DCF!$L$31*(1+G$5)/($B10-G$5)/(1+$B10)^DCF!$C$42+('DCF Inputs'!$C$33-'DCF Inputs'!$C$32))/'DCF Inputs'!$C$30 -> 176.5303
B11: =DCF!$C$20+(0.01) -> 0.15945207 | C11: =(SUMPRODUCT(DCF!$C$33:$L$33/(1+$B11)^DCF!$C$34:$L$34)+DCF!$L$31*(1+C$5)/($B11-C$5)/(1+$B11)^DCF!$C$42+('DCF Inputs'!$C$33-'DCF Inputs'!$C$32))/'DCF Inputs'!$C$30 -> 148.56786 | D11: =(SUMPRODUCT(DCF!$C$33:$L$33/(1+$B11)^DCF!$C$34:$L$34)+DCF!$L$31*(1+D$5)/($B11-D$5)/(1+$B11)^DCF!$C$42+('DCF Inputs'!$C$33-'DCF Inputs'!$C$32))/'DCF Inputs'!$C$30 -> 151.10158 | E11: =(SUMPRODUCT(DCF!$C$33:$L$33/(1+$B11)^DCF!$C$34:$L$34)+DCF!$L$31*(1+E$5)/($B11-E$5)/(1+$B11)^DCF!$C$42+('DCF Inputs'!$C$33-'DCF Inputs'!$C$32))/'DCF Inputs'!$C$30 -> 153.83103 | F11: =(SUMPRODUCT(DCF!$C$33:$L$33/(1+$B11)^DCF!$C$34:$L$34)+DCF!$L$31*(1+F$5)/($B11-F$5)/(1+$B11)^DCF!$C$42+('DCF Inputs'!$C$33-'DCF Inputs'!$C$32))/'DCF Inputs'!$C$30 -> 156.77979 | G11: =(SUMPRODUCT(DCF!$C$33:$L$33/(1+$B11)^DCF!$C$34:$L$34)+DCF!$L$31*(1+G$5)/($B11-G$5)/(1+$B11)^DCF!$C$42+('DCF Inputs'!$C$33-'DCF Inputs'!$C$32))/'DCF Inputs'!$C$30 -> 159.97541
B12: =DCF!$C$20+(0.02) -> 0.16945207 | C12: =(SUMPRODUCT(DCF!$C$33:$L$33/(1+$B12)^DCF!$C$34:$L$34)+DCF!$L$31*(1+C$5)/($B12-C$5)/(1+$B12)^DCF!$C$42+('DCF Inputs'!$C$33-'DCF Inputs'!$C$32))/'DCF Inputs'!$C$30 -> 136.94418 | D12: =(SUMPRODUCT(DCF!$C$33:$L$33/(1+$B12)^DCF!$C$34:$L$34)+DCF!$L$31*(1+D$5)/($B12-D$5)/(1+$B12)^DCF!$C$42+('DCF Inputs'!$C$33-'DCF Inputs'!$C$32))/'DCF Inputs'!$C$30 -> 138.99507 | E12: =(SUMPRODUCT(DCF!$C$33:$L$33/(1+$B12)^DCF!$C$34:$L$34)+DCF!$L$31*(1+E$5)/($B12-E$5)/(1+$B12)^DCF!$C$42+('DCF Inputs'!$C$33-'DCF Inputs'!$C$32))/'DCF Inputs'!$C$30 -> 141.19303 | F12: =(SUMPRODUCT(DCF!$C$33:$L$33/(1+$B12)^DCF!$C$34:$L$34)+DCF!$L$31*(1+F$5)/($B12-F$5)/(1+$B12)^DCF!$C$42+('DCF Inputs'!$C$33-'DCF Inputs'!$C$32))/'DCF Inputs'!$C$30 -> 143.55446 | G12: =(SUMPRODUCT(DCF!$C$33:$L$33/(1+$B12)^DCF!$C$34:$L$34)+DCF!$L$31*(1+G$5)/($B12-G$5)/(1+$B12)^DCF!$C$42+('DCF Inputs'!$C$33-'DCF Inputs'!$C$32))/'DCF Inputs'!$C$30 -> 146.09831
A15: TABLE 2: WACC (rows) vs. TERMINAL FY2035E UFCF MARGIN (columns) - value per share (USD)
B16: WACC \ margin | C16: 0.24 | D16: 0.27 | E16: 0.3 | F16: 0.33 | G16: 0.36
