Workbook

Sheet DCF
A1: Microsoft Corporation (MSFT) - DCF Model
A2: Ticker: MSFT | Valuation date: 2026-10-14 | Fiscal year end: June 30 | USD millions except per-share
A4: Case selector (1=Bear, 2=Base, 3=Bull) | B4: 2 | C4: =CHOOSE(B4,"Bear case","Base case","Bull case") -> Base case
A6: MARKET DATA & KEY INPUTS
A7: Current share price ($) | B7: 533.69
A8: Diluted shares (M) | B8: 7453
A9: Market capitalisation ($M) | B9: =B7*B8 -> 3977591.6
A10: Cash + short-term investments ($M) | B10: 76843
A11: Total debt ($M) | B11: 40294
A12: Net debt / (net cash) ($M) | B12: =B11-B10 -> -36549
A13: Tax rate (cash/operating) | B13: 0.19
A14: Change in NWC (% of change in revenue) | B14: 0.05
A15: Base WACC (from WACC sheet) | B15: =WACC!B29 -> 0.10658549
A16: Peer median EV/LTM EBITDA (from Comps sheet) | B16: =Comps!J34 -> 17.074188
A17: FY2026A diluted EPS ($) | B17: 17.95
A19: SCENARIO ASSUMPTIONS
A20: BEAR CASE ASSUMPTIONS
A21: Assumption | E21: FY2027E | F21: FY2028E | G21: FY2029E | H21: FY2030E | I21: FY2031E | J21: FY2032E | K21: FY2033E | L21: FY2034E | M21: FY2035E | N21: FY2036E
A22: Revenue growth (%) | E22: 0.12 | F22: 0.1 | G22: 0.09 | H22: 0.08 | I22: 0.07 | J22: 0.06 | K22: 0.05 | L22: 0.045 | M22: 0.04 | N22: 0.035
A23: EBIT margin (%) | E23: 0.44 | F23: 0.435 | G23: 0.43 | H23: 0.425 | I23: 0.42 | J23: 0.415 | K23: 0.41 | L23: 0.41 | M23: 0.41 | N23: 0.41
A24: D&A (% of revenue) | E24: 0.14 | F24: 0.15 | G24: 0.155 | H24: 0.16 | I24: 0.16 | J24: 0.16 | K24: 0.155 | L24: 0.15 | M24: 0.145 | N24: 0.14
A25: CapEx (% of revenue) | E25: 0.38 | F25: 0.34 | G25: 0.29 | H25: 0.26 | I25: 0.23 | J25: 0.21 | K25: 0.195 | L25: 0.18 | M25: 0.17 | N25: 0.165
A26: WACC adjustment vs. base (pp) | E26: 0.005
A27: Terminal growth rate (%) | E27: 0.025
A29: BASE CASE ASSUMPTIONS
A30: Assumption | E30: FY2027E | F30: FY2028E | G30: FY2029E | H30: FY2030E | I30: FY2031E | J30: FY2032E | K30: FY2033E | L30: FY2034E | M30: FY2035E | N30: FY2036E
A31: Revenue growth (%) | E31: 0.16 | F31: 0.15 | G31: 0.13 | H31: 0.12 | I31: 0.11 | J31: 0.1 | K31: 0.08 | L31: 0.07 | M31: 0.06 | N31: 0.05
A32: EBIT margin (%) | E32: 0.46 | F32: 0.465 | G32: 0.47 | H32: 0.47 | I32: 0.47 | J32: 0.47 | K32: 0.465 | L32: 0.46 | M32: 0.46 | N32: 0.46
A33: D&A (% of revenue) | E33: 0.14 | F33: 0.15 | G33: 0.155 | H33: 0.16 | I33: 0.16 | J33: 0.16 | K33: 0.155 | L33: 0.15 | M33: 0.145 | N33: 0.14
A34: CapEx (% of revenue) | E34: 0.36 | F34: 0.32 | G34: 0.27 | H34: 0.24 | I34: 0.22 | J34: 0.2 | K34: 0.185 | L34: 0.17 | M34: 0.16 | N34: 0.155
A35: WACC adjustment vs. base (pp) | E35: 0
A36: Terminal growth rate (%) | E36: 0.03
A38: BULL CASE ASSUMPTIONS
A39: Assumption | E39: FY2027E | F39: FY2028E | G39: FY2029E | H39: FY2030E | I39: FY2031E | J39: FY2032E | K39: FY2033E | L39: FY2034E | M39: FY2035E | N39: FY2036E
A40: Revenue growth (%) | E40: 0.19 | F40: 0.18 | G40: 0.16 | H40: 0.15 | I40: 0.13 | J40: 0.12 | K40: 0.1 | L40: 0.09 | M40: 0.07 | N40: 0.06
A41: EBIT margin (%) | E41: 0.47 | F41: 0.475 | G41: 0.48 | H41: 0.485 | I41: 0.49 | J41: 0.49 | K41: 0.49 | L41: 0.49 | M41: 0.49 | N41: 0.49
A42: D&A (% of revenue) | E42: 0.14 | F42: 0.15 | G42: 0.155 | H42: 0.16 | I42: 0.16 | J42: 0.16 | K42: 0.155 | L42: 0.15 | M42: 0.145 | N42: 0.14
A43: CapEx (% of revenue) | E43: 0.34 | F43: 0.29 | G43: 0.24 | H43: 0.21 | I43: 0.19 | J43: 0.175 | K43: 0.16 | L43: 0.15 | M43: 0.145 | N43: 0.14
A44: WACC adjustment vs. base (pp) | E44: -0.005
A45: Terminal growth rate (%) | E45: 0.035
...

Sheet WACC
A1: MSFT - Weighted Average Cost of Capital
A3: COST OF EQUITY (CAPM)
A4: Risk-free rate (10Y UST, 2026-10-13) | B4: 0.0521
A5: Beta (5Y monthly vs S&P 500, raw) | B5: =Beta!H4 -> 1.1017697
A6: Equity risk premium | B6: 0.05
A7: Cost of equity | B7: =B4+B5*B6 -> 0.10718849
A9: COST OF DEBT
A10: Credit rating | B10: AAA
A11: Spread over 10Y UST | B11: 0.006
A12: Pre-tax cost of debt | B12: =B4+B11 -> 0.0581
A13: Tax rate | B13: =DCF!B13 -> 0.19
A14: After-tax cost of debt | B14: =B12*(1-B13) -> 0.047061
A15: Memo: FY2026 interest expense / avg. debt | B15: =C15/AVERAGE(43151,DCF!B11) -> 0.073126011 | C15: 3051
A17: CAPITAL STRUCTURE (market values)
A18: Share price ($) | B18: =DCF!B7 -> 533.69
A19: Diluted shares (M) | B19: =DCF!B8 -> 7453
A20: Market capitalisation ($M) | B20: =B18*B19 -> 3977591.6
A21: Total debt ($M) | B21: =DCF!B11 -> 40294
A22: Cash + ST investments ($M) | B22: =DCF!B10 -> 76843
A23: Net debt / (net cash) ($M) | B23: =B21-B22 -> -36549
A24: Total capital (E + D) ($M) | B24: =B20+B21 -> 4017885.6
A26: WACC | B26: Weight | C26: Cost | D26: Contribution
A27: Equity | B27: =B20/B24 -> 0.98997134 | C27: =B7 -> 0.10718849 | D27: =B27*C27 -> 0.10611353
A28: Debt (gross) | B28: =B21/B24 -> 0.010028658 | C28: =B14 -> 0.047061 | D28: =B28*C28 -> 0.00047195867
A29: WEIGHTED AVERAGE COST OF CAPITAL | B29: =D27+D28 -> 0.10658549
A31: Gross debt weights used (MSFT is net cash); lease liabilities excluded from debt and from the equity bridge for consistency.

Sheet Beta
A1: MSFT 5-year beta vs. S&P 500 - monthly total-return (MSFT adj. close) vs. index price returns
A3: Month-end | B3: MSFT adj. close | C3: S&P 500 close | D3: MSFT return | E3: S&P 500 return
A4: 2021-09 | B4: 270.57 | C4: 4307.54 | G4: Beta (SLOPE, raw) | H4: =SLOPE(D5:D64,E5:E64) -> 1.1017697
A5: 2021-10 | B5: 318.26 | C5: 4605.38 | D5: =B5/B4-1 -> 0.17625753 | E5: =C5/C4-1 -> 0.069143873 | G5: Observations (monthly returns) | H5: =COUNT(D5:D64) -> 60
A6: 2021-11 | B6: 317.86 | C6: 4567 | D6: =B6/B5-1 -> -0.001256834 | E6: =C6/C5-1 -> -0.0083337314 | G6: R-squared | H6: =RSQ(D5:D64,E5:E64) -> 0.39755815
A7: 2021-12 | B7: 323.37 | C7: 4766.18 | D7: =B7/B6-1 -> 0.017334676 | E7: =C7/C6-1 -> 0.043612875 | G7: Blume-adjusted beta (memo) | H7: =0.67*H4+0.33 -> 1.0681857
A8: 2022-01 | B8: 299 | C8: 4515.55 | D8: =B8/B7-1 -> -0.075362588 | E8: =C8/C7-1 -> -0.052585089 | G8: Window: 2021-09 to 2026-09 month-end closes (60 complete months; partial Oct-2026 excluded)
A9: 2022-02 | B9: 287.88 | C9: 4373.94 | D9: =B9/B8-1 -> -0.037190635 | E9: =C9/C8-1 -> -0.031360521
A10: 2022-03 | B10: 297.05 | C10: 4530.41 | D10: =B10/B9-1 -> 0.03185355 | E10: =C10/C9-1 -> 0.035773239
A11: 2022-04 | B11: 267.38 | C11: 4131.93 | D11: =B11/B10-1 -> -0.099882175 | E11: =C11/C10-1 -> -0.087956719
A12: 2022-05 | B12: 262.55 | C12: 4132.15 | D12: =B12/B11-1 -> -0.018064178 | E12: =C12/C11-1 -> 5.3243884e-05
A13: 2022-06 | B13: 248.02 | C13: 3785.38 | D13: =B13/B12-1 -> -0.05534184 | E13: =C13/C12-1 -> -0.083919993
A14: 2022-07 | B14: 271.11 | C14: 4130.29 | D14: =B14/B13-1 -> 0.093097331 | E14: =C14/C13-1 -> 0.091116348
A15: 2022-08 | B15: 253.04 | C15: 3955 | D15: =B15/B14-1 -> -0.066651913 | E15: =C15/C14-1 -> -0.042440119
A16: 2022-09 | B16: 225.39 | C16: 3585.62 | D16: =B16/B15-1 -> -0.10927126 | E16: =C16/C15-1 -> -0.093395702
A17: 2022-10 | B17: 224.65 | C17: 3871.98 | D17: =B17/B16-1 -> -0.003283198 | E17: =C17/C16-1 -> 0.079863455
A18: 2022-11 | B18: 247.61 | C18: 4080.11 | D18: =B18/B17-1 -> 0.10220343 | E18: =C18/C17-1 -> 0.05375286
A19: 2022-12 | B19: 232.74 | C19: 3839.5 | D19: =B19/B18-1 -> -0.060054117 | E19: =C19/C18-1 -> -0.058971449
A20: 2023-01 | B20: 240.5 | C20: 4076.6 | D20: =B20/B19-1 -> 0.033341927 | E20: =C20/C19-1 -> 0.061752832
... A64: 2026-09 | B64: 512.9 | C64: 7651.54 | D64: =B64/B63-1 -> 0.011058763 | E64: =C64/C63-1 -> -0.0045016094

Sheet Comps
A1: TECHNOLOGY MEGA-CAP - COMPARABLE COMPANY ANALYSIS
A2: Microsoft (MSFT) vs. Alphabet (GOOGL) • Amazon (AMZN) • Meta (META) • Apple (AAPL) • Oracle (ORCL)
A3: As of 2026-10-14 (prices) | LTM to latest reported quarter | USD millions except per-share and ratios
A5: OPERATING METRICS (LTM)
A6: Company | B6: Ticker | C6: LTM end | D6: Revenue | E6: Revenue prior LTM | F6: Rev growth | G6: Gross profit | H6: Gross margin | I6: EBIT | J6: EBIT margin | K6: D&A | L6: EBITDA | M6: EBITDA margin | N6: Net income
A7: Microsoft (target) | B7: MSFT | C7: 2026-06-30 | D7: 331839 | E7: 281724 | F7: =D7/E7-1 -> 0.17788687 | G7: 225465 | H7: =IF(ISNUMBER(G7),G7/D7,"n/a") -> 0.67944093 | I7: 155237 | J7: =I7/D7 -> 0.46780818 | K7: 39000 | L7: =I7+K7 -> 194237 | M7: =L7/D7 -> 0.58533506 | N7: 133749
A9: Alphabet | B9: GOOGL | C9: 2026-06-30 | D9: 445867 | E9: 371399 | F9: =D9/E9-1 -> 0.20050673 | G9: 271517 | H9: =IF(ISNUMBER(G9),G9/D9,"n/a") -> 0.60896411 | I9: 147628 | J9: =I9/D9 -> 0.33110322 | K9: 25086 | L9: =I9+K9 -> 172714 | M9: =L9/D9 -> 0.38736664 | N9: 244205
A10: Amazon | B10: AMZN | C10: 2026-06-30 | D10: 775680 | E10: 670038 | F10: =D10/E10-1 -> 0.15766568 | G10: 393810 | H10: =IF(ISNUMBER(G10),G10/D10,"n/a") -> 0.50769647 | I10: 93712 | J10: =I10/D10 -> 0.12081271 | K10: 75200 | L10: =I10+K10 -> 168912 | M10: =L10/D10 -> 0.2177599 | N10: 135281
A11: Meta Platforms | B11: META | C11: 2026-06-30 | D11: 228247 | E11: 178804 | F11: =D11/E11-1 -> 0.27652066 | G11: 186587 | H11: =IF(ISNUMBER(G11),G11/D11,"n/a") -> 0.81747843 | I11: 86927 | J11: =I11/D11 -> 0.38084619 | K11: 22729 | L11: =I11+K11 -> 109656 | M11: =L11/D11 -> 0.48042691 | N11: 68098
A12: Apple | B12: AAPL | C12: 2026-06-27 | D12: 466823 | E12: 408625 | F12: =D12/E12-1 -> 0.14242398 | G12: 227123 | H12: =IF(ISNUMBER(G12),G12/D12,"n/a") -> 0.48652916 | I12: 154859 | J12: =I12/D12 -> 0.33172958 | K12: 13100 | L12: =I12+K12 -> 167959 | M12: =L12/D12 -> 0.35979161 | N12: 128930
A13: Oracle | B13: ORCL | C13: 2026-08-31 | D13: 71777 | E13: 59018 | F13: =D13/E13-1 -> 0.21618828 | G13: n/a | H13: =IF(ISNUMBER(G13),G13/D13,"n/a") -> n/a | I13: 23056 | J13: =I13/D13 -> 0.3212171 | K13: 10881 | L13: =I13+K13 -> 33937 | M13: =L13/D13 -> 0.47281162 | N13: 18920
A15: Peer Maximum | F15: =MAX(F9:F13) -> 0.27652066 | H15: =MAX(H9:H13) -> 0.81747843 | J15: =MAX(J9:J13) -> 0.38084619 | M15: =MAX(M9:M13) -> 0.48042691
A16: Peer 75th Percentile | F16: =QUARTILE(F9:F13,3) -> 0.21618828 | H16: =QUARTILE(H9:H13,3) -> 0.66109269 | J16: =QUARTILE(J9:J13,3) -> 0.33172958 | M16: =QUARTILE(M9:M13,3) -> 0.47281162
A17: Peer Median | F17: =MEDIAN(F9:F13) -> 0.20050673 | H17: =MEDIAN(H9:H13) -> 0.55833029 | J17: =MEDIAN(J9:J13) -> 0.33110322 | M17: =MEDIAN(M9:M13) -> 0.38736664
A18: Peer 25th Percentile | F18: =QUARTILE(F9:F13,1) -> 0.15766568 | H18: =QUARTILE(H9:H13,1) -> 0.50240464 | J18: =QUARTILE(J9:J13,1) -> 0.3212171 | M18: =QUARTILE(M9:M13,1) -> 0.35979161
A19: Peer Minimum | F19: =MIN(F9:F13) -> 0.14242398 | H19: =MIN(H9:H13) -> 0.48652916 | J19: =MIN(J9:J13) -> 0.12081271 | M19: =MIN(M9:M13) -> 0.2177599
A22: VALUATION MULTIPLES
A23: Company | B23: Ticker | C23: Share price | D23: Diluted shares (M) | E23: Market cap | F23: Cash + ST inv. | G23: Total debt | H23: Enterprise value | I23: EV / Revenue | J23: EV / EBITDA | K23: EV / EBIT | L23: P / E | M23: FCF note
A24: =A7 -> Microsoft (target) | B24: =B7 -> MSFT | C24: 533.69 | D24: 7425.5 | E24: =C24*D24 -> 3962915.1 | F24: 76843 | G24: 40294 | H24: =E24-F24+G24 -> 3926366.1 | I24: =H24/D7 -> 11.832142 | J24: =H24/L7 -> 20.214306 | K24: =H24/I7 -> 25.292721 | L24: =E24/N7 -> 29.629493
A26: =A9 -> Alphabet | B26: =B9 -> GOOGL | C26: 347.64 | D26: 12229.9 | E26: =C26*D26 -> 4251602.4 | F26: 242474 | G26: 100164 | H26: =E26-F26+G26 -> 4109292.4 | I26: =H26/D9 -> 9.2164086 | J26: =H26/L9 -> 23.792469 | K26: =H26/I9 -> 27.835454 | L26: =E26/N9 -> 17.409973 | M26: P/E distorted by investment gains
A27: =A10 -> Amazon | B27: =B10 -> AMZN | C27: 254.08 | D27: 10786.3 | E27: =C27*D27 -> 2740583.1 | F27: 122988 | G27: 132224 | H27: =E27-F27+G27 -> 2749819.1 | I27: =H27/D10 -> 3.5450432 | J27: =H27/L10 -> 16.279596 | K27: =H27/I10 -> 29.343298 | L27: =E27/N10 -> 20.258448 | M27: P/E depressed by equity-investment gains
A28: =A11 -> Meta Platforms | B28: =B11 -> META | C28: 737.54 | D28: 2547.5 | E28: =C28*D28 -> 1878883.1 | F28: 90260 | G28: 83664 | H28: =E28-F28+G28 -> 1872287.1 | I28: =H28/D11 -> 8.2028993 | J28: =H28/L11 -> 17.074188 | K28: =H28/I11 -> 21.538615 | L28: =E28/N11 -> 27.590871 | M28: Q3-25 one-off tax charge
A29: =A12 -> Apple | B29: =B12 -> AAPL | C29: 342.96 | D29: 14594.2 | E29: =C29*D29 -> 5005226.8 | F29: 62399 | G29: 82347 | H29: =E29-F29+G29 -> 5025174.8 | I29: =H29/D12 -> 10.764626 | J29: =H29/L12 -> 29.919057 | K29: =H29/I12 -> 32.450002 | L29: =E29/N12 -> 38.821274
A30: =A13 -> Oracle | B30: =B13 -> ORCL | C30: 130.55 | D30: 3031.5 | E30: =C30*D30 -> 395762.33 | F30: 37077 | G30: 125337 | H30: =E30-F30+G30 -> 484022.33 | I30: =H30/D13 -> 6.7434182 | J30: =H30/L13 -> 14.262378 | K30: =H30/I13 -> 20.993335 | L30: =E30/N13 -> 20.91767
A32: Peer Maximum | I32: =MAX(I26:I30) -> 10.764626 | J32: =MAX(J26:J30) -> 29.919057 | K32: =MAX(K26:K30) -> 32.450002 | L32: =MAX(L26:L30) -> 38.821274
A33: Peer 75th Percentile | I33: =QUARTILE(I26:I30,3) -> 9.2164086 | J33: =QUARTILE(J26:J30,3) -> 23.792469 | K33: =QUARTILE(K26:K30,3) -> 29.343298 | L33: =QUARTILE(L26:L30,3) -> 27.590871
A34: Peer Median | I34: =MEDIAN(I26:I30) -> 8.2028993 | J34: =MEDIAN(J26:J30) -> 17.074188 | K34: =MEDIAN(K26:K30) -> 27.835454 | L34: =MEDIAN(L26:L30) -> 20.91767
A35: Peer 25th Percentile | I35: =QUARTILE(I26:I30,1) -> 6.7434182 | J35: =QUARTILE(J26:J30,1) -> 16.279596 | K35: =QUARTILE(K26:K30,1) -> 21.538615 | L35: =QUARTILE(L26:L30,1) -> 20.258448
A36: Peer Minimum | I36: =MIN(I26:I30) -> 3.5450432 | J36: =MIN(J26:J30) -> 14.262378 | K36: =MIN(K26:K30) -> 20.993335 | L36: =MIN(L26:L30) -> 17.409973
A38: MSFT EV/EBITDA premium/(discount) to peer median | J38: =J24/J34-1 -> 0.18391023
A39: MSFT P/E premium/(discount) to peer median | L39: =L24/L34-1 -> 0.4164815
A40: Peer median LTM revenue growth | F40: =F17 -> 0.20050673
A41: Peer median EBITDA margin | M41: =M17 -> 0.38736664
A44: NOTES & METHODOLOGY
A45: Data: SEC XBRL standardized financials via stock-data MCP (get_financials); prices/market caps via stock-data get_quote (Yahoo, close 2026-10-14).
A46: LTM = sum of last four reported quarters; prior LTM = the four quarters before. Fiscal year ends differ (AAPL Sep, ORCL May, MSFT Jun, others Dec).
A47: EBITDA = Operating income (EBIT) + D&A from the cash flow statement. GOOGL LTM D&A is an estimate (see cell comment).
A48: EV = market cap - cash & current marketable securities + total debt (operating and finance lease liabilities excluded for all companies).
A49: P/E for GOOGL, AMZN is depressed by large unrealized equity-investment gains in 2026; META LTM includes a one-off tax charge. Use EV/EBITDA and EV/EBIT as the primary multiples.
A50: Statistics are calculated over the five peers only (MSFT excluded).
