Workbook

Sheet DCF
A1: MICROSOFT CORPORATION (MSFT) - DCF MODEL
A2: Ticker: MSFT | Valuation date: 2026-10-14 | Fiscal year end: June 30 | USD millions except per share
A4: Case selector (1=Bear, 2=Base, 3=Bull) | B4: 2
A5: Active case | B5: =CHOOSE(B4,"Bear","Base","Bull") -> Base
A7: MARKET DATA & CAPITAL STRUCTURE
A8: Current share price ($) | B8: 533.69
A9: Diluted shares (M) | B9: 7453
A10: Market cap | B10: =B8*B9 -> 3977591.6
A11: Cash + short-term investments | B11: =WACC!B25 -> 76843
A12: Total debt incl. leases | B12: =WACC!B22 -> 128810
A13: Net debt / (net cash) | B13: =B12-B11 -> 51967
A14: WACC (active case) | B14: =WACC!D33+B59 -> 0.10505278
A15: Terminal growth (active case) | B15: =B60 -> 0.03
A18: BEAR CASE ASSUMPTIONS
A19: Assumption | F19: FY2027E | G19: FY2028E | H19: FY2029E | I19: FY2030E | J19: FY2031E | K19: FY2032E | L19: FY2033E | M19: FY2034E | N19: FY2035E | O19: FY2036E
A20: Revenue growth | F20: 0.12 | G20: 0.1 | H20: 0.09 | I20: 0.08 | J20: 0.07 | K20: 0.06 | L20: 0.05 | M20: 0.045 | N20: 0.04 | O20: 0.035
A21: EBIT margin | F21: 0.45 | G21: 0.445 | H21: 0.44 | I21: 0.44 | J21: 0.44 | K21: 0.435 | L21: 0.435 | M21: 0.43 | N21: 0.43 | O21: 0.43
A22: D&A % of revenue | F22: 0.125 | G22: 0.135 | H22: 0.14 | I22: 0.145 | J22: 0.145 | K22: 0.14 | L22: 0.135 | M22: 0.13 | N22: 0.13 | O22: 0.13
A23: CapEx % of revenue | F23: 0.35 | G23: 0.33 | H23: 0.29 | I23: 0.25 | J23: 0.22 | K23: 0.19 | L23: 0.17 | M23: 0.16 | N23: 0.15 | O23: 0.145
A24: Change in NWC % of change in revenue | F24: 0.08 | G24: 0.08 | H24: 0.08 | I24: 0.08 | J24: 0.08 | K24: 0.08 | L24: 0.08 | M24: 0.08 | N24: 0.08 | O24: 0.08
A25: Tax rate | F25: 0.19 | G25: 0.19 | H25: 0.19 | I25: 0.19 | J25: 0.19 | K25: 0.19 | L25: 0.19 | M25: 0.19 | N25: 0.19 | O25: 0.19
A26: WACC adjustment vs. CAPM WACC | B26: 0.005
A27: Terminal growth rate | B27: 0.025
A29: BASE CASE ASSUMPTIONS
A30: Assumption | F30: FY2027E | G30: FY2028E | H30: FY2029E | I30: FY2030E | J30: FY2031E | K30: FY2032E | L30: FY2033E | M30: FY2034E | N30: FY2035E | O30: FY2036E
A31: Revenue growth | F31: 0.16 | G31: 0.15 | H31: 0.14 | I31: 0.13 | J31: 0.12 | K31: 0.11 | L31: 0.1 | M31: 0.08 | N31: 0.06 | O31: 0.045
A32: EBIT margin | F32: 0.465 | G32: 0.465 | H32: 0.47 | I32: 0.475 | J32: 0.48 | K32: 0.48 | L32: 0.48 | M32: 0.48 | N32: 0.48 | O32: 0.48
A33: D&A % of revenue | F33: 0.125 | G33: 0.135 | H33: 0.14 | I33: 0.14 | J33: 0.14 | K33: 0.135 | L33: 0.13 | M33: 0.125 | N33: 0.12 | O33: 0.12
A34: CapEx % of revenue | F34: 0.33 | G34: 0.3 | H34: 0.26 | I34: 0.22 | J34: 0.19 | K34: 0.17 | L34: 0.155 | M34: 0.145 | N34: 0.135 | O34: 0.13
A35: Change in NWC % of change in revenue | F35: 0.08 | G35: 0.08 | H35: 0.08 | I35: 0.08 | J35: 0.08 | K35: 0.08 | L35: 0.08 | M35: 0.08 | N35: 0.08 | O35: 0.08
A36: Tax rate | F36: 0.19 | G36: 0.19 | H36: 0.19 | I36: 0.19 | J36: 0.19 | K36: 0.19 | L36: 0.19 | M36: 0.19 | N36: 0.19 | O36: 0.19
A37: WACC adjustment vs. CAPM WACC | B37: 0
A38: Terminal growth rate | B38: 0.03
A40: BULL CASE ASSUMPTIONS
A41: Assumption | F41: FY2027E | G41: FY2028E | H41: FY2029E | I41: FY2030E | J41: FY2031E | K41: FY2032E | L41: FY2033E | M41: FY2034E | N41: FY2035E | O41: FY2036E
A42: Revenue growth | F42: 0.19 | G42: 0.18 | H42: 0.17 | I42: 0.16 | J42: 0.15 | K42: 0.13 | L42: 0.12 | M42: 0.1 | N42: 0.08 | O42: 0.06
A43: EBIT margin | F43: 0.475 | G43: 0.48 | H43: 0.485 | I43: 0.49 | J43: 0.495 | K43: 0.5 | L43: 0.5 | M43: 0.5 | N43: 0.5 | O43: 0.5
A44: D&A % of revenue | F44: 0.125 | G44: 0.13 | H44: 0.135 | I44: 0.135 | J44: 0.135 | K44: 0.13 | L44: 0.125 | M44: 0.12 | N44: 0.115 | O44: 0.115
A45: CapEx % of revenue | F45: 0.31 | G45: 0.27 | H45: 0.23 | I45: 0.19 | J45: 0.16 | K45: 0.145 | L45: 0.135 | M45: 0.125 | N45: 0.12 | O45: 0.115
A46: Change in NWC % of change in revenue | F46: 0.08 | G46: 0.08 | H46: 0.08 | I46: 0.08 | J46: 0.08 | K46: 0.08 | L46: 0.08 | M46: 0.08 | N46: 0.08 | O46: 0.08
...

Sheet WACC
A1: MICROSOFT - WEIGHTED AVERAGE COST OF CAPITAL
A2: As of 2026-10-14 | USD millions
A3: COST OF EQUITY (CAPM)
A4: Risk-free rate (10Y UST par yield) | B4: 0.0519
A5: Risk-free rate date | B5: 2026-10-14
A6: Beta (5Y monthly vs S&P 500) | B6: =Beta!H5 -> 1.1017697
A7: Beta observations (months) | B7: =Beta!H6 -> 60
A8: Equity risk premium | B8: 0.05
A9: Cost of equity | B9: =B4+B6*B8 -> 0.10698849
A11: COST OF DEBT
A12: Credit rating (S&P / Moody's) | B12: AAA / Aaa
A13: Spread over 10Y UST | B13: 0.004
A14: Pre-tax cost of debt | B14: =B4+B13 -> 0.0559
A15: Tax rate | B15: 0.19
A16: After-tax cost of debt | B16: =B14*(1-B15) -> 0.045279
A18: CAPITAL STRUCTURE (market values)
A19: Share price ($) | B19: =DCF!B8 -> 533.69
A20: Diluted shares (M) | B20: =DCF!B9 -> 7453
A21: Market capitalisation | B21: =B19*B20 -> 3977591.6
A22: Total debt incl. lease liabilities | B22: 128810
A23: memo: financial debt (bonds) | B23: 40294
A24: memo: lease liabilities (derived) | B24: =B22-B23 -> 88516
A25: Cash + short-term investments | B25: 76843
A26: Net debt / (net cash) | B26: =B22-B25 -> 51967
A27: Enterprise value (market) | B27: =B21+B26 -> 4029558.6
A29: WACC CALCULATION
A30: Component | B30: Weight | C30: Cost | D30: Contribution
A31: Equity | B31: =B21/(B21+B22) -> 0.9686319 | C31: =B9 -> 0.10698849 | D31: =B31*C31 -> 0.10363246
A32: Debt (gross) | B32: =B22/(B21+B22) -> 0.031368096 | C32: =B16 -> 0.045279 | D32: =B32*C32 -> 0.001420316
A33: WACC | D33: =D31+D32 -> 0.10505278
A35: Note: weights use gross debt (incl. leases) and market equity. Scenario WACC adjustments (Bear +0.5pp / Bull -0.5pp) are applied on the DCF sheet.

Sheet Beta
A1: MSFT 5-YEAR MONTHLY BETA vs S&P 500
A2: Month-end adjusted closes Sep-2021 to Sep-2026 (61 prices -> 60 monthly returns). Oct-2026 partial month excluded.
A4: Month | B4: MSFT Adj Close | C4: S&P 500 Close | D4: MSFT Return | E4: S&P 500 Return | G4: Regression output
A5: 2021-09-01 | B5: 270.57 | C5: 4307.54 | G5: Beta (SLOPE) | H5: =SLOPE(D6:D65,E6:E65) -> 1.1017697
A6: 2021-10-01 | B6: 318.26 | C6: 4605.38 | D6: =B6/B5-1 -> 0.17625753 | E6: =C6/C5-1 -> 0.069143873 | G6: Observations | H6: =COUNT(D6:D65) -> 60
A7: 2021-11-01 | B7: 317.86 | C7: 4567 | D7: =B7/B6-1 -> -0.001256834 | E7: =C7/C6-1 -> -0.0083337314 | G7: Correlation | H7: =CORREL(D6:D65,E6:E65) -> 0.63052212
A8: 2021-12-01 | B8: 323.37 | C8: 4766.18 | D8: =B8/B7-1 -> 0.017334676 | E8: =C8/C7-1 -> 0.043612875 | G8: R-squared | H8: =H7^2 -> 0.39755815
A9: 2022-01-01 | B9: 299 | C9: 4515.55 | D9: =B9/B8-1 -> -0.075362588 | E9: =C9/C8-1 -> -0.052585089 | G9: Blume-adjusted beta (memo) | H9: =0.67*H5+0.33 -> 1.0681857
A10: 2022-02-01 | B10: 287.88 | C10: 4373.94 | D10: =B10/B9-1 -> -0.037190635 | E10: =C10/C9-1 -> -0.031360521
A11: 2022-03-01 | B11: 297.05 | C11: 4530.41 | D11: =B11/B10-1 -> 0.03185355 | E11: =C11/C10-1 -> 0.035773239
A12: 2022-04-01 | B12: 267.38 | C12: 4131.93 | D12: =B12/B11-1 -> -0.099882175 | E12: =C12/C11-1 -> -0.087956719
A13: 2022-05-01 | B13: 262.55 | C13: 4132.15 | D13: =B13/B12-1 -> -0.018064178 | E13: =C13/C12-1 -> 5.3243884e-05
A14: 2022-06-01 | B14: 248.02 | C14: 3785.38 | D14: =B14/B13-1 -> -0.05534184 | E14: =C14/C13-1 -> -0.083919993
A15: 2022-07-01 | B15: 271.11 | C15: 4130.29 | D15: =B15/B14-1 -> 0.093097331 | E15: =C15/C14-1 -> 0.091116348
A16: 2022-08-01 | B16: 253.04 | C16: 3955 | D16: =B16/B15-1 -> -0.066651913 | E16: =C16/C15-1 -> -0.042440119
A17: 2022-09-01 | B17: 225.39 | C17: 3585.62 | D17: =B17/B16-1 -> -0.10927126 | E17: =C17/C16-1 -> -0.093395702
A18: 2022-10-01 | B18: 224.65 | C18: 3871.98 | D18: =B18/B17-1 -> -0.003283198 | E18: =C18/C17-1 -> 0.079863455
A19: 2022-11-01 | B19: 247.61 | C19: 4080.11 | D19: =B19/B18-1 -> 0.10220343 | E19: =C19/C18-1 -> 0.05375286
A20: 2022-12-01 | B20: 232.74 | C20: 3839.5 | D20: =B20/B19-1 -> -0.060054117 | E20: =C20/C19-1 -> -0.058971449
A21: 2023-01-01 | B21: 240.5 | C21: 4076.6 | D21: =B21/B20-1 -> 0.033341927 | E21: =C21/C20-1 -> 0.061752832
... A65: 2026-09-01 | B65: 512.9 | C65: 7651.54 | D65: =B65/B64-1 -> 0.011058763 | E65: =C65/C64-1 -> -0.0045016094

Sheet Scenarios
A1: SCENARIO ENGINE - full DCF recomputed for each case (reads DCF scenario blocks)
A3: Case | C3: Bear | D3: Base | E3: Bull
A24: WACC | C24: =WACC!D33+DCF!B26 -> 0.11005278 | D24: =WACC!D33+DCF!B37 -> 0.10505278 | E24: =WACC!D33+DCF!B48 -> 0.10005278
A25: Terminal growth | C25: =DCF!B27 -> 0.025 | D25: =DCF!B38 -> 0.03 | E25: =DCF!B49 -> 0.035
A26: Sum PV FCF | C26: =SUM(D42:M42) -> 772276.61 | D26: =SUM(D52:M52) -> 1195350.6 | E26: =SUM(D62:M62) -> 1562119.1
A27: PV terminal value | C27: =M40*(1+C25)/(C24-C25)*M41 -> 952629.62 | D27: =M50*(1+D25)/(D24-D25)*M51 -> 1860459.2 | E27: =M60*(1+E25)/(E24-E25)*M61 -> 2984934
A28: Enterprise value | C28: =C26+C27 -> 1724906.2 | D28: =D26+D27 -> 3055809.8 | E28: =E26+E27 -> 4547053.2
A29: Equity value | C29: =C28-DCF!B12+DCF!B11 -> 1672939.2 | D29: =D28-DCF!B12+DCF!B11 -> 3003842.8 | E29: =E28-DCF!B12+DCF!B11 -> 4495086.2
A30: Value per share ($) | C30: =C29/DCF!B9 -> 224.46521 | D30: =D29/DCF!B9 -> 403.03808 | E30: =E29/DCF!B9 -> 603.1244
A31: TV % of EV | C31: =C27/C28 -> 0.55227908 | D31: =D27/D28 -> 0.60882689 | E31: =E27/E28 -> 0.65645461
A35: BEAR CASE CASH FLOWS
A36: Item | C36: FY2026A | D36: FY2027E | E36: FY2028E | F36: FY2029E | G36: FY2030E | H36: FY2031E | I36: FY2032E | J36: FY2033E | K36: FY2034E | L36: FY2035E | M36: FY2036E
A37: Revenue | C37: =DCF!E64 -> 331839 | D37: =C37*(1+DCF!F20) -> 371659.68 | E37: =D37*(1+DCF!G20) -> 408825.65 | F37: =E37*(1+DCF!H20) -> 445619.96 | G37: =F37*(1+DCF!I20) -> 481269.55 | H37: =G37*(1+DCF!J20) -> 514958.42 | I37: =H37*(1+DCF!K20) -> 545855.93 | J37: =I37*(1+DCF!L20) -> 573148.72 | K37: =J37*(1+DCF!M20) -> 598940.42 | ... M37: =L37*(1+DCF!O20) -> 644699.46
A38: EBIT | D38: =D37*DCF!F21 -> 167246.86 | E38: =E37*DCF!G21 -> 181927.41 | F38: =F37*DCF!H21 -> 196072.78 | G38: =G37*DCF!I21 -> 211758.6 | H38: =H37*DCF!J21 -> 226581.71 | I38: =I37*DCF!K21 -> 237447.33 | J38: =J37*DCF!L21 -> 249319.69 | K38: =K37*DCF!M21 -> 257544.38 | ... M38: =M37*DCF!O21 -> 277220.77
A39: NOPAT | D39: =D38*(1-DCF!F25) -> 135469.95 | E39: =E38*(1-DCF!G25) -> 147361.2 | F39: =F38*(1-DCF!H25) -> 158818.95 | G39: =G38*(1-DCF!I25) -> 171524.47 | H39: =H38*(1-DCF!J25) -> 183531.18 | I39: =I38*(1-DCF!K25) -> 192332.34 | J39: =J38*(1-DCF!L25) -> 201948.95 | K39: =K38*(1-DCF!M25) -> 208610.95 | ... M39: =M38*(1-DCF!O25) -> 224548.82
A40: UFCF | D40: =D39+D37*DCF!F22-D37*DCF!F23-(D37-C37)*DCF!F24 -> 48660.871 | E40: =E39+E37*DCF!G22-E37*DCF!G23-(E37-D37)*DCF!G24 -> 64666.926 | F40: =F39+F37*DCF!H22-F37*DCF!H23-(F37-E37)*DCF!H24 -> 89032.414 | G40: =G39+G37*DCF!I22-G37*DCF!I23-(G37-F37)*DCF!I24 -> 118139.2 | H40: =H39+H37*DCF!J22-H37*DCF!J23-(H37-G37)*DCF!J24 -> 142214.19 | I40: =I39+I37*DCF!K22-I37*DCF!K23-(I37-H37)*DCF!K24 -> 162567.74 | J40: =J39+J37*DCF!L22-J37*DCF!L23-(J37-I37)*DCF!L24 -> 179705.32 | K40: =K39+K37*DCF!M22-K37*DCF!M23-(K37-J37)*DCF!M24 -> 188579.4 | ... M40: =M39+M37*DCF!O22-M37*DCF!O23-(M37-L37)*DCF!O24 -> 213134.22
A41: Discount factor | D41: =1/(1+C$24)^D43 -> 0.94913543 | E41: =1/(1+C$24)^E43 -> 0.85503631 | F41: =1/(1+C$24)^F43 -> 0.77026636 | G41: =1/(1+C$24)^G43 -> 0.69390066 | H41: =1/(1+C$24)^H43 -> 0.62510601 | I41: =1/(1+C$24)^I43 -> 0.56313179 | J41: =1/(1+C$24)^J43 -> 0.50730182 | K41: =1/(1+C$24)^K43 -> 0.45700694 | L41: =1/(1+C$24)^L43 -> 0.41169839 | M41: =1/(1+C$24)^M43 -> 0.37088181
A42: PV UFCF | D42: =D40*D41 -> 46185.757 | E42: =E40*E41 -> 55292.57 | F42: =F40*F41 -> 68578.674 | G42: =G40*G41 -> 81976.868 | H42: =H40*H41 -> 88898.945 | I42: =I40*I41 -> 91547.062 | J42: =J40*J41 -> 91164.838 | K42: =K40*K41 -> 86182.093 | ... M42: =M40*M41 -> 79047.605
A43: Period | D43: =DCF!F82 -> 0.5 | E43: =DCF!G82 -> 1.5 | F43: =DCF!H82 -> 2.5 | G43: =DCF!I82 -> 3.5 | H43: =DCF!J82 -> 4.5 | I43: =DCF!K82 -> 5.5 | J43: =DCF!L82 -> 6.5 | K43: =DCF!M82 -> 7.5 | ... M43: =DCF!O82 -> 9.5
A45: BASE CASE CASH FLOWS
A46: Item | C46: FY2026A | D46: FY2027E | E46: FY2028E | F46: FY2029E | G46: FY2030E | H46: FY2031E | I46: FY2032E | J46: FY2033E | K46: FY2034E | L46: FY2035E | M46: FY2036E
A47: Revenue | C47: =DCF!E64 -> 331839 | D47: =C47*(1+DCF!F31) -> 384933.24 | E47: =D47*(1+DCF!G31) -> 442673.23 | F47: =E47*(1+DCF!H31) -> 504647.48 | G47: =F47*(1+DCF!I31) -> 570251.65 | H47: =G47*(1+DCF!J31) -> 638681.85 | I47: =H47*(1+DCF!K31) -> 708936.85 | J47: =I47*(1+DCF!L31) -> 779830.54 | K47: =J47*(1+DCF!M31) -> 842216.98 | ... M47: =L47*(1+DCF!O31) -> 932923.75
A48: EBIT | D48: =D47*DCF!F32 -> 178993.96 | E48: =E47*DCF!G32 -> 205843.05 | F48: =F47*DCF!H32 -> 237184.31 | G48: =G47*DCF!I32 -> 270869.53 | H48: =H47*DCF!J32 -> 306567.29 | I48: =I47*DCF!K32 -> 340289.69 | J48: =J47*DCF!L32 -> 374318.66 | K48: =K47*DCF!M32 -> 404264.15 | ... M48: =M47*DCF!O32 -> 447803.4
A49: NOPAT | D49: =D48*(1-DCF!F36) -> 144985.1 | E49: =E48*(1-DCF!G36) -> 166732.87 | F49: =F48*(1-DCF!H36) -> 192119.29 | G49: =G48*(1-DCF!I36) -> 219404.32 | H49: =H48*(1-DCF!J36) -> 248319.5 | I49: =I48*(1-DCF!K36) -> 275634.65 | J49: =J48*(1-DCF!L36) -> 303198.11 | K49: =K48*(1-DCF!M36) -> 327453.96 | ... M49: =M48*(1-DCF!O36) -> 362720.75
A50: UFCF | D50: =D49+D47*DCF!F33-D47*DCF!F34-(D47-C47)*DCF!F35 -> 61826.251 | E50: =E49+E47*DCF!G33-E47*DCF!G34-(E47-D47)*DCF!G35 -> 89072.589 | F50: =F49+F47*DCF!H33-F47*DCF!H34-(F47-E47)*DCF!H35 -> 126603.66 | G50: =G49+G47*DCF!I33-G47*DCF!I34-(G47-F47)*DCF!I35 -> 168535.86 | H50: =H49+H47*DCF!J33-H47*DCF!J34-(H47-G47)*DCF!J35 -> 210910.99 | I50: =I49+I47*DCF!K33-I47*DCF!K34-(I47-H47)*DCF!K35 -> 245201.46 | J50: =J49+J47*DCF!L33-J47*DCF!L34-(J47-I47)*DCF!L35 -> 278030.85 | K50: =K49+K47*DCF!M33-K47*DCF!M34-(K47-J47)*DCF!M35 -> 305618.71 | ... M50: =M49+M47*DCF!O33-M47*DCF!O34-(M47-L47)*DCF!O35 -> 350177.62
A51: Discount factor | D51: =1/(1+D$24)^D53 -> 0.95128027 | E51: =1/(1+D$24)^E53 -> 0.86084601 | F51: =1/(1+D$24)^F53 -> 0.77900895 | G51: =1/(1+D$24)^G53 -> 0.70495181 | H51: =1/(1+D$24)^H53 -> 0.63793497 | I51: =1/(1+D$24)^I53 -> 0.57728914 | J51: =1/(1+D$24)^J53 -> 0.52240866 | K51: =1/(1+D$24)^K53 -> 0.47274544 | L51: =1/(1+D$24)^L53 -> 0.42780349 | M51: =1/(1+D$24)^M53 -> 0.38713399
A52: PV UFCF | D52: =D50*D51 -> 58814.093 | E52: =E50*E51 -> 76677.783 | F52: =F50*F51 -> 98625.383 | G52: =G50*G51 -> 118809.66 | H52: =H50*H51 -> 134547.5 | I52: =I50*I51 -> 141552.14 | J52: =J50*J51 -> 145245.73 | K52: =K50*K51 -> 144479.85 | ... M52: =M50*M51 -> 135565.66
A53: Period | D53: =DCF!F82 -> 0.5 | E53: =DCF!G82 -> 1.5 | F53: =DCF!H82 -> 2.5 | G53: =DCF!I82 -> 3.5 | H53: =DCF!J82 -> 4.5 | I53: =DCF!K82 -> 5.5 | J53: =DCF!L82 -> 6.5 | K53: =DCF!M82 -> 7.5 | ... M53: =DCF!O82 -> 9.5
A55: BULL CASE CASH FLOWS
A56: Item | C56: FY2026A | D56: FY2027E | E56: FY2028E | F56: FY2029E | G56: FY2030E | H56: FY2031E | I56: FY2032E | J56: FY2033E | K56: FY2034E | L56: FY2035E | M56: FY2036E
A57: Revenue | C57: =DCF!E64 -> 331839 | D57: =C57*(1+DCF!F42) -> 394888.41 | E57: =D57*(1+DCF!G42) -> 465968.32 | F57: =E57*(1+DCF!H42) -> 545182.94 | G57: =F57*(1+DCF!I42) -> 632412.21 | H57: =G57*(1+DCF!J42) -> 727274.04 | I57: =H57*(1+DCF!K42) -> 821819.67 | J57: =I57*(1+DCF!L42) -> 920438.03 | K57: =J57*(1+DCF!M42) -> 1012481.8 | ... M57: =L57*(1+DCF!O42) -> 1159089.2
A58: EBIT | D58: =D57*DCF!F43 -> 187571.99 | E58: =E57*DCF!G43 -> 223664.8 | F58: =F57*DCF!H43 -> 264413.73 | G58: =G57*DCF!I43 -> 309881.98 | H58: =H57*DCF!J43 -> 360000.65 | I58: =I57*DCF!K43 -> 410909.83 | J58: =J57*DCF!L43 -> 460219.01 | K58: =K57*DCF!M43 -> 506240.91 | ... M58: =M57*DCF!O43 -> 579544.6
A59: NOPAT | D59: =D58*(1-DCF!F47) -> 151933.32 | E59: =E58*(1-DCF!G47) -> 181168.48 | F59: =F58*(1-DCF!H47) -> 214175.12 | G59: =G58*(1-DCF!I47) -> 251004.41 | H59: =H58*(1-DCF!J47) -> 291600.53 | I59: =I58*(1-DCF!K47) -> 332836.96 | J59: =J58*(1-DCF!L47) -> 372777.4 | K59: =K58*(1-DCF!M47) -> 410055.14 | ... M59: =M58*(1-DCF!O47) -> 469431.12
A60: UFCF | D60: =D59+D57*DCF!F44-D57*DCF!F45-(D57-C57)*DCF!F46 -> 73835.007 | E60: =E59+E57*DCF!G44-E57*DCF!G45-(E57-D57)*DCF!G46 -> 110246.53 | F60: =F59+F57*DCF!H44-F57*DCF!H45-(F57-E57)*DCF!H46 -> 156045.57 | G60: =G59+G57*DCF!I44-G57*DCF!I45-(G57-F57)*DCF!I46 -> 209243.39 | H60: =H59+H57*DCF!J44-H57*DCF!J45-(H57-G57)*DCF!J46 -> 265829.73 | I60: =I59+I57*DCF!K44-I57*DCF!K45-(I57-H57)*DCF!K46 -> 312946.02 | J60: =J59+J57*DCF!L44-J57*DCF!L45-(J57-I57)*DCF!L46 -> 355683.55 | K60: =K59+K57*DCF!M44-K57*DCF!M45-(K57-J57)*DCF!M46 -> 397629.23 | ... M60: =M59+M57*DCF!O44-M57*DCF!O45-(M57-L57)*DCF!O46 -> 464182.42
A61: Discount factor | D61: =1/(1+E$24)^D63 -> 0.95343972 | E61: =1/(1+E$24)^E63 -> 0.86672179 | F61: =1/(1+E$24)^F63 -> 0.7878911 | G61: =1/(1+E$24)^G63 -> 0.71623027 | H61: =1/(1+E$24)^H63 -> 0.65108719 | I61: =1/(1+E$24)^I63 -> 0.59186905 | J61: =1/(1+E$24)^J63 -> 0.53803696 | K61: =1/(1+E$24)^K63 -> 0.48910104 | L61: =1/(1+E$24)^L63 -> 0.44461598 | M61: =1/(1+E$24)^M63 -> 0.40417695
A62: PV UFCF | D62: =D60*D61 -> 70397.228 | E62: =E60*E61 -> 95553.067 | F62: =F60*F61 -> 122946.92 | G62: =G60*G61 -> 149866.45 | H62: =H60*H61 -> 173078.33 | I62: =I60*I61 -> 185223.06 | J62: =J60*J61 -> 191370.9 | K62: =K60*K61 -> 194480.87 | ... M62: =M60*M61 -> 187611.83
A63: Period | D63: =DCF!F82 -> 0.5 | E63: =DCF!G82 -> 1.5 | F63: =DCF!H82 -> 2.5 | G63: =DCF!I82 -> 3.5 | H63: =DCF!J82 -> 4.5 | I63: =DCF!K82 -> 5.5 | J63: =DCF!L82 -> 6.5 | K63: =DCF!M82 -> 7.5 | ... M63: =DCF!O82 -> 9.5

Sheet Comps
A1: BIG TECH - COMPARABLE COMPANY ANALYSIS (peer set for MSFT DCF)
A2: Alphabet (GOOGL) • Amazon (AMZN) • Meta Platforms (META) • Apple (AAPL) • Oracle (ORCL) | Target: Microsoft (MSFT)
A3: Prices as of 2026-10-14 close | LTM financials through each company's latest reported quarter | USD millions except per-share amounts and ratios
A5: OPERATING METRICS (LTM)
A6: Company | B6: Ticker | C6: Revenue | D6: Gross Profit | E6: Gross Margin | F6: Operating Income | G6: Operating Margin | H6: EBITDA | I6: EBITDA Margin | J6: Net Income | K6: Free Cash Flow | L6: FCF Margin
A7: Alphabet | B7: GOOGL | C7: 445870 | D7: 271520 | E7: =D7/C7 -> 0.60896674 | F7: 147630 | G7: =F7/C7 -> 0.33110548 | H7: 173160 | I7: =H7/C7 -> 0.38836432 | J7: 244120 | K7: 53270 | L7: =K7/C7 -> 0.11947429
A8: Amazon | B8: AMZN | C8: 775680 | D8: 393810 | E8: =D8/C8 -> 0.50769647 | F8: 93710 | G8: =F8/C8 -> 0.12081013 | H8: 168910 | I8: =H8/C8 -> 0.21775732 | J8: 135280 | K8: -11630 | L8: =K8/C8 -> -0.014993296
A9: Meta Platforms | B9: META | C9: 228250 | D9: 186590 | E9: =D9/C9 -> 0.81748083 | F9: 86930 | G9: =F9/C9 -> 0.38085433 | H9: 109660 | I9: =H9/C9 -> 0.48043812 | J9: 68100 | K9: 40980 | L9: =K9/C9 -> 0.17953998
A10: Apple | B10: AAPL | C10: 466820 | D10: 227120 | E10: =D10/C10 -> 0.48652586 | F10: 154860 | G10: =F10/C10 -> 0.33173386 | H10: 167960 | I10: =H10/C10 -> 0.35979607 | J10: 128930 | K10: 136680 | L10: =K10/C10 -> 0.29278951
A11: Oracle | B11: ORCL | C11: 71780 | D11: 45910 | E11: =D11/C11 -> 0.6395932 | F11: 24600 | G11: =F11/C11 -> 0.34271385 | H11: 34430 | I11: =H11/C11 -> 0.47966007 | J11: 18740 | K11: -28720 | L11: =K11/C11 -> -0.40011145
A13: Maximum | E13: =MAX(E7:E11) -> 0.81748083 | G13: =MAX(G7:G11) -> 0.38085433 | I13: =MAX(I7:I11) -> 0.48043812 | L13: =MAX(L7:L11) -> 0.29278951
A14: 75th Percentile | E14: =QUARTILE(E7:E11,3) -> 0.6395932 | G14: =QUARTILE(G7:G11,3) -> 0.34271385 | I14: =QUARTILE(I7:I11,3) -> 0.47966007 | L14: =QUARTILE(L7:L11,3) -> 0.17953998
A15: Median | E15: =MEDIAN(E7:E11) -> 0.60896674 | G15: =MEDIAN(G7:G11) -> 0.33173386 | I15: =MEDIAN(I7:I11) -> 0.38836432 | L15: =MEDIAN(L7:L11) -> 0.11947429
A16: 25th Percentile | E16: =QUARTILE(E7:E11,1) -> 0.50769647 | G16: =QUARTILE(G7:G11,1) -> 0.33110548 | I16: =QUARTILE(I7:I11,1) -> 0.35979607 | L16: =QUARTILE(L7:L11,1) -> -0.014993296
A17: Minimum | E17: =MIN(E7:E11) -> 0.48652586 | G17: =MIN(G7:G11) -> 0.12081013 | I17: =MIN(I7:I11) -> 0.21775732 | L17: =MIN(L7:L11) -> -0.40011145
A19: Microsoft (target, excluded from stats) | B19: MSFT | C19: 331839 | D19: 225465 | E19: =D19/C19 -> 0.67944093 | F19: 155237 | G19: =F19/C19 -> 0.46780818 | H19: 193771 | I19: =H19/C19 -> 0.58393076 | J19: 133749 | K19: 66987 | L19: =K19/C19 -> 0.20186597
A21: VALUATION MULTIPLES
A22: Company | B22: Ticker | C22: Share Price ($) | D22: Shares Out (M) | E22: Market Cap | F22: Total Debt | G22: Cash & ST Inv. | H22: Enterprise Value | I22: EV / Revenue | J22: EV / EBITDA | K22: P / E | L22: FCF Yield
A23: Alphabet | B23: GOOGL | C23: 347.64 | D23: 12230 | E23: =C23*D23 -> 4251637.2 | F23: 120790 | G23: 242470 | H23: =E23+F23-G23 -> 4129957.2 | I23: =H23/C7 -> 9.2626936 | J23: =H23/H7 -> 23.850527 | K23: =E23/J7 -> 17.416177 | L23: =K7/E23 -> 0.012529291
A24: Amazon | B24: AMZN | C24: 254.08 | D24: 10790 | E24: =C24*D24 -> 2741523.2 | F24: 251640 | G24: 122990 | H24: =E24+F24-G24 -> 2870173.2 | I24: =H24/C8 -> 3.7002027 | J24: =H24/H8 -> 16.992323 | K24: =E24/J8 -> 20.265547 | L24: =K8/E24 -> -0.0042421673
A25: Meta Platforms | B25: META | C25: 737.54 | D25: 2550 | E25: =C25*D25 -> 1880727 | F25: 112320 | G25: 90260 | H25: =E25+F25-G25 -> 1902787 | I25: =H25/C9 -> 8.3364162 | J25: =H25/H9 -> 17.351696 | K25: =E25/J9 -> 27.617137 | L25: =K9/E25 -> 0.021789446
A26: Apple | B26: AAPL | C26: 342.96 | D26: 14590 | E26: =C26*D26 -> 5003786.4 | F26: 84340 | G26: 146520 | H26: =E26+F26-G26 -> 4941606.4 | I26: =H26/C10 -> 10.585678 | J26: =H26/H10 -> 29.421329 | K26: =E26/J10 -> 38.810102 | L26: =K10/E26 -> 0.027315315
A27: Oracle | B27: ORCL | C27: 130.55 | D27: 3030 | E27: =C27*D27 -> 395566.5 | F27: 169140 | G27: 37080 | H27: =E27+F27-G27 -> 527626.5 | I27: =H27/C11 -> 7.350606 | J27: =H27/H11 -> 15.324615 | K27: =E27/J11 -> 21.108138 | L27: =K11/E27 -> -0.072604733
A29: Maximum | I29: =MAX(I23:I27) -> 10.585678 | J29: =MAX(J23:J27) -> 29.421329 | K29: =MAX(K23:K27) -> 38.810102 | L29: =MAX(L23:L27) -> 0.027315315
A30: 75th Percentile | I30: =QUARTILE(I23:I27,3) -> 9.2626936 | J30: =QUARTILE(J23:J27,3) -> 23.850527 | K30: =QUARTILE(K23:K27,3) -> 27.617137 | L30: =QUARTILE(L23:L27,3) -> 0.021789446
A31: Median | I31: =MEDIAN(I23:I27) -> 8.3364162 | J31: =MEDIAN(J23:J27) -> 17.351696 | K31: =MEDIAN(K23:K27) -> 21.108138 | L31: =MEDIAN(L23:L27) -> 0.012529291
A32: 25th Percentile | I32: =QUARTILE(I23:I27,1) -> 7.350606 | J32: =QUARTILE(J23:J27,1) -> 16.992323 | K32: =QUARTILE(K23:K27,1) -> 20.265547 | L32: =QUARTILE(L23:L27,1) -> -0.0042421673
A33: Minimum | I33: =MIN(I23:I27) -> 3.7002027 | J33: =MIN(J23:J27) -> 15.324615 | K33: =MIN(K23:K27) -> 17.416177 | L33: =MIN(L23:L27) -> -0.072604733
A35: Microsoft (target, excluded from stats) | B35: MSFT | C35: 533.69 | D35: 7430 | E35: =C35*D35 -> 3965316.7 | F35: 128810 | G35: 76843 | H35: =E35+F35-G35 -> 4017283.7 | I35: =H35/C19 -> 12.106123 | J35: =H35/H19 -> 20.73212 | K35: =E35/J19 -> 29.647449 | L35: =K19/E35 -> 0.016893228
A38: NOTES & METHODOLOGY
A39: Data: peer LTM financials, prices, shares, debt and cash from stockanalysis.com statistics pages accessed 2026-10-14 (close 2026-10-14). MSFT financials from FY26 (June 30, 2026) earnings release.
A40: EBITDA = operating income + D&A (provider definition for peers). FCF = operating cash flow - capex. EV = market cap + total debt (incl. lease liabilities) - cash & short-term investments.
A41: Statistics exclude MSFT. Peer GOOGL/AMZN net income includes large unrealised gains on AI-lab investments, which depresses their P/E; EV/EBITDA is the primary multiple.
A42: Peer fiscal periods differ (AAPL Sep FYE, ORCL May FYE, MSFT Jun FYE); LTM basis used for all. AMZN and ORCL FCF negative due to AI capex.
