Workbook

Sheet Inputs
A1: Zoom Communications (ZM) - Take-Private LBO: Inputs
A2: USD millions except per-share; blue = hard-coded input, black = formula, purple = same-tab link, green = cross-tab link
A3: MARKET DATA
A4: Current share price (USD) | B4: 98.51 | C4: stock-data get_quote, close 2026-10-15
A5: Price date | B5: 2026-10-15
A6: Basic shares outstanding (m) | B6: 291.78371 | C6: 10-Q filed 2026-08-26 cover: 263.233m Cl.A + 28.551m Cl.B as of 2026-08-14
A7: Dilutive securities, treasury method (m) | B7: 6.867 | C7: Estimate: FY27Q2 weighted diluted 299.746m less basic 292.879m
A8: Diluted shares (m) | B8: =B6+B7 -> 298.65071
A9: Cash & cash equivalents | B9: 931.99 | C9: 10-Q 2026-07-31
A10: Short-term marketable securities | B10: 6317.73 | C10: 10-Q 2026-07-31
A11: Existing debt | B11: 0 | C11: 10-Q 2026-07-31: no borrowings
A12: SOFR | B12: 0.0388 | C12: FRED SOFR, 2026-10-14
A13: High-yield OAS (ICE BofA US HY) | B13: 0.0325 | C13: FRED BAMLH0A0HYM2, 2026-10-14
A14: 7-year US Treasury yield | B14: 0.0509 | C14: FRED DGS7, 2026-10-14
A16: LTM FINANCIALS (four fiscal quarters to 2026-07-31; source: SEC XBRL via stock-data get_financials)
A17: USD m | B17: FY26Q3 | C17: FY26Q4 | D17: FY27Q1 | E17: FY27Q2 | F17: LTM
A18: Revenue | B18: 1229.84 | C18: 1246.99 | D18: 1239.01 | E18: 1277.22 | F18: =SUM(B18:E18) -> 4993.06
A19: Operating income (GAAP) | B19: 310.41 | C19: 249.89 | D19: 310.47 | E19: 314.32 | F19: =SUM(B19:E19) -> 1185.09
A20: Depreciation & amortization | B20: 32.39 | C20: 32.96 | D20: 32.78 | E20: 32.33 | F20: =SUM(B20:E20) -> 130.46
A21: Stock-based compensation | B21: 185.28 | C21: 185.23 | D21: 178.95 | E21: 179.78 | F21: =SUM(B21:E21) -> 729.24
A22: Capital expenditures | B22: 15.01 | C22: 16.08 | D22: 21.11 | E22: 22.35 | F22: =SUM(B22:E22) -> 74.55
A23: EBITDA = Op. income + D&A (SBC expensed) | B23: =B19+B20 -> 342.8 | C23: =C19+C20 -> 282.85 | D23: =D19+D20 -> 343.25 | E23: =E19+E20 -> 346.65 | F23: =F19+F20 -> 1315.55
A24: Adj. EBITDA incl. SBC add-back (memo) | B24: =B23+B21 -> 528.08 | C24: =C23+C21 -> 468.08 | D24: =D23+D21 -> 522.2 | E24: =E23+E21 -> 526.43 | F24: =F23+F21 -> 2044.79
A25: EBITDA margin | B25: =B23/B18 -> 0.27873545 | C25: =C23/C18 -> 0.2268262 | D25: =D23/D18 -> 0.2770357 | E25: =E23/E18 -> 0.27140978 | F25: =F23/F18 -> 0.2634757
A27: TRANSACTION & FINANCING ASSUMPTIONS
A28: Offer premium to current price | B28: 0.3 | C28: Per user
A29: Minimum operating cash retained | B29: 500 | C29: Default (~10% of LTM revenue)
A30: Transaction / advisory fees (% of EV) | B30: 0.02 | C30: Default
A31: Financing fees (% of debt raised) | B31: 0.025 | C31: Default
A32: Term Loan B size (x LTM EBITDA) | B32: 4 | C32: Default
A33: Term Loan B spread over SOFR | B33: 0.0325 | C33: Default (single-B software TLB)
A34: Term Loan B mandatory amortization (% p.a.) | B34: 0.01 | C34: Market standard
A35: Senior notes size (x LTM EBITDA) | B35: 2 | C35: Default
A36: Excess cash sweep to Term Loan B | B36: 1 | C36: Default
A37: Cash tax rate | B37: 0.23 | C37: Default (21% federal + state)
A38: Exit multiple vs entry multiple (+/- x) | B38: 0 | C38: Per user: exit at entry EV/EBITDA
A39: Holding period (years) | B39: 5 | C39: Per user
A41: OPERATING ASSUMPTIONS
B42: Year 1 | C42: Year 2 | D42: Year 3 | E42: Year 4 | F42: Year 5
A43: Revenue growth | B43: 0.045 | C43: 0.045 | D43: 0.04 | E43: 0.04 | F43: 0.035
...

Sheet Sources & Uses
A1: Sources & Uses
A3: PURCHASE PRICE
A4: Current share price (USD) | B4: =Inputs!B4 -> 98.51
A5: Offer premium | B5: =Inputs!B28 -> 0.3
A6: Offer price per share (USD) | B6: =B4*(1+B5) -> 128.063
A7: Diluted shares (m) | B7: =Inputs!B8 -> 298.65071
A8: Equity purchase price | B8: =B6*B7 -> 38246.106
A9: Less: cash & short-term investments | B9: =-(Inputs!B9+Inputs!B10) -> -7249.72
A10: Plus: existing debt | B10: =Inputs!B11 -> 0
A11: Entry enterprise value | B11: =B8+B9+B10 -> 30996.386
A12: LTM EBITDA (SBC expensed) | B12: =Inputs!F23 -> 1315.55
A13: Entry EV / LTM EBITDA | B13: =B11/B12 -> 23.561542
A14: Entry EV / LTM Adj. EBITDA (SBC added back) | B14: =B11/Inputs!F24 -> 15.158714
A15: Entry EV / LTM revenue | B15: =B11/Inputs!F18 -> 6.2078938
A17: SOURCES
A18: Source | B18: USD m | C18: % of total | D18: x EBITDA
A19: Term Loan B (SOFR + spread) | B19: =Inputs!B32*B12 -> 5262.2 | C19: =B19/$B$23 -> 0.13470933 | D19: =B19/$B$12 -> 4
A20: Senior unsecured notes (UST + HY OAS) | B20: =Inputs!B35*B12 -> 2631.1 | C20: =B20/$B$23 -> 0.067354666 | D20: =B20/$B$12 -> 2
A21: Existing cash used (above minimum) | B21: =Inputs!B9+Inputs!B10-Inputs!B29 -> 6749.72 | C21: =B21/$B$23 -> 0.172789 | D21: =B21/$B$12 -> 5.130721
A22: Sponsor equity (plug) | B22: =B31-B19-B20-B21 -> 24420.346 | C22: =B22/$B$23 -> 0.625147 | D22: =B22/$B$12 -> 18.562842
A23: Total sources | B23: =SUM(B19:B22) -> 39063.366 | C23: =B23/$B$23 -> 1 | D23: =B23/$B$12 -> 29.693563
A25: USES
A26: Use | B26: USD m | C26: % of total
A27: Purchase of diluted equity | B27: =B8 -> 38246.106 | C27: =B27/$B$31 -> 0.9790786
A28: Refinance existing debt | B28: =B10 -> 0 | C28: =B28/$B$31 -> 0
A29: Transaction / advisory fees | B29: =Inputs!B30*B11 -> 619.92772 | C29: =B29/$B$31 -> 0.015869798
A30: Financing fees | B30: =Inputs!B31*(B19+B20) -> 197.3325 | C30: =B30/$B$31 -> 0.0050516
A31: Total uses | B31: =SUM(B27:B30) -> 39063.366 | C31: =B31/$B$31 -> 1
A32: Check: sources - uses (must be 0) | B32: =ROUND(B23-B31,6) -> 0
A34: CAPITAL STRUCTURE AT CLOSE
A35: Total debt raised | B35: =B19+B20 -> 7893.3
A36: Total leverage (x LTM EBITDA) | B36: =B35/B12 -> 6
A37: Total leverage (x LTM Adj. EBITDA) | B37: =B35/Inputs!F24 -> 3.8602008
A38: Net leverage (x LTM EBITDA, after minimum cash) | B38: =(B35-Inputs!B29)/B12 -> 5.6199308
A39: Sponsor equity % of total capitalization | B39: =B22/(B22+B35) -> 0.75572859

Sheet Operating Model
A1: Operating Model (USD m)
A3: USD m | B3: LTM Jul-26 | C3: Year 1 | D3: Year 2 | E3: Year 3 | F3: Year 4 | G3: Year 5
A4: INCOME STATEMENT
A5: Revenue | B5: =Inputs!F18 -> 4993.06 | C5: =B5*(1+Inputs!B43) -> 5217.7477 | D5: =C5*(1+Inputs!C43) -> 5452.5463 | E5: =D5*(1+Inputs!D43) -> 5670.6482 | F5: =E5*(1+Inputs!E43) -> 5897.4741 | G5: =F5*(1+Inputs!F43) -> 6103.8857
A6: growth % | C6: =C5/B5-1 -> 0.045 | D6: =D5/C5-1 -> 0.045 | E6: =E5/D5-1 -> 0.04 | F6: =F5/E5-1 -> 0.04 | G6: =G5/F5-1 -> 0.035
A7: EBITDA (SBC expensed) | B7: =Inputs!F23 -> 1315.55 | C7: =C5*Inputs!B44 -> 1382.7031 | D7: =D5*Inputs!C44 -> 1472.1875 | E7: =E5*Inputs!D44 -> 1559.4283 | F7: =F5*Inputs!E44 -> 1651.2928 | G7: =G5*Inputs!F44 -> 1739.6074
A8: margin % | B8: =B7/B5 -> 0.2634757 | C8: =C7/C5 -> 0.265 | D8: =D7/D5 -> 0.27 | E8: =E7/E5 -> 0.275 | F8: =F7/F5 -> 0.28 | G8: =G7/G5 -> 0.285
A9: Depreciation & amortization | B9: =Inputs!F20 -> 130.46 | C9: =C5*Inputs!B45 -> 135.66144 | D9: =D5*Inputs!C45 -> 141.76621 | E9: =E5*Inputs!D45 -> 147.43685 | F9: =F5*Inputs!E45 -> 153.33433 | G9: =G5*Inputs!F45 -> 158.70103
A10: EBIT | B10: =B7-B9 -> 1185.09 | C10: =C7-C9 -> 1247.0417 | D10: =D7-D9 -> 1330.4213 | E10: =E7-E9 -> 1411.9914 | F10: =F7-F9 -> 1497.9584 | G10: =G7-G9 -> 1580.9064
A11: Interest expense | C11: ='Debt Schedule'!C26 -> 594.6286 | D11: ='Debt Schedule'!D26 -> 553.11617 | E11: ='Debt Schedule'!E26 -> 504.49079 | F11: ='Debt Schedule'!F26 -> 448.66554 | G11: ='Debt Schedule'!G26 -> 384.81566
A12: Pre-tax income | C12: =C10-C11 -> 652.4131 | D12: =D10-D11 -> 777.30514 | E12: =E10-E11 -> 907.50061 | F12: =F10-F11 -> 1049.2929 | G12: =G10-G11 -> 1196.0907
A13: Taxes | C13: =MAX(0,C12)*Inputs!$B$37 -> 150.05501 | D13: =MAX(0,D12)*Inputs!$B$37 -> 178.78018 | E13: =MAX(0,E12)*Inputs!$B$37 -> 208.72514 | F13: =MAX(0,F12)*Inputs!$B$37 -> 241.33736 | G13: =MAX(0,G12)*Inputs!$B$37 -> 275.10087
A14: Net income | C14: =C12-C13 -> 502.35809 | D14: =D12-D13 -> 598.52496 | E14: =E12-E13 -> 698.77547 | F14: =F12-F13 -> 807.95552 | G14: =G12-G13 -> 920.98987
A16: FREE CASH FLOW
A17: Net income | C17: =C14 -> 502.35809 | D17: =D14 -> 598.52496 | E17: =E14 -> 698.77547 | F17: =F14 -> 807.95552 | G17: =G14 -> 920.98987
A18: Plus: D&A | C18: =C9 -> 135.66144 | D18: =D9 -> 141.76621 | E18: =E9 -> 147.43685 | F18: =F9 -> 153.33433 | G18: =G9 -> 158.70103
A19: Less: capex | C19: =-C5*Inputs!B46 -> -78.266216 | D19: =-D5*Inputs!C46 -> -81.788195 | E19: =-E5*Inputs!D46 -> -85.059723 | F19: =-F5*Inputs!E46 -> -88.462112 | G19: =-G5*Inputs!F46 -> -91.558286
A20: Less: increase in NWC | C20: =-(C5-B5)*Inputs!B47 -> 22.46877 | D20: =-(D5-C5)*Inputs!C47 -> 23.479865 | E20: =-(E5-D5)*Inputs!D47 -> 21.810185 | F20: =-(F5-E5)*Inputs!E47 -> 22.682593 | G20: =-(G5-F5)*Inputs!F47 -> 20.641159
A21: Free cash flow available for debt service | C21: =SUM(C17:C20) -> 582.22208 | D21: =SUM(D17:D20) -> 681.98283 | E21: =SUM(E17:E20) -> 782.96279 | F21: =SUM(F17:F20) -> 895.51033 | G21: =SUM(G17:G20) -> 1008.7738
A22: Memo: FCF / EBITDA | C22: =C21/C7 -> 0.42107526 | D22: =D21/D7 -> 0.46324454 | E22: =E21/E7 -> 0.50208324 | F22: =F21/F7 -> 0.54230864 | G22: =G21/G7 -> 0.57988587

Sheet Debt Schedule
A1: Debt Schedule (USD m) - interest on beginning balances (no circularity)
A3: USD m | B3: Close | C3: Year 1 | D3: Year 2 | E3: Year 3 | F3: Year 4 | G3: Year 5
A4: FCF available for debt service | C4: ='Operating Model'!C21 -> 582.22208 | D4: ='Operating Model'!D21 -> 681.98283 | E4: ='Operating Model'!E21 -> 782.96279 | F4: ='Operating Model'!F21 -> 895.51033 | G4: ='Operating Model'!G21 -> 1008.7738
A5: CASH
A6: Beginning cash | C6: =B9 -> 500 | D6: =C9 -> 500 | E6: =D9 -> 500 | F6: =E9 -> 500 | G6: =F9 -> 500
A7: Plus: FCF | C7: =C4 -> 582.22208 | D7: =D4 -> 681.98283 | E7: =E4 -> 782.96279 | F7: =F4 -> 895.51033 | G7: =G4 -> 1008.7738
A8: Less: debt repayment | C8: =C13+C14 -> -582.22208 | D8: =D13+D14 -> -681.98283 | E8: =E13+E14 -> -782.96279 | F8: =F13+F14 -> -895.51033 | G8: =G13+G14 -> -1008.7738
A9: Ending cash | B9: =Inputs!B29 -> 500 | C9: =SUM(C6:C8) -> 500 | D9: =SUM(D6:D8) -> 500 | E9: =SUM(E6:E8) -> 500 | F9: =SUM(F6:F8) -> 500 | G9: =SUM(G6:G8) -> 500
A11: TERM LOAN B
A12: Beginning balance | C12: =B15 -> 5262.2 | D12: =C15 -> 4679.9779 | E12: =D15 -> 3997.9951 | F12: =E15 -> 3215.0323 | G12: =F15 -> 2319.522
A13: Mandatory amortization | C13: =-MIN(C12,'Sources & Uses'!$B$19*Inputs!$B$34) -> -52.622 | D13: =-MIN(D12,'Sources & Uses'!$B$19*Inputs!$B$34) -> -52.622 | E13: =-MIN(E12,'Sources & Uses'!$B$19*Inputs!$B$34) -> -52.622 | F13: =-MIN(F12,'Sources & Uses'!$B$19*Inputs!$B$34) -> -52.622 | G13: =-MIN(G12,'Sources & Uses'!$B$19*Inputs!$B$34) -> -52.622
A14: Optional repayment (cash sweep) | C14: =-MAX(0,MIN(C12+C13,Inputs!$B$36*(C6+C4+C13-Inputs!$B$29))) -> -529.60008 | D14: =-MAX(0,MIN(D12+D13,Inputs!$B$36*(D6+D4+D13-Inputs!$B$29))) -> -629.36083 | E14: =-MAX(0,MIN(E12+E13,Inputs!$B$36*(E6+E4+E13-Inputs!$B$29))) -> -730.34079 | F14: =-MAX(0,MIN(F12+F13,Inputs!$B$36*(F6+F4+F13-Inputs!$B$29))) -> -842.88833 | G14: =-MAX(0,MIN(G12+G13,Inputs!$B$36*(G6+G4+G13-Inputs!$B$29))) -> -956.15178
A15: Ending balance | B15: ='Sources & Uses'!B19 -> 5262.2 | C15: =SUM(C12:C14) -> 4679.9779 | D15: =SUM(D12:D14) -> 3997.9951 | E15: =SUM(E12:E14) -> 3215.0323 | F15: =SUM(F12:F14) -> 2319.522 | G15: =SUM(G12:G14) -> 1310.7482
A16: Interest rate (SOFR + spread) | C16: =Inputs!$B$12+Inputs!$B$33 -> 0.0713 | D16: =Inputs!$B$12+Inputs!$B$33 -> 0.0713 | E16: =Inputs!$B$12+Inputs!$B$33 -> 0.0713 | F16: =Inputs!$B$12+Inputs!$B$33 -> 0.0713 | G16: =Inputs!$B$12+Inputs!$B$33 -> 0.0713
A17: Interest expense | C17: =C12*C16 -> 375.19486 | D17: =D12*D16 -> 333.68243 | E17: =E12*E16 -> 285.05705 | F17: =F12*F16 -> 229.2318 | G17: =G12*G16 -> 165.38192
A19: SENIOR UNSECURED NOTES (bullet)
A20: Beginning balance | C20: =B21 -> 2631.1 | D20: =C21 -> 2631.1 | E20: =D21 -> 2631.1 | F20: =E21 -> 2631.1 | G20: =F21 -> 2631.1
A21: Ending balance | B21: ='Sources & Uses'!B20 -> 2631.1 | C21: =C20 -> 2631.1 | D21: =D20 -> 2631.1 | E21: =E20 -> 2631.1 | F21: =F20 -> 2631.1 | G21: =G20 -> 2631.1
A22: Coupon (7Y UST + HY OAS) | C22: =Inputs!$B$14+Inputs!$B$13 -> 0.0834 | D22: =Inputs!$B$14+Inputs!$B$13 -> 0.0834 | E22: =Inputs!$B$14+Inputs!$B$13 -> 0.0834 | F22: =Inputs!$B$14+Inputs!$B$13 -> 0.0834 | G22: =Inputs!$B$14+Inputs!$B$13 -> 0.0834
A23: Interest expense | C23: =C20*C22 -> 219.43374 | D23: =D20*D22 -> 219.43374 | E23: =E20*E22 -> 219.43374 | F23: =F20*F22 -> 219.43374 | G23: =G20*G22 -> 219.43374
A24: SUMMARY
A25: Total debt (ending) | B25: =B15+B21 -> 7893.3 | C25: =C15+C21 -> 7311.0779 | D25: =D15+D21 -> 6629.0951 | E25: =E15+E21 -> 5846.1323 | F25: =F15+F21 -> 4950.622 | G25: =G15+G21 -> 3941.8482
A26: Total interest expense | C26: =C17+C23 -> 594.6286 | D26: =D17+D23 -> 553.11617 | E26: =E17+E23 -> 504.49079 | F26: =F17+F23 -> 448.66554 | G26: =G17+G23 -> 384.81566
A27: Total debt / EBITDA | B27: =B25/'Operating Model'!B7 -> 6 | C27: =C25/'Operating Model'!C7 -> 5.2875254 | D27: =D25/'Operating Model'!D7 -> 4.5028877 | E27: =E25/'Operating Model'!E7 -> 3.7488947 | F27: =F25/'Operating Model'!F7 -> 2.998028 | G27: =G25/'Operating Model'!G7 -> 2.2659412
A28: Net debt / EBITDA | B28: =(B25-B9)/'Operating Model'!B7 -> 5.6199308 | C28: =(C25-C9)/'Operating Model'!C7 -> 4.9259148 | D28: =(D25-D9)/'Operating Model'!D7 -> 4.1632571 | E28: =(E25-E9)/'Operating Model'!E7 -> 3.4282644 | F28: =(F25-F9)/'Operating Model'!F7 -> 2.695235 | G28: =(G25-G9)/'Operating Model'!G7 -> 1.9785201
A29: EBITDA / interest | C29: ='Operating Model'!C7/C26 -> 2.3253223 | D29: ='Operating Model'!D7/D26 -> 2.6616245 | E29: ='Operating Model'!E7/E26 -> 3.0910936 | F29: ='Operating Model'!F7/F26 -> 3.6804537 | G29: ='Operating Model'!G7/G26 -> 4.5206254
A30: Cumulative Term Loan B repaid (%) | C30: =1-C15/$B$15 -> 0.11064233 | D30: =1-D15/$B$15 -> 0.24024266 | E30: =1-E15/$B$15 -> 0.38903267 | F30: =1-F15/$B$15 -> 0.5592106 | G30: =1-G15/$B$15 -> 0.75091251

Sheet Returns
A1: Returns Analysis
A3: EXIT (END OF YEAR 5)
A4: Year 5 EBITDA | B4: ='Operating Model'!G7 -> 1739.6074
A5: Exit EV / EBITDA (= entry multiple + adj.) | B5: ='Sources & Uses'!B13+Inputs!B38 -> 23.561542
A6: Exit enterprise value | B6: =B4*B5 -> 40987.833
A7: Less: debt at exit | B7: =-'Debt Schedule'!G25 -> -3941.8482
A8: Plus: cash at exit | B8: ='Debt Schedule'!G9 -> 500
A9: Exit equity value | B9: =SUM(B6:B8) -> 37545.985
A10: Sponsor equity invested | B10: ='Sources & Uses'!B22 -> 24420.346
A11: MOIC | B11: =B9/B10 -> 1.5374878
A12: IRR | B12: =IRR(B16:G16) -> 0.089838977
A14: Sponsor cash flows | B14: Year 0 | C14: Year 1 | D14: Year 2 | E14: Year 3 | F14: Year 4 | G14: Year 5
A15: Period | B15: 0 | C15: 1 | D15: 2 | E15: 3 | F15: 4 | G15: 5
A16: Cash flow to / (from) sponsor | B16: =-B10 -> -24420.346 | C16: 0 | D16: 0 | E16: 0 | F16: 0 | G16: =B9 -> 37545.985
A18: SENSITIVITY: IRR
A19: Rows: offer premium to current price; columns: exit EV/EBITDA. Center = base case.
A20: Premium \ Exit multiple | B20: =$B$5+(-2) -> 21.561542 | C20: =$B$5+(-1) -> 22.561542 | D20: =$B$5 -> 23.561542 | E20: =$B$5+(1) -> 24.561542 | F20: =$B$5+(2) -> 25.561542 | G20: Sponsor equity | H20: Entry EV/EBITDA
A21: =Inputs!$B$28+(-0.1) -> 0.2 | B21: =((B$20*$B$4-'Debt Schedule'!$G$25+'Debt Schedule'!$G$9)/$G21)^(1/Inputs!$B$39)-1 -> 0.097246827 | C21: =((C$20*$B$4-'Debt Schedule'!$G$25+'Debt Schedule'!$G$9)/$G21)^(1/Inputs!$B$39)-1 -> 0.10823081 | D21: =((D$20*$B$4-'Debt Schedule'!$G$25+'Debt Schedule'!$G$9)/$G21)^(1/Inputs!$B$39)-1 -> 0.11879584 | E21: =((E$20*$B$4-'Debt Schedule'!$G$25+'Debt Schedule'!$G$9)/$G21)^(1/Inputs!$B$39)-1 -> 0.12897624 | F21: =((F$20*$B$4-'Debt Schedule'!$G$25+'Debt Schedule'!$G$9)/$G21)^(1/Inputs!$B$39)-1 -> 0.13880216 | G21: =Inputs!$B$4*(1+$A21)*Inputs!$B$8+'Sources & Uses'!$B$10+Inputs!$B$30*(Inputs!$B$4*(1+$A21)*Inputs!$B$8+'Sources & Uses'!$B$9+'Sources & Uses'!$B$10)+'Sources & Uses'!$B$30-'Sources & Uses'!$B$19-'Sources & Uses'!$B$20-'Sources & Uses'!$B$21 -> 21419.498 | H21: =(Inputs!$B$4*(1+$A21)*Inputs!$B$8+'Sources & Uses'!$B$9+'Sources & Uses'!$B$10)/'Sources & Uses'!$B$12 -> 21.325208
A22: =Inputs!$B$28+(-0.05) -> 0.25 | B22: =((B$20*$B$4-'Debt Schedule'!$G$25+'Debt Schedule'!$G$9)/$G22)^(1/Inputs!$B$39)-1 -> 0.082489179 | C22: =((C$20*$B$4-'Debt Schedule'!$G$25+'Debt Schedule'!$G$9)/$G22)^(1/Inputs!$B$39)-1 -> 0.093325429 | D22: =((D$20*$B$4-'Debt Schedule'!$G$25+'Debt Schedule'!$G$9)/$G22)^(1/Inputs!$B$39)-1 -> 0.10374836 | E22: =((E$20*$B$4-'Debt Schedule'!$G$25+'Debt Schedule'!$G$9)/$G22)^(1/Inputs!$B$39)-1 -> 0.11379184 | F22: =((F$20*$B$4-'Debt Schedule'!$G$25+'Debt Schedule'!$G$9)/$G22)^(1/Inputs!$B$39)-1 -> 0.12348561 | G22: =Inputs!$B$4*(1+$A22)*Inputs!$B$8+'Sources & Uses'!$B$10+Inputs!$B$30*(Inputs!$B$4*(1+$A22)*Inputs!$B$8+'Sources & Uses'!$B$9+'Sources & Uses'!$B$10)+'Sources & Uses'!$B$30-'Sources & Uses'!$B$19-'Sources & Uses'!$B$20-'Sources & Uses'!$B$21 -> 22919.922 | H22: =(Inputs!$B$4*(1+$A22)*Inputs!$B$8+'Sources & Uses'!$B$9+'Sources & Uses'!$B$10)/'Sources & Uses'!$B$12 -> 22.443375
A23: =Inputs!$B$28 -> 0.3 | B23: =((B$20*$B$4-'Debt Schedule'!$G$25+'Debt Schedule'!$G$9)/$G23)^(1/Inputs!$B$39)-1 -> 0.068847701 | C23: =((C$20*$B$4-'Debt Schedule'!$G$25+'Debt Schedule'!$G$9)/$G23)^(1/Inputs!$B$39)-1 -> 0.079547393 | D23: =((D$20*$B$4-'Debt Schedule'!$G$25+'Debt Schedule'!$G$9)/$G23)^(1/Inputs!$B$39)-1 -> 0.089838977 | E23: =((E$20*$B$4-'Debt Schedule'!$G$25+'Debt Schedule'!$G$9)/$G23)^(1/Inputs!$B$39)-1 -> 0.099755891 | F23: =((F$20*$B$4-'Debt Schedule'!$G$25+'Debt Schedule'!$G$9)/$G23)^(1/Inputs!$B$39)-1 -> 0.10932749 | G23: =Inputs!$B$4*(1+$A23)*Inputs!$B$8+'Sources & Uses'!$B$10+Inputs!$B$30*(Inputs!$B$4*(1+$A23)*Inputs!$B$8+'Sources & Uses'!$B$9+'Sources & Uses'!$B$10)+'Sources & Uses'!$B$30-'Sources & Uses'!$B$19-'Sources & Uses'!$B$20-'Sources & Uses'!$B$21 -> 24420.346 | H23: =(Inputs!$B$4*(1+$A23)*Inputs!$B$8+'Sources & Uses'!$B$9+'Sources & Uses'!$B$10)/'Sources & Uses'!$B$12 -> 23.561542
A24: =Inputs!$B$28+(0.05) -> 0.35 | B24: =((B$20*$B$4-'Debt Schedule'!$G$25+'Debt Schedule'!$G$9)/$G24)^(1/Inputs!$B$39)-1 -> 0.056176767 | C24: =((C$20*$B$4-'Debt Schedule'!$G$25+'Debt Schedule'!$G$9)/$G24)^(1/Inputs!$B$39)-1 -> 0.066749617 | D24: =((D$20*$B$4-'Debt Schedule'!$G$25+'Debt Schedule'!$G$9)/$G24)^(1/Inputs!$B$39)-1 -> 0.076919197 | E24: =((E$20*$B$4-'Debt Schedule'!$G$25+'Debt Schedule'!$G$9)/$G24)^(1/Inputs!$B$39)-1 -> 0.086718548 | F24: =((F$20*$B$4-'Debt Schedule'!$G$25+'Debt Schedule'!$G$9)/$G24)^(1/Inputs!$B$39)-1 -> 0.096176681 | G24: =Inputs!$B$4*(1+$A24)*Inputs!$B$8+'Sources & Uses'!$B$10+Inputs!$B$30*(Inputs!$B$4*(1+$A24)*Inputs!$B$8+'Sources & Uses'!$B$9+'Sources & Uses'!$B$10)+'Sources & Uses'!$B$30-'Sources & Uses'!$B$19-'Sources & Uses'!$B$20-'Sources & Uses'!$B$21 -> 25920.77 | H24: =(Inputs!$B$4*(1+$A24)*Inputs!$B$8+'Sources & Uses'!$B$9+'Sources & Uses'!$B$10)/'Sources & Uses'!$B$12 -> 24.679708
A25: =Inputs!$B$28+(0.1) -> 0.4 | B25: =((B$20*$B$4-'Debt Schedule'!$G$25+'Debt Schedule'!$G$9)/$G25)^(1/Inputs!$B$39)-1 -> 0.044356844 | C25: =((C$20*$B$4-'Debt Schedule'!$G$25+'Debt Schedule'!$G$9)/$G25)^(1/Inputs!$B$39)-1 -> 0.05481137 | D25: =((D$20*$B$4-'Debt Schedule'!$G$25+'Debt Schedule'!$G$9)/$G25)^(1/Inputs!$B$39)-1 -> 0.06486714 | E25: =((E$20*$B$4-'Debt Schedule'!$G$25+'Debt Schedule'!$G$9)/$G25)^(1/Inputs!$B$39)-1 -> 0.074556824 | F25: =((F$20*$B$4-'Debt Schedule'!$G$25+'Debt Schedule'!$G$9)/$G25)^(1/Inputs!$B$39)-1 -> 0.08390911 | G25: =Inputs!$B$4*(1+$A25)*Inputs!$B$8+'Sources & Uses'!$B$10+Inputs!$B$30*(Inputs!$B$4*(1+$A25)*Inputs!$B$8+'Sources & Uses'!$B$9+'Sources & Uses'!$B$10)+'Sources & Uses'!$B$30-'Sources & Uses'!$B$19-'Sources & Uses'!$B$20-'Sources & Uses'!$B$21 -> 27421.195 | H25: =(Inputs!$B$4*(1+$A25)*Inputs!$B$8+'Sources & Uses'!$B$9+'Sources & Uses'!$B$10)/'Sources & Uses'!$B$12 -> 25.797875
A27: SENSITIVITY: MOIC
A28: Rows: offer premium to current price; columns: exit EV/EBITDA. Center = base case.
A29: Premium \ Exit multiple | B29: =$B$5+(-2) -> 21.561542 | C29: =$B$5+(-1) -> 22.561542 | D29: =$B$5 -> 23.561542 | E29: =$B$5+(1) -> 24.561542 | F29: =$B$5+(2) -> 25.561542 | G29: Sponsor equity | H29: Entry EV/EBITDA
A30: =Inputs!$B$28+(-0.1) -> 0.2 | B30: =(B$29*$B$4-'Debt Schedule'!$G$25+'Debt Schedule'!$G$9)/$G30 -> 1.590456 | C30: =(C$29*$B$4-'Debt Schedule'!$G$25+'Debt Schedule'!$G$9)/$G30 -> 1.6716721 | D30: =(D$29*$B$4-'Debt Schedule'!$G$25+'Debt Schedule'!$G$9)/$G30 -> 1.7528882 | E30: =(E$29*$B$4-'Debt Schedule'!$G$25+'Debt Schedule'!$G$9)/$G30 -> 1.8341042 | F30: =(F$29*$B$4-'Debt Schedule'!$G$25+'Debt Schedule'!$G$9)/$G30 -> 1.9153203 | G30: =Inputs!$B$4*(1+$A30)*Inputs!$B$8+'Sources & Uses'!$B$10+Inputs!$B$30*(Inputs!$B$4*(1+$A30)*Inputs!$B$8+'Sources & Uses'!$B$9+'Sources & Uses'!$B$10)+'Sources & Uses'!$B$30-'Sources & Uses'!$B$19-'Sources & Uses'!$B$20-'Sources & Uses'!$B$21 -> 21419.498 | H30: =(Inputs!$B$4*(1+$A30)*Inputs!$B$8+'Sources & Uses'!$B$9+'Sources & Uses'!$B$10)/'Sources & Uses'!$B$12 -> 21.325208
A31: =Inputs!$B$28+(-0.05) -> 0.25 | B31: =(B$29*$B$4-'Debt Schedule'!$G$25+'Debt Schedule'!$G$9)/$G31 -> 1.4863388 | C31: =(C$29*$B$4-'Debt Schedule'!$G$25+'Debt Schedule'!$G$9)/$G31 -> 1.5622382 | D31: =(D$29*$B$4-'Debt Schedule'!$G$25+'Debt Schedule'!$G$9)/$G31 -> 1.6381375 | E31: =(E$29*$B$4-'Debt Schedule'!$G$25+'Debt Schedule'!$G$9)/$G31 -> 1.7140369 | F31: =(F$29*$B$4-'Debt Schedule'!$G$25+'Debt Schedule'!$G$9)/$G31 -> 1.7899363 | G31: =Inputs!$B$4*(1+$A31)*Inputs!$B$8+'Sources & Uses'!$B$10+Inputs!$B$30*(Inputs!$B$4*(1+$A31)*Inputs!$B$8+'Sources & Uses'!$B$9+'Sources & Uses'!$B$10)+'Sources & Uses'!$B$30-'Sources & Uses'!$B$19-'Sources & Uses'!$B$20-'Sources & Uses'!$B$21 -> 22919.922 | H31: =(Inputs!$B$4*(1+$A31)*Inputs!$B$8+'Sources & Uses'!$B$9+'Sources & Uses'!$B$10)/'Sources & Uses'!$B$12 -> 22.443375
A32: =Inputs!$B$28 -> 0.3 | B32: =(B$29*$B$4-'Debt Schedule'!$G$25+'Debt Schedule'!$G$9)/$G32 -> 1.3950158 | C32: =(C$29*$B$4-'Debt Schedule'!$G$25+'Debt Schedule'!$G$9)/$G32 -> 1.4662518 | D32: =(D$29*$B$4-'Debt Schedule'!$G$25+'Debt Schedule'!$G$9)/$G32 -> 1.5374878 | E32: =(E$29*$B$4-'Debt Schedule'!$G$25+'Debt Schedule'!$G$9)/$G32 -> 1.6087238 | F32: =(F$29*$B$4-'Debt Schedule'!$G$25+'Debt Schedule'!$G$9)/$G32 -> 1.6799598 | G32: =Inputs!$B$4*(1+$A32)*Inputs!$B$8+'Sources & Uses'!$B$10+Inputs!$B$30*(Inputs!$B$4*(1+$A32)*Inputs!$B$8+'Sources & Uses'!$B$9+'Sources & Uses'!$B$10)+'Sources & Uses'!$B$30-'Sources & Uses'!$B$19-'Sources & Uses'!$B$20-'Sources & Uses'!$B$21 -> 24420.346 | H32: =(Inputs!$B$4*(1+$A32)*Inputs!$B$8+'Sources & Uses'!$B$9+'Sources & Uses'!$B$10)/'Sources & Uses'!$B$12 -> 23.561542
A33: =Inputs!$B$28+(0.05) -> 0.35 | B33: =(B$29*$B$4-'Debt Schedule'!$G$25+'Debt Schedule'!$G$9)/$G33 -> 1.3142653 | C33: =(C$29*$B$4-'Debt Schedule'!$G$25+'Debt Schedule'!$G$9)/$G33 -> 1.3813778 | D33: =(D$29*$B$4-'Debt Schedule'!$G$25+'Debt Schedule'!$G$9)/$G33 -> 1.4484903 | E33: =(E$29*$B$4-'Debt Schedule'!$G$25+'Debt Schedule'!$G$9)/$G33 -> 1.5156028 | F33: =(F$29*$B$4-'Debt Schedule'!$G$25+'Debt Schedule'!$G$9)/$G33 -> 1.5827153 | G33: =Inputs!$B$4*(1+$A33)*Inputs!$B$8+'Sources & Uses'!$B$10+Inputs!$B$30*(Inputs!$B$4*(1+$A33)*Inputs!$B$8+'Sources & Uses'!$B$9+'Sources & Uses'!$B$10)+'Sources & Uses'!$B$30-'Sources & Uses'!$B$19-'Sources & Uses'!$B$20-'Sources & Uses'!$B$21 -> 25920.77 | H33: =(Inputs!$B$4*(1+$A33)*Inputs!$B$8+'Sources & Uses'!$B$9+'Sources & Uses'!$B$10)/'Sources & Uses'!$B$12 -> 24.679708
A34: =Inputs!$B$28+(0.1) -> 0.4 | B34: =(B$29*$B$4-'Debt Schedule'!$G$25+'Debt Schedule'!$G$9)/$G34 -> 1.2423518 | C34: =(C$29*$B$4-'Debt Schedule'!$G$25+'Debt Schedule'!$G$9)/$G34 -> 1.305792 | D34: =(D$29*$B$4-'Debt Schedule'!$G$25+'Debt Schedule'!$G$9)/$G34 -> 1.3692323 | E34: =(E$29*$B$4-'Debt Schedule'!$G$25+'Debt Schedule'!$G$9)/$G34 -> 1.4326725 | F34: =(F$29*$B$4-'Debt Schedule'!$G$25+'Debt Schedule'!$G$9)/$G34 -> 1.4961128 | G34: =Inputs!$B$4*(1+$A34)*Inputs!$B$8+'Sources & Uses'!$B$10+Inputs!$B$30*(Inputs!$B$4*(1+$A34)*Inputs!$B$8+'Sources & Uses'!$B$9+'Sources & Uses'!$B$10)+'Sources & Uses'!$B$30-'Sources & Uses'!$B$19-'Sources & Uses'!$B$20-'Sources & Uses'!$B$21 -> 27421.195 | H34: =(Inputs!$B$4*(1+$A34)*Inputs!$B$8+'Sources & Uses'!$B$9+'Sources & Uses'!$B$10)/'Sources & Uses'!$B$12 -> 25.797875
A36: Check: center IRR - model IRR | B36: =ROUND(D23-B12,8) -> 0
A37: Check: center MOIC - model MOIC | B37: =ROUND(D32-B11,8) -> 0
